INFO 2024-03-28 19:03:30,788 autoreload 16792 6980 Watching for file changes with StatReloader
INFO 2024-03-28 19:03:37,050 basehttp 16792 24504 "GET / HTTP/1.1" 200 130
INFO 2024-03-28 19:04:21,617 basehttp 16792 24504 "GET /info/ HTTP/1.1" 200 228
INFO 2024-03-28 19:12:32,171 autoreload 20972 15376 Watching for file changes with StatReloader
INFO 2024-03-28 19:12:38,274 basehttp 20972 13816 "GET / HTTP/1.1" 200 130
INFO 2024-03-28 19:12:56,480 basehttp 20972 13816 "GET /info/ HTTP/1.1" 200 228
INFO 2024-03-28 19:17:40,305 autoreload 20972 15376 C:\Users\Рабочий\Desktop\djangodzr\myproj\myproj\settings.py changed, reloading.
INFO 2024-03-28 19:17:40,780 autoreload 22452 15576 Watching for file changes with StatReloader
INFO 2024-03-28 19:17:45,282 views 22452 7012 Перешли на страницу с информацией обо мне - 
        <h2>Чуть-чуть обо мне.</h2>
        <p>Зовут меня Максим. Являюсь студентом GB.</p>
        <p>Мало времени на учёбу, но я стараюсь.</p>
        
INFO 2024-03-28 19:17:45,283 basehttp 22452 7012 "GET /info/ HTTP/1.1" 200 228
INFO 2024-03-28 19:17:46,150 views 22452 7012 Перешли на страницу с информацией обо мне - 
        <h2>Чуть-чуть обо мне.</h2>
        <p>Зовут меня Максим. Являюсь студентом GB.</p>
        <p>Мало времени на учёбу, но я стараюсь.</p>
        
INFO 2024-03-28 19:17:46,152 basehttp 22452 7012 "GET /info/ HTTP/1.1" 200 228
INFO 2024-03-28 19:17:49,441 views 22452 7012 Перешли на главную страницу - 
        <h1>Добро пожаловать!</h1>
        <p>Вы посетили мой первый Django - сайт</p>
    
INFO 2024-03-28 19:17:49,442 basehttp 22452 7012 "GET / HTTP/1.1" 200 130
INFO 2024-03-28 19:18:12,788 autoreload 22452 15576 C:\Users\Рабочий\Desktop\djangodzr\myproj\myweb\views.py changed, reloading.
INFO 2024-03-28 19:18:13,271 autoreload 14120 19944 Watching for file changes with StatReloader
INFO 2024-03-28 19:18:17,048 views 14120 25416 Перешли на главную страницу.
INFO 2024-03-28 19:18:17,049 basehttp 14120 25416 "GET / HTTP/1.1" 200 130
INFO 2024-03-28 19:18:27,737 views 14120 25416 Перешли на страницу с информацией обо мне.
INFO 2024-03-28 19:18:27,737 basehttp 14120 25416 "GET /info/ HTTP/1.1" 200 228
INFO 2024-04-02 19:40:24,680 autoreload 18664 15192 Watching for file changes with StatReloader
INFO 2024-04-02 19:48:02,673 autoreload 14768 6520 Watching for file changes with StatReloader
INFO 2024-04-02 19:48:58,885 autoreload 25236 12060 Watching for file changes with StatReloader
INFO 2024-04-02 19:50:25,541 autoreload 24008 19532 Watching for file changes with StatReloader
INFO 2024-04-02 19:58:19,377 autoreload 24008 19532 C:\Users\Рабочий\Desktop\djangodzr\myproj\myweb\models.py changed, reloading.
INFO 2024-04-02 19:58:19,903 autoreload 12712 4508 Watching for file changes with StatReloader
INFO 2024-04-02 19:58:25,761 autoreload 3868 8828 Watching for file changes with StatReloader
WARNING 2024-04-02 19:58:35,182 log 3868 25224 Not Found: /
WARNING 2024-04-02 19:58:35,183 basehttp 3868 25224 "GET / HTTP/1.1" 404 2584
INFO 2024-04-02 19:59:15,137 autoreload 3868 8828 C:\Users\Рабочий\Desktop\djangodzr\myproj\myweb\urls.py changed, reloading.
INFO 2024-04-02 19:59:15,718 autoreload 5036 1368 Watching for file changes with StatReloader
INFO 2024-04-02 19:59:19,107 basehttp 5036 18016 "GET /client HTTP/1.1" 301 0
ERROR 2024-04-02 19:59:19,199 log 5036 20656 Internal Server Error: /client/
Traceback (most recent call last):
  File "C:\Users\Рабочий\Desktop\djangodzr\venv\Lib\site-packages\django\core\handlers\exception.py", line 55, in inner
    response = get_response(request)
               ^^^^^^^^^^^^^^^^^^^^^
  File "C:\Users\Рабочий\Desktop\djangodzr\venv\Lib\site-packages\django\core\handlers\base.py", line 197, in _get_response
    response = wrapped_callback(request, *callback_args, **callback_kwargs)
               ^^^^^^^^^^^^^^^^^^^^^^^^^^^^^^^^^^^^^^^^^^^^^^^^^^^^^^^^^^^^
  File "C:\Users\Рабочий\Desktop\djangodzr\myproj\myweb\views.py", line 43, in create_client
    return render(request, 'create_client.html', {'form': form})
           ^^^^^^^^^^^^^^^^^^^^^^^^^^^^^^^^^^^^^^^^^^^^^^^^^^^^^
  File "C:\Users\Рабочий\Desktop\djangodzr\venv\Lib\site-packages\django\shortcuts.py", line 25, in render
    content = loader.render_to_string(template_name, context, request, using=using)
              ^^^^^^^^^^^^^^^^^^^^^^^^^^^^^^^^^^^^^^^^^^^^^^^^^^^^^^^^^^^^^^^^^^^^^
  File "C:\Users\Рабочий\Desktop\djangodzr\venv\Lib\site-packages\django\template\loader.py", line 61, in render_to_string
    template = get_template(template_name, using=using)
               ^^^^^^^^^^^^^^^^^^^^^^^^^^^^^^^^^^^^^^^^
  File "C:\Users\Рабочий\Desktop\djangodzr\venv\Lib\site-packages\django\template\loader.py", line 19, in get_template
    raise TemplateDoesNotExist(template_name, chain=chain)
django.template.exceptions.TemplateDoesNotExist: create_client.html
ERROR 2024-04-02 19:59:19,203 basehttp 5036 20656 "GET /client/ HTTP/1.1" 500 84000
WARNING 2024-04-02 20:01:03,357 log 5036 15540 Not Found: /corder
WARNING 2024-04-02 20:01:03,358 basehttp 5036 15540 "GET /corder HTTP/1.1" 404 2623
INFO 2024-04-02 20:01:09,540 basehttp 5036 25528 "GET /order HTTP/1.1" 301 0
ERROR 2024-04-02 20:01:09,721 log 5036 17700 Internal Server Error: /order/
Traceback (most recent call last):
  File "C:\Users\Рабочий\Desktop\djangodzr\venv\Lib\site-packages\django\db\backends\utils.py", line 105, in _execute
    return self.cursor.execute(sql, params)
           ^^^^^^^^^^^^^^^^^^^^^^^^^^^^^^^^
  File "C:\Users\Рабочий\Desktop\djangodzr\venv\Lib\site-packages\django\db\backends\sqlite3\base.py", line 329, in execute
    return super().execute(query, params)
           ^^^^^^^^^^^^^^^^^^^^^^^^^^^^^^
sqlite3.OperationalError: no such column: myweb_client.registration_date

The above exception was the direct cause of the following exception:

Traceback (most recent call last):
  File "C:\Users\Рабочий\Desktop\djangodzr\venv\Lib\site-packages\django\core\handlers\exception.py", line 55, in inner
    response = get_response(request)
               ^^^^^^^^^^^^^^^^^^^^^
  File "C:\Users\Рабочий\Desktop\djangodzr\venv\Lib\site-packages\django\core\handlers\base.py", line 197, in _get_response
    response = wrapped_callback(request, *callback_args, **callback_kwargs)
               ^^^^^^^^^^^^^^^^^^^^^^^^^^^^^^^^^^^^^^^^^^^^^^^^^^^^^^^^^^^^
  File "C:\Users\Рабочий\Desktop\djangodzr\myproj\myweb\views.py", line 58, in create_order
    return render(request, 'create_order.html', {'form': form})
           ^^^^^^^^^^^^^^^^^^^^^^^^^^^^^^^^^^^^^^^^^^^^^^^^^^^^
  File "C:\Users\Рабочий\Desktop\djangodzr\venv\Lib\site-packages\django\shortcuts.py", line 25, in render
    content = loader.render_to_string(template_name, context, request, using=using)
              ^^^^^^^^^^^^^^^^^^^^^^^^^^^^^^^^^^^^^^^^^^^^^^^^^^^^^^^^^^^^^^^^^^^^^
  File "C:\Users\Рабочий\Desktop\djangodzr\venv\Lib\site-packages\django\template\loader.py", line 62, in render_to_string
    return template.render(context, request)
           ^^^^^^^^^^^^^^^^^^^^^^^^^^^^^^^^^
  File "C:\Users\Рабочий\Desktop\djangodzr\venv\Lib\site-packages\django\template\backends\django.py", line 61, in render
    return self.template.render(context)
           ^^^^^^^^^^^^^^^^^^^^^^^^^^^^^
  File "C:\Users\Рабочий\Desktop\djangodzr\venv\Lib\site-packages\django\template\base.py", line 171, in render
    return self._render(context)
           ^^^^^^^^^^^^^^^^^^^^^
  File "C:\Users\Рабочий\Desktop\djangodzr\venv\Lib\site-packages\django\template\base.py", line 163, in _render
    return self.nodelist.render(context)
           ^^^^^^^^^^^^^^^^^^^^^^^^^^^^^
  File "C:\Users\Рабочий\Desktop\djangodzr\venv\Lib\site-packages\django\template\base.py", line 1000, in render
    return SafeString("".join([node.render_annotated(context) for node in self]))
                              ^^^^^^^^^^^^^^^^^^^^^^^^^^^^^^^^^^^^^^^^^^^^^^^^^
  File "C:\Users\Рабочий\Desktop\djangodzr\venv\Lib\site-packages\django\template\base.py", line 1000, in <listcomp>
    return SafeString("".join([node.render_annotated(context) for node in self]))
                               ^^^^^^^^^^^^^^^^^^^^^^^^^^^^^^
  File "C:\Users\Рабочий\Desktop\djangodzr\venv\Lib\site-packages\django\template\base.py", line 961, in render_annotated
    return self.render(context)
           ^^^^^^^^^^^^^^^^^^^^
  File "C:\Users\Рабочий\Desktop\djangodzr\venv\Lib\site-packages\django\template\base.py", line 1059, in render
    output = self.filter_expression.resolve(context)
             ^^^^^^^^^^^^^^^^^^^^^^^^^^^^^^^^^^^^^^^
  File "C:\Users\Рабочий\Desktop\djangodzr\venv\Lib\site-packages\django\template\base.py", line 710, in resolve
    obj = self.var.resolve(context)
          ^^^^^^^^^^^^^^^^^^^^^^^^^
  File "C:\Users\Рабочий\Desktop\djangodzr\venv\Lib\site-packages\django\template\base.py", line 842, in resolve
    value = self._resolve_lookup(context)
            ^^^^^^^^^^^^^^^^^^^^^^^^^^^^^
  File "C:\Users\Рабочий\Desktop\djangodzr\venv\Lib\site-packages\django\template\base.py", line 909, in _resolve_lookup
    current = current()
              ^^^^^^^^^
  File "C:\Users\Рабочий\Desktop\djangodzr\venv\Lib\site-packages\django\forms\utils.py", line 87, in as_p
    return self.render(self.template_name_p)
           ^^^^^^^^^^^^^^^^^^^^^^^^^^^^^^^^^
  File "C:\Users\Рабочий\Desktop\djangodzr\venv\Lib\site-packages\django\forms\utils.py", line 55, in render
    return mark_safe(renderer.render(template, context))
                     ^^^^^^^^^^^^^^^^^^^^^^^^^^^^^^^^^^
  File "C:\Users\Рабочий\Desktop\djangodzr\venv\Lib\site-packages\django\forms\renderers.py", line 29, in render
    return template.render(context, request=request).strip()
           ^^^^^^^^^^^^^^^^^^^^^^^^^^^^^^^^^^^^^^^^^
  File "C:\Users\Рабочий\Desktop\djangodzr\venv\Lib\site-packages\django\template\backends\django.py", line 61, in render
    return self.template.render(context)
           ^^^^^^^^^^^^^^^^^^^^^^^^^^^^^
  File "C:\Users\Рабочий\Desktop\djangodzr\venv\Lib\site-packages\django\template\base.py", line 171, in render
    return self._render(context)
           ^^^^^^^^^^^^^^^^^^^^^
  File "C:\Users\Рабочий\Desktop\djangodzr\venv\Lib\site-packages\django\template\base.py", line 163, in _render
    return self.nodelist.render(context)
           ^^^^^^^^^^^^^^^^^^^^^^^^^^^^^
  File "C:\Users\Рабочий\Desktop\djangodzr\venv\Lib\site-packages\django\template\base.py", line 1000, in render
    return SafeString("".join([node.render_annotated(context) for node in self]))
                              ^^^^^^^^^^^^^^^^^^^^^^^^^^^^^^^^^^^^^^^^^^^^^^^^^
  File "C:\Users\Рабочий\Desktop\djangodzr\venv\Lib\site-packages\django\template\base.py", line 1000, in <listcomp>
    return SafeString("".join([node.render_annotated(context) for node in self]))
                               ^^^^^^^^^^^^^^^^^^^^^^^^^^^^^^
  File "C:\Users\Рабочий\Desktop\djangodzr\venv\Lib\site-packages\django\template\base.py", line 961, in render_annotated
    return self.render(context)
           ^^^^^^^^^^^^^^^^^^^^
  File "C:\Users\Рабочий\Desktop\djangodzr\venv\Lib\site-packages\django\template\defaulttags.py", line 242, in render
    nodelist.append(node.render_annotated(context))
                    ^^^^^^^^^^^^^^^^^^^^^^^^^^^^^^
  File "C:\Users\Рабочий\Desktop\djangodzr\venv\Lib\site-packages\django\template\base.py", line 961, in render_annotated
    return self.render(context)
           ^^^^^^^^^^^^^^^^^^^^
  File "C:\Users\Рабочий\Desktop\djangodzr\venv\Lib\site-packages\django\template\base.py", line 1065, in render
    return render_value_in_context(output, context)
           ^^^^^^^^^^^^^^^^^^^^^^^^^^^^^^^^^^^^^^^^
  File "C:\Users\Рабочий\Desktop\djangodzr\venv\Lib\site-packages\django\template\base.py", line 1042, in render_value_in_context
    value = str(value)
            ^^^^^^^^^^
  File "C:\Users\Рабочий\Desktop\djangodzr\venv\Lib\site-packages\django\forms\utils.py", line 79, in __str__
    return self.as_widget()
           ^^^^^^^^^^^^^^^^
  File "C:\Users\Рабочий\Desktop\djangodzr\venv\Lib\site-packages\django\forms\boundfield.py", line 108, in as_widget
    return widget.render(
           ^^^^^^^^^^^^^^
  File "C:\Users\Рабочий\Desktop\djangodzr\venv\Lib\site-packages\django\forms\widgets.py", line 278, in render
    context = self.get_context(name, value, attrs)
              ^^^^^^^^^^^^^^^^^^^^^^^^^^^^^^^^^^^^
  File "C:\Users\Рабочий\Desktop\djangodzr\venv\Lib\site-packages\django\forms\widgets.py", line 764, in get_context
    context = super().get_context(name, value, attrs)
              ^^^^^^^^^^^^^^^^^^^^^^^^^^^^^^^^^^^^^^^
  File "C:\Users\Рабочий\Desktop\djangodzr\venv\Lib\site-packages\django\forms\widgets.py", line 715, in get_context
    context["widget"]["optgroups"] = self.optgroups(
                                     ^^^^^^^^^^^^^^^
  File "C:\Users\Рабочий\Desktop\djangodzr\venv\Lib\site-packages\django\forms\widgets.py", line 655, in optgroups
    for index, (option_value, option_label) in enumerate(self.choices):
  File "C:\Users\Рабочий\Desktop\djangodzr\venv\Lib\site-packages\django\forms\models.py", line 1422, in __iter__
    for obj in queryset:
  File "C:\Users\Рабочий\Desktop\djangodzr\venv\Lib\site-packages\django\db\models\query.py", line 518, in _iterator
    yield from iterable
  File "C:\Users\Рабочий\Desktop\djangodzr\venv\Lib\site-packages\django\db\models\query.py", line 91, in __iter__
    results = compiler.execute_sql(
              ^^^^^^^^^^^^^^^^^^^^^
  File "C:\Users\Рабочий\Desktop\djangodzr\venv\Lib\site-packages\django\db\models\sql\compiler.py", line 1562, in execute_sql
    cursor.execute(sql, params)
  File "C:\Users\Рабочий\Desktop\djangodzr\venv\Lib\site-packages\django\db\backends\utils.py", line 122, in execute
    return super().execute(sql, params)
           ^^^^^^^^^^^^^^^^^^^^^^^^^^^^
  File "C:\Users\Рабочий\Desktop\djangodzr\venv\Lib\site-packages\django\db\backends\utils.py", line 79, in execute
    return self._execute_with_wrappers(
           ^^^^^^^^^^^^^^^^^^^^^^^^^^^^
  File "C:\Users\Рабочий\Desktop\djangodzr\venv\Lib\site-packages\django\db\backends\utils.py", line 92, in _execute_with_wrappers
    return executor(sql, params, many, context)
           ^^^^^^^^^^^^^^^^^^^^^^^^^^^^^^^^^^^^
  File "C:\Users\Рабочий\Desktop\djangodzr\venv\Lib\site-packages\django\db\backends\utils.py", line 100, in _execute
    with self.db.wrap_database_errors:
  File "C:\Users\Рабочий\Desktop\djangodzr\venv\Lib\site-packages\django\db\utils.py", line 91, in __exit__
    raise dj_exc_value.with_traceback(traceback) from exc_value
  File "C:\Users\Рабочий\Desktop\djangodzr\venv\Lib\site-packages\django\db\backends\utils.py", line 105, in _execute
    return self.cursor.execute(sql, params)
           ^^^^^^^^^^^^^^^^^^^^^^^^^^^^^^^^
  File "C:\Users\Рабочий\Desktop\djangodzr\venv\Lib\site-packages\django\db\backends\sqlite3\base.py", line 329, in execute
    return super().execute(query, params)
           ^^^^^^^^^^^^^^^^^^^^^^^^^^^^^^
django.db.utils.OperationalError: no such column: myweb_client.registration_date
ERROR 2024-04-02 20:01:09,741 basehttp 5036 17700 "GET /order/ HTTP/1.1" 500 280779
INFO 2024-04-02 20:02:34,144 autoreload 5036 1368 C:\Users\Рабочий\Desktop\djangodzr\myproj\myweb\views.py changed, reloading.
INFO 2024-04-02 20:02:34,688 autoreload 11964 10968 Watching for file changes with StatReloader
INFO 2024-04-02 20:02:48,214 autoreload 11964 10968 C:\Users\Рабочий\Desktop\djangodzr\myproj\myweb\urls.py changed, reloading.
INFO 2024-04-02 20:02:48,727 autoreload 22924 18596 Watching for file changes with StatReloader
INFO 2024-04-02 20:03:08,162 autoreload 8536 10700 Watching for file changes with StatReloader
INFO 2024-04-02 20:03:26,773 autoreload 8536 10700 C:\Users\Рабочий\Desktop\djangodzr\myproj\myweb\urls.py changed, reloading.
INFO 2024-04-02 20:03:27,242 autoreload 13276 18496 Watching for file changes with StatReloader
INFO 2024-04-02 20:03:35,904 basehttp 13276 11556 "GET /client/ HTTP/1.1" 200 224
INFO 2024-04-02 20:03:38,325 basehttp 13276 4484 "POST /client/ HTTP/1.1" 200 224
INFO 2024-04-02 20:03:40,064 basehttp 13276 4484 "POST /client/ HTTP/1.1" 200 224
INFO 2024-04-02 20:03:41,234 basehttp 13276 4484 "POST /client/ HTTP/1.1" 200 224
INFO 2024-04-02 20:07:58,955 autoreload 13276 18496 C:\Users\Рабочий\Desktop\djangodzr\myproj\myweb\views.py changed, reloading.
INFO 2024-04-02 20:07:59,502 autoreload 19152 16456 Watching for file changes with StatReloader
INFO 2024-04-02 20:08:38,502 autoreload 19152 16456 C:\Users\Рабочий\Desktop\djangodzr\myproj\myweb\urls.py changed, reloading.
INFO 2024-04-02 20:08:38,974 autoreload 2700 14120 Watching for file changes with StatReloader
INFO 2024-04-02 20:08:48,489 basehttp 2700 2948 "POST /client/ HTTP/1.1" 200 1418
INFO 2024-04-02 20:09:28,323 basehttp 2700 23660 "POST /client/ HTTP/1.1" 200 1174
INFO 2024-04-02 20:12:40,816 basehttp 2700 18308 "POST /client/ HTTP/1.1" 200 1174
INFO 2024-04-02 20:19:14,653 autoreload 15280 5100 Watching for file changes with StatReloader
INFO 2024-04-02 20:19:23,665 basehttp 15280 19992 "POST /client/ HTTP/1.1" 200 1174
INFO 2024-04-02 20:19:26,296 basehttp 15280 12016 "POST /client/ HTTP/1.1" 200 1174
INFO 2024-04-02 20:25:23,192 autoreload 15280 5100 C:\Users\Рабочий\Desktop\djangodzr\myproj\myweb\views.py changed, reloading.
INFO 2024-04-02 20:25:23,692 autoreload 5096 25084 Watching for file changes with StatReloader
INFO 2024-04-02 20:25:43,378 autoreload 5096 25084 C:\Users\Рабочий\Desktop\djangodzr\myproj\myweb\views.py changed, reloading.
INFO 2024-04-02 20:25:43,875 autoreload 23856 13292 Watching for file changes with StatReloader
INFO 2024-04-02 20:25:52,127 basehttp 23856 18388 "POST /client/ HTTP/1.1" 200 1174
INFO 2024-04-02 20:25:56,472 basehttp 23856 18388 "POST /client/ HTTP/1.1" 200 1174
INFO 2024-04-02 20:26:37,535 autoreload 14136 22500 Watching for file changes with StatReloader
WARNING 2024-04-02 20:26:47,588 log 14136 19340 Not Found: /
WARNING 2024-04-02 20:26:47,589 basehttp 14136 19340 "GET / HTTP/1.1" 404 2585
INFO 2024-04-02 20:26:53,435 basehttp 14136 19340 "GET /client/ HTTP/1.1" 200 1020
INFO 2024-04-02 20:27:40,555 basehttp 14136 19340 "POST /client/ HTTP/1.1" 200 1193
INFO 2024-04-02 20:28:45,343 basehttp 14136 19340 "GET /product HTTP/1.1" 301 0
INFO 2024-04-02 20:28:45,352 basehttp 14136 11488 "GET /product/ HTTP/1.1" 200 996
INFO 2024-04-02 20:29:03,042 basehttp 14136 11488 "POST /product/ HTTP/1.1" 200 1130
INFO 2024-04-02 20:29:17,372 basehttp 14136 11488 "GET /order/ HTTP/1.1" 200 870
INFO 2024-04-02 20:32:48,389 autoreload 14136 22500 C:\Users\Рабочий\Desktop\djangodzr\myproj\myweb\views.py changed, reloading.
INFO 2024-04-02 20:32:48,954 autoreload 5732 12696 Watching for file changes with StatReloader
INFO 2024-04-02 20:36:31,800 basehttp 5732 17704 "GET /client/ HTTP/1.1" 200 1020
INFO 2024-04-02 20:36:44,184 basehttp 5732 17704 "POST /client/ HTTP/1.1" 200 1193
INFO 2024-04-02 20:37:08,852 basehttp 5732 4984 "POST /client/ HTTP/1.1" 200 1194
INFO 2024-04-02 20:37:13,045 basehttp 5732 4984 "POST /client/ HTTP/1.1" 200 1192
ERROR 2024-04-02 20:38:00,161 log 5732 23400 Internal Server Error: /client/
Traceback (most recent call last):
  File "C:\Users\Рабочий\Desktop\djangodzr\venv\Lib\site-packages\django\core\handlers\exception.py", line 55, in inner
    response = get_response(request)
               ^^^^^^^^^^^^^^^^^^^^^
  File "C:\Users\Рабочий\Desktop\djangodzr\venv\Lib\site-packages\django\core\handlers\base.py", line 197, in _get_response
    response = wrapped_callback(request, *callback_args, **callback_kwargs)
               ^^^^^^^^^^^^^^^^^^^^^^^^^^^^^^^^^^^^^^^^^^^^^^^^^^^^^^^^^^^^
  File "C:\Users\Рабочий\Desktop\djangodzr\myproj\myweb\views.py", line 49, in create_client
    return render(request, 'success.html')
           ^^^^^^^^^^^^^^^^^^^^^^^^^^^^^^^
  File "C:\Users\Рабочий\Desktop\djangodzr\venv\Lib\site-packages\django\shortcuts.py", line 25, in render
    content = loader.render_to_string(template_name, context, request, using=using)
              ^^^^^^^^^^^^^^^^^^^^^^^^^^^^^^^^^^^^^^^^^^^^^^^^^^^^^^^^^^^^^^^^^^^^^
  File "C:\Users\Рабочий\Desktop\djangodzr\venv\Lib\site-packages\django\template\loader.py", line 61, in render_to_string
    template = get_template(template_name, using=using)
               ^^^^^^^^^^^^^^^^^^^^^^^^^^^^^^^^^^^^^^^^
  File "C:\Users\Рабочий\Desktop\djangodzr\venv\Lib\site-packages\django\template\loader.py", line 19, in get_template
    raise TemplateDoesNotExist(template_name, chain=chain)
django.template.exceptions.TemplateDoesNotExist: success.html
ERROR 2024-04-02 20:38:00,164 basehttp 5732 23400 "POST /client/ HTTP/1.1" 500 85417
INFO 2024-04-02 20:46:33,957 autoreload 5732 12696 C:\Users\Рабочий\Desktop\djangodzr\myproj\myweb\views.py changed, reloading.
INFO 2024-04-02 20:46:34,465 autoreload 20216 8136 Watching for file changes with StatReloader
INFO 2024-04-02 20:46:41,103 basehttp 20216 19080 "POST /client/ HTTP/1.1" 200 190
INFO 2024-04-02 20:46:54,444 basehttp 20216 19080 "POST /client/ HTTP/1.1" 200 188
INFO 2024-04-02 20:47:21,487 basehttp 20216 19080 "GET /product/ HTTP/1.1" 200 996
INFO 2024-04-02 20:48:12,963 basehttp 20216 19080 "POST /product/ HTTP/1.1" 200 184
INFO 2024-04-02 20:48:47,011 basehttp 20216 19080 "GET /order/ HTTP/1.1" 200 1026
INFO 2024-04-02 20:49:10,845 autoreload 20216 8136 C:\Users\Рабочий\Desktop\djangodzr\myproj\myweb\views.py changed, reloading.
INFO 2024-04-02 20:49:11,360 autoreload 21732 9788 Watching for file changes with StatReloader
INFO 2024-04-02 20:49:40,146 basehttp 21732 4236 "POST /order/ HTTP/1.1" 200 184
INFO 2024-04-05 19:59:52,265 autoreload 10852 19364 Watching for file changes with StatReloader
WARNING 2024-04-05 19:59:59,885 log 10852 4768 Not Found: /
WARNING 2024-04-05 19:59:59,886 basehttp 10852 4768 "GET / HTTP/1.1" 404 2585
INFO 2024-04-05 20:00:08,411 basehttp 10852 20048 "GET /client/ HTTP/1.1" 200 1020
INFO 2024-04-05 20:00:54,363 basehttp 10852 13812 "POST /client/ HTTP/1.1" 200 189
INFO 2024-04-05 20:02:01,277 basehttp 10852 9900 "GET /product/ HTTP/1.1" 200 996
INFO 2024-04-05 20:02:32,637 basehttp 10852 21192 "POST /product/ HTTP/1.1" 200 1144
INFO 2024-04-05 20:02:42,107 basehttp 10852 3264 "POST /product/ HTTP/1.1" 200 184
INFO 2024-04-05 20:03:22,163 basehttp 10852 7416 "POST /product/ HTTP/1.1" 200 184
INFO 2024-04-05 20:04:07,966 basehttp 10852 4136 "POST /product/ HTTP/1.1" 200 184
INFO 2024-04-05 20:05:06,997 basehttp 10852 15484 "GET /order/ HTTP/1.1" 200 1189
INFO 2024-04-05 20:05:32,168 basehttp 10852 13140 "POST /order/ HTTP/1.1" 200 184
INFO 2024-04-05 20:05:53,010 basehttp 10852 8740 "GET /order/ HTTP/1.1" 200 1189
INFO 2024-04-05 20:06:06,551 basehttp 10852 1240 "POST /order/ HTTP/1.1" 200 184
INFO 2024-04-05 20:06:09,377 basehttp 10852 1240 "GET /order/ HTTP/1.1" 200 1189
INFO 2024-04-05 20:06:18,280 basehttp 10852 11276 "POST /order/ HTTP/1.1" 200 184
INFO 2024-04-05 20:06:31,899 basehttp 10852 24196 "GET /order/ HTTP/1.1" 200 1189
INFO 2024-04-05 20:06:42,091 basehttp 10852 3472 "POST /order/ HTTP/1.1" 200 184
INFO 2024-04-05 20:06:54,621 basehttp 10852 14424 "GET /order/ HTTP/1.1" 200 1189
INFO 2024-04-05 20:06:59,507 basehttp 10852 15656 "POST /order/ HTTP/1.1" 200 184
INFO 2024-04-05 20:09:00,656 autoreload 10852 19364 C:\Users\Рабочий\Desktop\djangodzr\myproj\myweb\views.py changed, reloading.
INFO 2024-04-05 20:09:01,151 autoreload 13872 1480 Watching for file changes with StatReloader
INFO 2024-04-05 20:09:34,035 autoreload 13872 1480 C:\Users\Рабочий\Desktop\djangodzr\myproj\myweb\views.py changed, reloading.
INFO 2024-04-05 20:09:34,509 autoreload 3636 8616 Watching for file changes with StatReloader
INFO 2024-04-05 20:11:53,474 autoreload 3636 8616 C:\Users\Рабочий\Desktop\djangodzr\myproj\myweb\views.py changed, reloading.
INFO 2024-04-05 20:11:53,950 autoreload 12292 15528 Watching for file changes with StatReloader
INFO 2024-04-05 20:13:36,186 autoreload 12292 15528 C:\Users\Рабочий\Desktop\djangodzr\myproj\myweb\urls.py changed, reloading.
INFO 2024-04-05 20:13:36,666 autoreload 8116 15384 Watching for file changes with StatReloader
INFO 2024-04-05 20:14:01,380 autoreload 8116 15384 C:\Users\Рабочий\Desktop\djangodzr\myproj\myweb\urls.py changed, reloading.
INFO 2024-04-05 20:14:01,839 autoreload 19744 6804 Watching for file changes with StatReloader
INFO 2024-04-05 20:14:08,254 basehttp 19744 18552 "GET /orders/ HTTP/1.1" 200 918
INFO 2024-04-05 20:15:22,769 basehttp 19744 12948 "GET /orders/ HTTP/1.1" 200 918
INFO 2024-04-05 20:15:23,328 basehttp 19744 12948 "GET /orders/ HTTP/1.1" 200 918
INFO 2024-04-05 20:15:23,975 basehttp 19744 12948 "GET /orders/ HTTP/1.1" 200 918
INFO 2024-04-05 20:15:26,936 basehttp 19744 12948 "GET /order/ HTTP/1.1" 200 1189
INFO 2024-04-05 20:15:34,083 basehttp 19744 12948 "GET /orders/ HTTP/1.1" 200 918
INFO 2024-04-05 20:16:50,111 basehttp 19744 14792 "GET /orders/ HTTP/1.1" 200 918
INFO 2024-04-05 20:16:50,756 basehttp 19744 14792 "GET /orders/ HTTP/1.1" 200 918
INFO 2024-04-05 20:16:51,122 basehttp 19744 14792 "GET /orders/ HTTP/1.1" 200 918
INFO 2024-04-05 20:16:51,340 basehttp 19744 14792 "GET /orders/ HTTP/1.1" 200 918
INFO 2024-04-05 20:16:51,512 basehttp 19744 14792 "GET /orders/ HTTP/1.1" 200 918
INFO 2024-04-05 20:16:51,850 basehttp 19744 14792 "GET /orders/ HTTP/1.1" 200 918
INFO 2024-04-05 20:16:52,097 basehttp 19744 14792 "GET /orders/ HTTP/1.1" 200 918
INFO 2024-04-05 20:16:52,271 basehttp 19744 14792 "GET /orders/ HTTP/1.1" 200 918
INFO 2024-04-05 20:16:52,429 basehttp 19744 14792 "GET /orders/ HTTP/1.1" 200 918
INFO 2024-04-05 20:16:52,586 basehttp 19744 14792 "GET /orders/ HTTP/1.1" 200 918
INFO 2024-04-05 20:16:52,728 basehttp 19744 14792 "GET /orders/ HTTP/1.1" 200 918
INFO 2024-04-05 20:16:52,871 basehttp 19744 14792 "GET /orders/ HTTP/1.1" 200 918
INFO 2024-04-05 20:16:53,022 basehttp 19744 14792 "GET /orders/ HTTP/1.1" 200 918
INFO 2024-04-05 20:16:53,298 basehttp 19744 14792 "GET /orders/ HTTP/1.1" 200 918
INFO 2024-04-05 20:16:53,644 basehttp 19744 14792 "GET /orders/ HTTP/1.1" 200 918
INFO 2024-04-05 20:16:53,853 basehttp 19744 14792 "GET /orders/ HTTP/1.1" 200 918
INFO 2024-04-05 20:16:54,003 basehttp 19744 14792 "GET /orders/ HTTP/1.1" 200 918
INFO 2024-04-05 20:16:54,169 basehttp 19744 14792 "GET /orders/ HTTP/1.1" 200 918
INFO 2024-04-05 20:16:54,334 basehttp 19744 14792 "GET /orders/ HTTP/1.1" 200 918
INFO 2024-04-05 20:16:54,499 basehttp 19744 14792 "GET /orders/ HTTP/1.1" 200 918
INFO 2024-04-05 20:20:33,421 basehttp 19744 3704 "GET /orders/ HTTP/1.1" 200 1692
INFO 2024-04-05 20:21:33,806 basehttp 19744 10632 "GET /orders/ HTTP/1.1" 200 1704
INFO 2024-04-05 20:21:34,947 basehttp 19744 10632 "GET /orders/ HTTP/1.1" 200 1704
INFO 2024-04-05 20:21:43,270 basehttp 19744 17992 "GET /orders/ HTTP/1.1" 200 1636
INFO 2024-04-05 20:29:39,633 autoreload 19744 6804 C:\Users\Рабочий\Desktop\djangodzr\myproj\myweb\views.py changed, reloading.
INFO 2024-04-05 20:29:40,297 autoreload 17404 17060 Watching for file changes with StatReloader
INFO 2024-04-05 20:30:15,201 autoreload 17404 17060 C:\Users\Рабочий\Desktop\djangodzr\myproj\myweb\views.py changed, reloading.
INFO 2024-04-05 20:30:15,681 autoreload 12044 12376 Watching for file changes with StatReloader
INFO 2024-04-05 20:31:39,549 autoreload 12044 12376 C:\Users\Рабочий\Desktop\djangodzr\myproj\myweb\views.py changed, reloading.
INFO 2024-04-05 20:31:40,051 autoreload 22372 16272 Watching for file changes with StatReloader
INFO 2024-04-05 20:32:14,829 autoreload 20832 9260 Watching for file changes with StatReloader
INFO 2024-04-05 20:33:30,302 autoreload 22372 16272 C:\Users\Рабочий\Desktop\djangodzr\myproj\myweb\urls.py changed, reloading.
INFO 2024-04-05 20:33:30,434 autoreload 20832 9260 C:\Users\Рабочий\Desktop\djangodzr\myproj\myweb\urls.py changed, reloading.
INFO 2024-04-05 20:33:30,792 autoreload 18952 9720 Watching for file changes with StatReloader
INFO 2024-04-05 20:33:30,925 autoreload 6772 13032 Watching for file changes with StatReloader
INFO 2024-04-05 20:33:44,425 autoreload 6772 13032 C:\Users\Рабочий\Desktop\djangodzr\myproj\myweb\urls.py changed, reloading.
INFO 2024-04-05 20:33:44,913 autoreload 4192 11692 Watching for file changes with StatReloader
INFO 2024-04-05 20:33:45,319 autoreload 18952 9720 C:\Users\Рабочий\Desktop\djangodzr\myproj\myweb\urls.py changed, reloading.
INFO 2024-04-05 20:33:45,775 autoreload 22868 8228 Watching for file changes with StatReloader
INFO 2024-04-05 20:33:53,972 autoreload 9012 13612 Watching for file changes with StatReloader
INFO 2024-04-05 20:34:11,511 autoreload 22868 8228 C:\Users\Рабочий\Desktop\djangodzr\myproj\myweb\urls.py changed, reloading.
INFO 2024-04-05 20:34:11,530 autoreload 9012 13612 C:\Users\Рабочий\Desktop\djangodzr\myproj\myweb\urls.py changed, reloading.
INFO 2024-04-05 20:34:11,982 autoreload 3884 3604 Watching for file changes with StatReloader
INFO 2024-04-05 20:34:12,000 autoreload 3016 2448 Watching for file changes with StatReloader
INFO 2024-04-05 20:34:16,863 basehttp 3884 7732 "GET /orders/ HTTP/1.1" 200 1595
INFO 2024-04-05 20:40:39,853 autoreload 3884 3604 C:\Users\Рабочий\Desktop\djangodzr\myproj\myweb\views.py changed, reloading.
INFO 2024-04-05 20:40:40,497 autoreload 7644 21388 Watching for file changes with StatReloader
INFO 2024-04-05 20:40:40,573 autoreload 3016 2448 C:\Users\Рабочий\Desktop\djangodzr\myproj\myweb\views.py changed, reloading.
INFO 2024-04-05 20:40:41,054 autoreload 25480 22972 Watching for file changes with StatReloader
INFO 2024-04-05 20:42:38,026 autoreload 7644 21388 C:\Users\Рабочий\Desktop\djangodzr\myproj\myweb\forms.py changed, reloading.
INFO 2024-04-05 20:42:38,523 autoreload 20164 13184 Watching for file changes with StatReloader
INFO 2024-04-05 20:42:38,561 autoreload 25480 22972 C:\Users\Рабочий\Desktop\djangodzr\myproj\myweb\forms.py changed, reloading.
INFO 2024-04-05 20:42:39,029 autoreload 10516 10420 Watching for file changes with StatReloader
INFO 2024-04-05 20:43:04,799 autoreload 10516 10420 C:\Users\Рабочий\Desktop\djangodzr\myproj\myweb\views.py changed, reloading.
INFO 2024-04-05 20:43:05,287 autoreload 8556 11272 Watching for file changes with StatReloader
INFO 2024-04-05 20:43:05,312 autoreload 20164 13184 C:\Users\Рабочий\Desktop\djangodzr\myproj\myweb\views.py changed, reloading.
INFO 2024-04-05 20:43:05,854 autoreload 11404 23900 Watching for file changes with StatReloader
INFO 2024-04-05 20:43:21,953 basehttp 8556 16604 "GET /order/ HTTP/1.1" 200 1499
ERROR 2024-04-05 20:43:34,300 log 8556 16604 Internal Server Error: /order/
Traceback (most recent call last):
  File "C:\Users\Рабочий\Desktop\djangodzr\venv\Lib\site-packages\django\core\handlers\exception.py", line 55, in inner
    response = get_response(request)
               ^^^^^^^^^^^^^^^^^^^^^
  File "C:\Users\Рабочий\Desktop\djangodzr\venv\Lib\site-packages\django\core\handlers\base.py", line 197, in _get_response
    response = wrapped_callback(request, *callback_args, **callback_kwargs)
               ^^^^^^^^^^^^^^^^^^^^^^^^^^^^^^^^^^^^^^^^^^^^^^^^^^^^^^^^^^^^
  File "C:\Users\Рабочий\Desktop\djangodzr\myproj\myweb\views.py", line 80, in create_order
    order.products.add(product)
    ^^^^^^^^^^^^^^
  File "C:\Users\Рабочий\Desktop\djangodzr\venv\Lib\site-packages\django\db\models\fields\related_descriptors.py", line 650, in __get__
    return self.related_manager_cls(instance)
           ^^^^^^^^^^^^^^^^^^^^^^^^^^^^^^^^^^
  File "C:\Users\Рабочий\Desktop\djangodzr\venv\Lib\site-packages\django\db\models\fields\related_descriptors.py", line 1069, in __init__
    raise ValueError(
ValueError: "<Order: Order None by Maria>" needs to have a value for field "id" before this many-to-many relationship can be used.
ERROR 2024-04-05 20:43:34,304 basehttp 8556 16604 "POST /order/ HTTP/1.1" 500 81102
INFO 2024-04-05 20:45:16,527 autoreload 8556 11272 C:\Users\Рабочий\Desktop\djangodzr\myproj\myproj\urls.py changed, reloading.
INFO 2024-04-05 20:45:16,591 autoreload 11404 23900 C:\Users\Рабочий\Desktop\djangodzr\myproj\myproj\urls.py changed, reloading.
INFO 2024-04-05 20:45:17,024 autoreload 23048 17584 Watching for file changes with StatReloader
INFO 2024-04-05 20:45:17,078 autoreload 3252 20876 Watching for file changes with StatReloader
INFO 2024-04-05 20:45:37,087 autoreload 24876 16564 Watching for file changes with StatReloader
INFO 2024-04-05 20:46:17,862 autoreload 17400 12620 Watching for file changes with StatReloader
INFO 2024-04-05 20:47:58,558 autoreload 10960 11792 Watching for file changes with StatReloader
INFO 2024-04-05 20:48:24,460 autoreload 5948 18588 Watching for file changes with StatReloader
ERROR 2024-04-05 20:48:36,947 log 5948 20432 Internal Server Error: /order/
Traceback (most recent call last):
  File "C:\Users\Рабочий\Desktop\djangodzr\venv\Lib\site-packages\django\core\handlers\exception.py", line 55, in inner
    response = get_response(request)
               ^^^^^^^^^^^^^^^^^^^^^
  File "C:\Users\Рабочий\Desktop\djangodzr\venv\Lib\site-packages\django\core\handlers\base.py", line 197, in _get_response
    response = wrapped_callback(request, *callback_args, **callback_kwargs)
               ^^^^^^^^^^^^^^^^^^^^^^^^^^^^^^^^^^^^^^^^^^^^^^^^^^^^^^^^^^^^
  File "C:\Users\Рабочий\Desktop\djangodzr\myproj\myweb\views.py", line 80, in create_order
    order.products.add(product)
    ^^^^^^^^^^^^^^
  File "C:\Users\Рабочий\Desktop\djangodzr\venv\Lib\site-packages\django\db\models\fields\related_descriptors.py", line 650, in __get__
    return self.related_manager_cls(instance)
           ^^^^^^^^^^^^^^^^^^^^^^^^^^^^^^^^^^
  File "C:\Users\Рабочий\Desktop\djangodzr\venv\Lib\site-packages\django\db\models\fields\related_descriptors.py", line 1069, in __init__
    raise ValueError(
ValueError: "<Order: Order None by Maria>" needs to have a value for field "id" before this many-to-many relationship can be used.
ERROR 2024-04-05 20:48:36,951 basehttp 5948 20432 "POST /order/ HTTP/1.1" 500 81102
ERROR 2024-04-05 20:48:44,243 log 5948 20432 Internal Server Error: /order/
Traceback (most recent call last):
  File "C:\Users\Рабочий\Desktop\djangodzr\venv\Lib\site-packages\django\core\handlers\exception.py", line 55, in inner
    response = get_response(request)
               ^^^^^^^^^^^^^^^^^^^^^
  File "C:\Users\Рабочий\Desktop\djangodzr\venv\Lib\site-packages\django\core\handlers\base.py", line 197, in _get_response
    response = wrapped_callback(request, *callback_args, **callback_kwargs)
               ^^^^^^^^^^^^^^^^^^^^^^^^^^^^^^^^^^^^^^^^^^^^^^^^^^^^^^^^^^^^
  File "C:\Users\Рабочий\Desktop\djangodzr\myproj\myweb\views.py", line 80, in create_order
    order.products.add(product)
    ^^^^^^^^^^^^^^
  File "C:\Users\Рабочий\Desktop\djangodzr\venv\Lib\site-packages\django\db\models\fields\related_descriptors.py", line 650, in __get__
    return self.related_manager_cls(instance)
           ^^^^^^^^^^^^^^^^^^^^^^^^^^^^^^^^^^
  File "C:\Users\Рабочий\Desktop\djangodzr\venv\Lib\site-packages\django\db\models\fields\related_descriptors.py", line 1069, in __init__
    raise ValueError(
ValueError: "<Order: Order None by Maria>" needs to have a value for field "id" before this many-to-many relationship can be used.
ERROR 2024-04-05 20:48:44,246 basehttp 5948 20432 "POST /order/ HTTP/1.1" 500 81102
INFO 2024-04-05 20:50:46,680 autoreload 5948 18588 C:\Users\Рабочий\Desktop\djangodzr\myproj\myproj\urls.py changed, reloading.
INFO 2024-04-05 20:50:47,194 autoreload 15528 16604 Watching for file changes with StatReloader
INFO 2024-04-05 20:52:13,136 autoreload 15528 16604 C:\Users\Рабочий\Desktop\djangodzr\myproj\myweb\views.py changed, reloading.
INFO 2024-04-05 20:52:13,610 autoreload 22120 19392 Watching for file changes with StatReloader
ERROR 2024-04-05 20:52:19,513 log 22120 17632 Internal Server Error: /order/
Traceback (most recent call last):
  File "C:\Users\Рабочий\Desktop\djangodzr\venv\Lib\site-packages\django\core\handlers\exception.py", line 55, in inner
    response = get_response(request)
               ^^^^^^^^^^^^^^^^^^^^^
  File "C:\Users\Рабочий\Desktop\djangodzr\venv\Lib\site-packages\django\core\handlers\base.py", line 197, in _get_response
    response = wrapped_callback(request, *callback_args, **callback_kwargs)
               ^^^^^^^^^^^^^^^^^^^^^^^^^^^^^^^^^^^^^^^^^^^^^^^^^^^^^^^^^^^^
  File "C:\Users\Рабочий\Desktop\djangodzr\myproj\myweb\views.py", line 78, in create_order
    order.products.add(product)
    ^^^^^^^^^^^^^^
  File "C:\Users\Рабочий\Desktop\djangodzr\venv\Lib\site-packages\django\db\models\fields\related_descriptors.py", line 650, in __get__
    return self.related_manager_cls(instance)
           ^^^^^^^^^^^^^^^^^^^^^^^^^^^^^^^^^^
  File "C:\Users\Рабочий\Desktop\djangodzr\venv\Lib\site-packages\django\db\models\fields\related_descriptors.py", line 1069, in __init__
    raise ValueError(
ValueError: "<Order: Order None by Maria>" needs to have a value for field "id" before this many-to-many relationship can be used.
ERROR 2024-04-05 20:52:19,516 basehttp 22120 17632 "POST /order/ HTTP/1.1" 500 80904
INFO 2024-04-05 20:52:27,682 basehttp 22120 17632 "GET /orders/ HTTP/1.1" 200 1595
INFO 2024-04-05 20:52:32,640 basehttp 22120 17632 "GET /order/ HTTP/1.1" 200 1499
ERROR 2024-04-05 20:52:41,379 log 22120 17632 Internal Server Error: /order/
Traceback (most recent call last):
  File "C:\Users\Рабочий\Desktop\djangodzr\venv\Lib\site-packages\django\core\handlers\exception.py", line 55, in inner
    response = get_response(request)
               ^^^^^^^^^^^^^^^^^^^^^
  File "C:\Users\Рабочий\Desktop\djangodzr\venv\Lib\site-packages\django\core\handlers\base.py", line 197, in _get_response
    response = wrapped_callback(request, *callback_args, **callback_kwargs)
               ^^^^^^^^^^^^^^^^^^^^^^^^^^^^^^^^^^^^^^^^^^^^^^^^^^^^^^^^^^^^
  File "C:\Users\Рабочий\Desktop\djangodzr\myproj\myweb\views.py", line 78, in create_order
    order.products.add(product)
    ^^^^^^^^^^^^^^
  File "C:\Users\Рабочий\Desktop\djangodzr\venv\Lib\site-packages\django\db\models\fields\related_descriptors.py", line 650, in __get__
    return self.related_manager_cls(instance)
           ^^^^^^^^^^^^^^^^^^^^^^^^^^^^^^^^^^
  File "C:\Users\Рабочий\Desktop\djangodzr\venv\Lib\site-packages\django\db\models\fields\related_descriptors.py", line 1069, in __init__
    raise ValueError(
ValueError: "<Order: Order None by Ivan>" needs to have a value for field "id" before this many-to-many relationship can be used.
ERROR 2024-04-05 20:52:41,382 basehttp 22120 17632 "POST /order/ HTTP/1.1" 500 80858
INFO 2024-04-05 20:55:24,969 autoreload 22120 19392 C:\Users\Рабочий\Desktop\djangodzr\myproj\myweb\views.py changed, reloading.
INFO 2024-04-05 20:55:25,492 autoreload 9964 22696 Watching for file changes with StatReloader
INFO 2024-04-05 20:55:29,349 basehttp 9964 25444 "POST /order/ HTTP/1.1" 200 184
INFO 2024-04-05 20:55:36,198 basehttp 9964 25444 "GET /order/ HTTP/1.1" 200 1499
INFO 2024-04-05 20:55:39,652 basehttp 9964 25444 "POST /order/ HTTP/1.1" 200 184
INFO 2024-04-05 20:55:42,332 basehttp 9964 25444 "GET /order/ HTTP/1.1" 200 1499
WARNING 2024-04-05 20:55:47,659 log 9964 25444 Not Found: /orderы/
WARNING 2024-04-05 20:55:47,660 basehttp 9964 25444 "GET /order%D1%8B/ HTTP/1.1" 404 2804
INFO 2024-04-05 20:55:52,679 basehttp 9964 25444 "GET /orders/ HTTP/1.1" 200 2193
INFO 2024-04-06 12:18:50,268 autoreload 22756 6764 Watching for file changes with StatReloader
WARNING 2024-04-06 12:19:01,044 log 22756 9940 Not Found: /
WARNING 2024-04-06 12:19:01,047 basehttp 22756 9940 "GET / HTTP/1.1" 404 2758
WARNING 2024-04-06 12:19:01,138 log 22756 9940 Not Found: /favicon.ico
WARNING 2024-04-06 12:19:01,139 basehttp 22756 9940 "GET /favicon.ico HTTP/1.1" 404 2809
INFO 2024-04-06 12:19:11,185 basehttp 22756 14292 "GET /orders/ HTTP/1.1" 200 2193
INFO 2024-04-06 12:20:10,548 basehttp 22756 21672 "GET /order/ HTTP/1.1" 200 1499
INFO 2024-04-06 12:20:40,858 basehttp 22756 13636 "POST /order/ HTTP/1.1" 200 184
INFO 2024-04-06 12:20:44,638 basehttp 22756 13636 "GET /order/ HTTP/1.1" 200 1499
INFO 2024-04-06 12:21:00,988 basehttp 22756 14284 "POST /order/ HTTP/1.1" 200 184
INFO 2024-04-06 12:21:06,070 basehttp 22756 14284 "GET /orders/ HTTP/1.1" 200 2935
INFO 2024-04-06 12:22:53,666 autoreload 22756 6764 C:\Users\Рабочий\Desktop\djangodzr\myproj\myweb\views.py changed, reloading.
INFO 2024-04-06 12:22:54,272 autoreload 4852 21216 Watching for file changes with StatReloader
INFO 2024-04-06 12:23:12,910 autoreload 4852 21216 C:\Users\Рабочий\Desktop\djangodzr\myproj\myweb\views.py changed, reloading.
INFO 2024-04-06 12:23:13,410 autoreload 23692 15648 Watching for file changes with StatReloader
INFO 2024-04-06 12:25:00,726 autoreload 23692 15648 C:\Users\Рабочий\Desktop\djangodzr\myproj\myweb\urls.py changed, reloading.
INFO 2024-04-06 12:25:01,223 autoreload 20284 5520 Watching for file changes with StatReloader
INFO 2024-04-06 12:25:20,398 basehttp 20284 23048 "GET /purchased_products HTTP/1.1" 301 0
ERROR 2024-04-06 12:25:20,543 log 20284 22704 Internal Server Error: /purchased_products/
Traceback (most recent call last):
  File "C:\Users\Рабочий\Desktop\djangodzr\venv\Lib\site-packages\django\core\handlers\exception.py", line 55, in inner
    response = get_response(request)
               ^^^^^^^^^^^^^^^^^^^^^
  File "C:\Users\Рабочий\Desktop\djangodzr\venv\Lib\site-packages\django\core\handlers\base.py", line 197, in _get_response
    response = wrapped_callback(request, *callback_args, **callback_kwargs)
               ^^^^^^^^^^^^^^^^^^^^^^^^^^^^^^^^^^^^^^^^^^^^^^^^^^^^^^^^^^^^
  File "C:\Users\Рабочий\Desktop\djangodzr\myproj\myweb\views.py", line 105, in purchased_products
    week_orders = Order.objects.filter(customer=request.user, date_created__gte=week_ago)
                  ^^^^^^^^^^^^^^^^^^^^^^^^^^^^^^^^^^^^^^^^^^^^^^^^^^^^^^^^^^^^^^^^^^^^^^^
  File "C:\Users\Рабочий\Desktop\djangodzr\venv\Lib\site-packages\django\db\models\manager.py", line 87, in manager_method
    return getattr(self.get_queryset(), name)(*args, **kwargs)
           ^^^^^^^^^^^^^^^^^^^^^^^^^^^^^^^^^^^^^^^^^^^^^^^^^^^
  File "C:\Users\Рабочий\Desktop\djangodzr\venv\Lib\site-packages\django\db\models\query.py", line 1476, in filter
    return self._filter_or_exclude(False, args, kwargs)
           ^^^^^^^^^^^^^^^^^^^^^^^^^^^^^^^^^^^^^^^^^^^^
  File "C:\Users\Рабочий\Desktop\djangodzr\venv\Lib\site-packages\django\db\models\query.py", line 1494, in _filter_or_exclude
    clone._filter_or_exclude_inplace(negate, args, kwargs)
  File "C:\Users\Рабочий\Desktop\djangodzr\venv\Lib\site-packages\django\db\models\query.py", line 1501, in _filter_or_exclude_inplace
    self._query.add_q(Q(*args, **kwargs))
  File "C:\Users\Рабочий\Desktop\djangodzr\venv\Lib\site-packages\django\db\models\sql\query.py", line 1613, in add_q
    clause, _ = self._add_q(q_object, self.used_aliases)
                ^^^^^^^^^^^^^^^^^^^^^^^^^^^^^^^^^^^^^^^^
  File "C:\Users\Рабочий\Desktop\djangodzr\venv\Lib\site-packages\django\db\models\sql\query.py", line 1645, in _add_q
    child_clause, needed_inner = self.build_filter(
                                 ^^^^^^^^^^^^^^^^^^
  File "C:\Users\Рабочий\Desktop\djangodzr\venv\Lib\site-packages\django\db\models\sql\query.py", line 1495, in build_filter
    lookups, parts, reffed_expression = self.solve_lookup_type(arg, summarize)
                                        ^^^^^^^^^^^^^^^^^^^^^^^^^^^^^^^^^^^^^^
  File "C:\Users\Рабочий\Desktop\djangodzr\venv\Lib\site-packages\django\db\models\sql\query.py", line 1307, in solve_lookup_type
    _, field, _, lookup_parts = self.names_to_path(lookup_splitted, self.get_meta())
                                ^^^^^^^^^^^^^^^^^^^^^^^^^^^^^^^^^^^^^^^^^^^^^^^^^^^^
  File "C:\Users\Рабочий\Desktop\djangodzr\venv\Lib\site-packages\django\db\models\sql\query.py", line 1772, in names_to_path
    raise FieldError(
django.core.exceptions.FieldError: Cannot resolve keyword 'customer' into field. Choices are: client, client_id, id, order_date, products, total_amount
ERROR 2024-04-06 12:25:20,551 basehttp 20284 22704 "GET /purchased_products/ HTTP/1.1" 500 116900
INFO 2024-04-06 12:26:56,877 autoreload 20284 5520 C:\Users\Рабочий\Desktop\djangodzr\myproj\myweb\views.py changed, reloading.
INFO 2024-04-06 12:26:57,403 autoreload 16432 9124 Watching for file changes with StatReloader
ERROR 2024-04-06 12:26:57,926 log 16432 4608 Internal Server Error: /purchased_products/
Traceback (most recent call last):
  File "C:\Users\Рабочий\Desktop\djangodzr\venv\Lib\site-packages\django\db\models\fields\__init__.py", line 2117, in get_prep_value
    return int(value)
           ^^^^^^^^^^
TypeError: int() argument must be a string, a bytes-like object or a real number, not 'SimpleLazyObject'

The above exception was the direct cause of the following exception:

Traceback (most recent call last):
  File "C:\Users\Рабочий\Desktop\djangodzr\venv\Lib\site-packages\django\core\handlers\exception.py", line 55, in inner
    response = get_response(request)
               ^^^^^^^^^^^^^^^^^^^^^
  File "C:\Users\Рабочий\Desktop\djangodzr\venv\Lib\site-packages\django\core\handlers\base.py", line 197, in _get_response
    response = wrapped_callback(request, *callback_args, **callback_kwargs)
               ^^^^^^^^^^^^^^^^^^^^^^^^^^^^^^^^^^^^^^^^^^^^^^^^^^^^^^^^^^^^
  File "C:\Users\Рабочий\Desktop\djangodzr\myproj\myweb\views.py", line 105, in purchased_products
    week_orders = Order.objects.filter(client=request.user, date_created__gte=week_ago)
                  ^^^^^^^^^^^^^^^^^^^^^^^^^^^^^^^^^^^^^^^^^^^^^^^^^^^^^^^^^^^^^^^^^^^^^
  File "C:\Users\Рабочий\Desktop\djangodzr\venv\Lib\site-packages\django\db\models\manager.py", line 87, in manager_method
    return getattr(self.get_queryset(), name)(*args, **kwargs)
           ^^^^^^^^^^^^^^^^^^^^^^^^^^^^^^^^^^^^^^^^^^^^^^^^^^^
  File "C:\Users\Рабочий\Desktop\djangodzr\venv\Lib\site-packages\django\db\models\query.py", line 1476, in filter
    return self._filter_or_exclude(False, args, kwargs)
           ^^^^^^^^^^^^^^^^^^^^^^^^^^^^^^^^^^^^^^^^^^^^
  File "C:\Users\Рабочий\Desktop\djangodzr\venv\Lib\site-packages\django\db\models\query.py", line 1494, in _filter_or_exclude
    clone._filter_or_exclude_inplace(negate, args, kwargs)
  File "C:\Users\Рабочий\Desktop\djangodzr\venv\Lib\site-packages\django\db\models\query.py", line 1501, in _filter_or_exclude_inplace
    self._query.add_q(Q(*args, **kwargs))
  File "C:\Users\Рабочий\Desktop\djangodzr\venv\Lib\site-packages\django\db\models\sql\query.py", line 1613, in add_q
    clause, _ = self._add_q(q_object, self.used_aliases)
                ^^^^^^^^^^^^^^^^^^^^^^^^^^^^^^^^^^^^^^^^
  File "C:\Users\Рабочий\Desktop\djangodzr\venv\Lib\site-packages\django\db\models\sql\query.py", line 1645, in _add_q
    child_clause, needed_inner = self.build_filter(
                                 ^^^^^^^^^^^^^^^^^^
  File "C:\Users\Рабочий\Desktop\djangodzr\venv\Lib\site-packages\django\db\models\sql\query.py", line 1559, in build_filter
    condition = self.build_lookup(lookups, col, value)
                ^^^^^^^^^^^^^^^^^^^^^^^^^^^^^^^^^^^^^^
  File "C:\Users\Рабочий\Desktop\djangodzr\venv\Lib\site-packages\django\db\models\sql\query.py", line 1389, in build_lookup
    lookup = lookup_class(lhs, rhs)
             ^^^^^^^^^^^^^^^^^^^^^^
  File "C:\Users\Рабочий\Desktop\djangodzr\venv\Lib\site-packages\django\db\models\lookups.py", line 30, in __init__
    self.rhs = self.get_prep_lookup()
               ^^^^^^^^^^^^^^^^^^^^^^
  File "C:\Users\Рабочий\Desktop\djangodzr\venv\Lib\site-packages\django\db\models\fields\related_lookups.py", line 156, in get_prep_lookup
    self.rhs = target_field.get_prep_value(self.rhs)
               ^^^^^^^^^^^^^^^^^^^^^^^^^^^^^^^^^^^^^
  File "C:\Users\Рабочий\Desktop\djangodzr\venv\Lib\site-packages\django\db\models\fields\__init__.py", line 2119, in get_prep_value
    raise e.__class__(
TypeError: Field 'id' expected a number but got <SimpleLazyObject: <django.contrib.auth.models.AnonymousUser object at 0x000001EF7C4E1A10>>.
ERROR 2024-04-06 12:26:57,935 basehttp 16432 4608 "GET /purchased_products/ HTTP/1.1" 500 131915
ERROR 2024-04-06 12:26:59,046 log 16432 8036 Internal Server Error: /purchased_products/
Traceback (most recent call last):
  File "C:\Users\Рабочий\Desktop\djangodzr\venv\Lib\site-packages\django\db\models\fields\__init__.py", line 2117, in get_prep_value
    return int(value)
           ^^^^^^^^^^
TypeError: int() argument must be a string, a bytes-like object or a real number, not 'SimpleLazyObject'

The above exception was the direct cause of the following exception:

Traceback (most recent call last):
  File "C:\Users\Рабочий\Desktop\djangodzr\venv\Lib\site-packages\django\core\handlers\exception.py", line 55, in inner
    response = get_response(request)
               ^^^^^^^^^^^^^^^^^^^^^
  File "C:\Users\Рабочий\Desktop\djangodzr\venv\Lib\site-packages\django\core\handlers\base.py", line 197, in _get_response
    response = wrapped_callback(request, *callback_args, **callback_kwargs)
               ^^^^^^^^^^^^^^^^^^^^^^^^^^^^^^^^^^^^^^^^^^^^^^^^^^^^^^^^^^^^
  File "C:\Users\Рабочий\Desktop\djangodzr\myproj\myweb\views.py", line 105, in purchased_products
    week_orders = Order.objects.filter(client=request.user, date_created__gte=week_ago)
                  ^^^^^^^^^^^^^^^^^^^^^^^^^^^^^^^^^^^^^^^^^^^^^^^^^^^^^^^^^^^^^^^^^^^^^
  File "C:\Users\Рабочий\Desktop\djangodzr\venv\Lib\site-packages\django\db\models\manager.py", line 87, in manager_method
    return getattr(self.get_queryset(), name)(*args, **kwargs)
           ^^^^^^^^^^^^^^^^^^^^^^^^^^^^^^^^^^^^^^^^^^^^^^^^^^^
  File "C:\Users\Рабочий\Desktop\djangodzr\venv\Lib\site-packages\django\db\models\query.py", line 1476, in filter
    return self._filter_or_exclude(False, args, kwargs)
           ^^^^^^^^^^^^^^^^^^^^^^^^^^^^^^^^^^^^^^^^^^^^
  File "C:\Users\Рабочий\Desktop\djangodzr\venv\Lib\site-packages\django\db\models\query.py", line 1494, in _filter_or_exclude
    clone._filter_or_exclude_inplace(negate, args, kwargs)
  File "C:\Users\Рабочий\Desktop\djangodzr\venv\Lib\site-packages\django\db\models\query.py", line 1501, in _filter_or_exclude_inplace
    self._query.add_q(Q(*args, **kwargs))
  File "C:\Users\Рабочий\Desktop\djangodzr\venv\Lib\site-packages\django\db\models\sql\query.py", line 1613, in add_q
    clause, _ = self._add_q(q_object, self.used_aliases)
                ^^^^^^^^^^^^^^^^^^^^^^^^^^^^^^^^^^^^^^^^
  File "C:\Users\Рабочий\Desktop\djangodzr\venv\Lib\site-packages\django\db\models\sql\query.py", line 1645, in _add_q
    child_clause, needed_inner = self.build_filter(
                                 ^^^^^^^^^^^^^^^^^^
  File "C:\Users\Рабочий\Desktop\djangodzr\venv\Lib\site-packages\django\db\models\sql\query.py", line 1559, in build_filter
    condition = self.build_lookup(lookups, col, value)
                ^^^^^^^^^^^^^^^^^^^^^^^^^^^^^^^^^^^^^^
  File "C:\Users\Рабочий\Desktop\djangodzr\venv\Lib\site-packages\django\db\models\sql\query.py", line 1389, in build_lookup
    lookup = lookup_class(lhs, rhs)
             ^^^^^^^^^^^^^^^^^^^^^^
  File "C:\Users\Рабочий\Desktop\djangodzr\venv\Lib\site-packages\django\db\models\lookups.py", line 30, in __init__
    self.rhs = self.get_prep_lookup()
               ^^^^^^^^^^^^^^^^^^^^^^
  File "C:\Users\Рабочий\Desktop\djangodzr\venv\Lib\site-packages\django\db\models\fields\related_lookups.py", line 156, in get_prep_lookup
    self.rhs = target_field.get_prep_value(self.rhs)
               ^^^^^^^^^^^^^^^^^^^^^^^^^^^^^^^^^^^^^
  File "C:\Users\Рабочий\Desktop\djangodzr\venv\Lib\site-packages\django\db\models\fields\__init__.py", line 2119, in get_prep_value
    raise e.__class__(
TypeError: Field 'id' expected a number but got <SimpleLazyObject: <django.contrib.auth.models.AnonymousUser object at 0x000001EF7C776850>>.
ERROR 2024-04-06 12:26:59,053 basehttp 16432 8036 "GET /purchased_products/ HTTP/1.1" 500 131897
ERROR 2024-04-06 12:26:59,625 log 16432 8036 Internal Server Error: /purchased_products/
Traceback (most recent call last):
  File "C:\Users\Рабочий\Desktop\djangodzr\venv\Lib\site-packages\django\db\models\fields\__init__.py", line 2117, in get_prep_value
    return int(value)
           ^^^^^^^^^^
TypeError: int() argument must be a string, a bytes-like object or a real number, not 'SimpleLazyObject'

The above exception was the direct cause of the following exception:

Traceback (most recent call last):
  File "C:\Users\Рабочий\Desktop\djangodzr\venv\Lib\site-packages\django\core\handlers\exception.py", line 55, in inner
    response = get_response(request)
               ^^^^^^^^^^^^^^^^^^^^^
  File "C:\Users\Рабочий\Desktop\djangodzr\venv\Lib\site-packages\django\core\handlers\base.py", line 197, in _get_response
    response = wrapped_callback(request, *callback_args, **callback_kwargs)
               ^^^^^^^^^^^^^^^^^^^^^^^^^^^^^^^^^^^^^^^^^^^^^^^^^^^^^^^^^^^^
  File "C:\Users\Рабочий\Desktop\djangodzr\myproj\myweb\views.py", line 105, in purchased_products
    week_orders = Order.objects.filter(client=request.user, date_created__gte=week_ago)
                  ^^^^^^^^^^^^^^^^^^^^^^^^^^^^^^^^^^^^^^^^^^^^^^^^^^^^^^^^^^^^^^^^^^^^^
  File "C:\Users\Рабочий\Desktop\djangodzr\venv\Lib\site-packages\django\db\models\manager.py", line 87, in manager_method
    return getattr(self.get_queryset(), name)(*args, **kwargs)
           ^^^^^^^^^^^^^^^^^^^^^^^^^^^^^^^^^^^^^^^^^^^^^^^^^^^
  File "C:\Users\Рабочий\Desktop\djangodzr\venv\Lib\site-packages\django\db\models\query.py", line 1476, in filter
    return self._filter_or_exclude(False, args, kwargs)
           ^^^^^^^^^^^^^^^^^^^^^^^^^^^^^^^^^^^^^^^^^^^^
  File "C:\Users\Рабочий\Desktop\djangodzr\venv\Lib\site-packages\django\db\models\query.py", line 1494, in _filter_or_exclude
    clone._filter_or_exclude_inplace(negate, args, kwargs)
  File "C:\Users\Рабочий\Desktop\djangodzr\venv\Lib\site-packages\django\db\models\query.py", line 1501, in _filter_or_exclude_inplace
    self._query.add_q(Q(*args, **kwargs))
  File "C:\Users\Рабочий\Desktop\djangodzr\venv\Lib\site-packages\django\db\models\sql\query.py", line 1613, in add_q
    clause, _ = self._add_q(q_object, self.used_aliases)
                ^^^^^^^^^^^^^^^^^^^^^^^^^^^^^^^^^^^^^^^^
  File "C:\Users\Рабочий\Desktop\djangodzr\venv\Lib\site-packages\django\db\models\sql\query.py", line 1645, in _add_q
    child_clause, needed_inner = self.build_filter(
                                 ^^^^^^^^^^^^^^^^^^
  File "C:\Users\Рабочий\Desktop\djangodzr\venv\Lib\site-packages\django\db\models\sql\query.py", line 1559, in build_filter
    condition = self.build_lookup(lookups, col, value)
                ^^^^^^^^^^^^^^^^^^^^^^^^^^^^^^^^^^^^^^
  File "C:\Users\Рабочий\Desktop\djangodzr\venv\Lib\site-packages\django\db\models\sql\query.py", line 1389, in build_lookup
    lookup = lookup_class(lhs, rhs)
             ^^^^^^^^^^^^^^^^^^^^^^
  File "C:\Users\Рабочий\Desktop\djangodzr\venv\Lib\site-packages\django\db\models\lookups.py", line 30, in __init__
    self.rhs = self.get_prep_lookup()
               ^^^^^^^^^^^^^^^^^^^^^^
  File "C:\Users\Рабочий\Desktop\djangodzr\venv\Lib\site-packages\django\db\models\fields\related_lookups.py", line 156, in get_prep_lookup
    self.rhs = target_field.get_prep_value(self.rhs)
               ^^^^^^^^^^^^^^^^^^^^^^^^^^^^^^^^^^^^^
  File "C:\Users\Рабочий\Desktop\djangodzr\venv\Lib\site-packages\django\db\models\fields\__init__.py", line 2119, in get_prep_value
    raise e.__class__(
TypeError: Field 'id' expected a number but got <SimpleLazyObject: <django.contrib.auth.models.AnonymousUser object at 0x000001EF7C9D5410>>.
ERROR 2024-04-06 12:26:59,633 basehttp 16432 8036 "GET /purchased_products/ HTTP/1.1" 500 131915
ERROR 2024-04-06 12:27:00,093 log 16432 8036 Internal Server Error: /purchased_products/
Traceback (most recent call last):
  File "C:\Users\Рабочий\Desktop\djangodzr\venv\Lib\site-packages\django\db\models\fields\__init__.py", line 2117, in get_prep_value
    return int(value)
           ^^^^^^^^^^
TypeError: int() argument must be a string, a bytes-like object or a real number, not 'SimpleLazyObject'

The above exception was the direct cause of the following exception:

Traceback (most recent call last):
  File "C:\Users\Рабочий\Desktop\djangodzr\venv\Lib\site-packages\django\core\handlers\exception.py", line 55, in inner
    response = get_response(request)
               ^^^^^^^^^^^^^^^^^^^^^
  File "C:\Users\Рабочий\Desktop\djangodzr\venv\Lib\site-packages\django\core\handlers\base.py", line 197, in _get_response
    response = wrapped_callback(request, *callback_args, **callback_kwargs)
               ^^^^^^^^^^^^^^^^^^^^^^^^^^^^^^^^^^^^^^^^^^^^^^^^^^^^^^^^^^^^
  File "C:\Users\Рабочий\Desktop\djangodzr\myproj\myweb\views.py", line 105, in purchased_products
    week_orders = Order.objects.filter(client=request.user, date_created__gte=week_ago)
                  ^^^^^^^^^^^^^^^^^^^^^^^^^^^^^^^^^^^^^^^^^^^^^^^^^^^^^^^^^^^^^^^^^^^^^
  File "C:\Users\Рабочий\Desktop\djangodzr\venv\Lib\site-packages\django\db\models\manager.py", line 87, in manager_method
    return getattr(self.get_queryset(), name)(*args, **kwargs)
           ^^^^^^^^^^^^^^^^^^^^^^^^^^^^^^^^^^^^^^^^^^^^^^^^^^^
  File "C:\Users\Рабочий\Desktop\djangodzr\venv\Lib\site-packages\django\db\models\query.py", line 1476, in filter
    return self._filter_or_exclude(False, args, kwargs)
           ^^^^^^^^^^^^^^^^^^^^^^^^^^^^^^^^^^^^^^^^^^^^
  File "C:\Users\Рабочий\Desktop\djangodzr\venv\Lib\site-packages\django\db\models\query.py", line 1494, in _filter_or_exclude
    clone._filter_or_exclude_inplace(negate, args, kwargs)
  File "C:\Users\Рабочий\Desktop\djangodzr\venv\Lib\site-packages\django\db\models\query.py", line 1501, in _filter_or_exclude_inplace
    self._query.add_q(Q(*args, **kwargs))
  File "C:\Users\Рабочий\Desktop\djangodzr\venv\Lib\site-packages\django\db\models\sql\query.py", line 1613, in add_q
    clause, _ = self._add_q(q_object, self.used_aliases)
                ^^^^^^^^^^^^^^^^^^^^^^^^^^^^^^^^^^^^^^^^
  File "C:\Users\Рабочий\Desktop\djangodzr\venv\Lib\site-packages\django\db\models\sql\query.py", line 1645, in _add_q
    child_clause, needed_inner = self.build_filter(
                                 ^^^^^^^^^^^^^^^^^^
  File "C:\Users\Рабочий\Desktop\djangodzr\venv\Lib\site-packages\django\db\models\sql\query.py", line 1559, in build_filter
    condition = self.build_lookup(lookups, col, value)
                ^^^^^^^^^^^^^^^^^^^^^^^^^^^^^^^^^^^^^^
  File "C:\Users\Рабочий\Desktop\djangodzr\venv\Lib\site-packages\django\db\models\sql\query.py", line 1389, in build_lookup
    lookup = lookup_class(lhs, rhs)
             ^^^^^^^^^^^^^^^^^^^^^^
  File "C:\Users\Рабочий\Desktop\djangodzr\venv\Lib\site-packages\django\db\models\lookups.py", line 30, in __init__
    self.rhs = self.get_prep_lookup()
               ^^^^^^^^^^^^^^^^^^^^^^
  File "C:\Users\Рабочий\Desktop\djangodzr\venv\Lib\site-packages\django\db\models\fields\related_lookups.py", line 156, in get_prep_lookup
    self.rhs = target_field.get_prep_value(self.rhs)
               ^^^^^^^^^^^^^^^^^^^^^^^^^^^^^^^^^^^^^
  File "C:\Users\Рабочий\Desktop\djangodzr\venv\Lib\site-packages\django\db\models\fields\__init__.py", line 2119, in get_prep_value
    raise e.__class__(
TypeError: Field 'id' expected a number but got <SimpleLazyObject: <django.contrib.auth.models.AnonymousUser object at 0x000001EF7C9C8D50>>.
ERROR 2024-04-06 12:27:00,100 basehttp 16432 8036 "GET /purchased_products/ HTTP/1.1" 500 131897
ERROR 2024-04-06 12:27:00,336 log 16432 8036 Internal Server Error: /purchased_products/
Traceback (most recent call last):
  File "C:\Users\Рабочий\Desktop\djangodzr\venv\Lib\site-packages\django\db\models\fields\__init__.py", line 2117, in get_prep_value
    return int(value)
           ^^^^^^^^^^
TypeError: int() argument must be a string, a bytes-like object or a real number, not 'SimpleLazyObject'

The above exception was the direct cause of the following exception:

Traceback (most recent call last):
  File "C:\Users\Рабочий\Desktop\djangodzr\venv\Lib\site-packages\django\core\handlers\exception.py", line 55, in inner
    response = get_response(request)
               ^^^^^^^^^^^^^^^^^^^^^
  File "C:\Users\Рабочий\Desktop\djangodzr\venv\Lib\site-packages\django\core\handlers\base.py", line 197, in _get_response
    response = wrapped_callback(request, *callback_args, **callback_kwargs)
               ^^^^^^^^^^^^^^^^^^^^^^^^^^^^^^^^^^^^^^^^^^^^^^^^^^^^^^^^^^^^
  File "C:\Users\Рабочий\Desktop\djangodzr\myproj\myweb\views.py", line 105, in purchased_products
    week_orders = Order.objects.filter(client=request.user, date_created__gte=week_ago)
                  ^^^^^^^^^^^^^^^^^^^^^^^^^^^^^^^^^^^^^^^^^^^^^^^^^^^^^^^^^^^^^^^^^^^^^
  File "C:\Users\Рабочий\Desktop\djangodzr\venv\Lib\site-packages\django\db\models\manager.py", line 87, in manager_method
    return getattr(self.get_queryset(), name)(*args, **kwargs)
           ^^^^^^^^^^^^^^^^^^^^^^^^^^^^^^^^^^^^^^^^^^^^^^^^^^^
  File "C:\Users\Рабочий\Desktop\djangodzr\venv\Lib\site-packages\django\db\models\query.py", line 1476, in filter
    return self._filter_or_exclude(False, args, kwargs)
           ^^^^^^^^^^^^^^^^^^^^^^^^^^^^^^^^^^^^^^^^^^^^
  File "C:\Users\Рабочий\Desktop\djangodzr\venv\Lib\site-packages\django\db\models\query.py", line 1494, in _filter_or_exclude
    clone._filter_or_exclude_inplace(negate, args, kwargs)
  File "C:\Users\Рабочий\Desktop\djangodzr\venv\Lib\site-packages\django\db\models\query.py", line 1501, in _filter_or_exclude_inplace
    self._query.add_q(Q(*args, **kwargs))
  File "C:\Users\Рабочий\Desktop\djangodzr\venv\Lib\site-packages\django\db\models\sql\query.py", line 1613, in add_q
    clause, _ = self._add_q(q_object, self.used_aliases)
                ^^^^^^^^^^^^^^^^^^^^^^^^^^^^^^^^^^^^^^^^
  File "C:\Users\Рабочий\Desktop\djangodzr\venv\Lib\site-packages\django\db\models\sql\query.py", line 1645, in _add_q
    child_clause, needed_inner = self.build_filter(
                                 ^^^^^^^^^^^^^^^^^^
  File "C:\Users\Рабочий\Desktop\djangodzr\venv\Lib\site-packages\django\db\models\sql\query.py", line 1559, in build_filter
    condition = self.build_lookup(lookups, col, value)
                ^^^^^^^^^^^^^^^^^^^^^^^^^^^^^^^^^^^^^^
  File "C:\Users\Рабочий\Desktop\djangodzr\venv\Lib\site-packages\django\db\models\sql\query.py", line 1389, in build_lookup
    lookup = lookup_class(lhs, rhs)
             ^^^^^^^^^^^^^^^^^^^^^^
  File "C:\Users\Рабочий\Desktop\djangodzr\venv\Lib\site-packages\django\db\models\lookups.py", line 30, in __init__
    self.rhs = self.get_prep_lookup()
               ^^^^^^^^^^^^^^^^^^^^^^
  File "C:\Users\Рабочий\Desktop\djangodzr\venv\Lib\site-packages\django\db\models\fields\related_lookups.py", line 156, in get_prep_lookup
    self.rhs = target_field.get_prep_value(self.rhs)
               ^^^^^^^^^^^^^^^^^^^^^^^^^^^^^^^^^^^^^
  File "C:\Users\Рабочий\Desktop\djangodzr\venv\Lib\site-packages\django\db\models\fields\__init__.py", line 2119, in get_prep_value
    raise e.__class__(
TypeError: Field 'id' expected a number but got <SimpleLazyObject: <django.contrib.auth.models.AnonymousUser object at 0x000001EF7C9C2390>>.
ERROR 2024-04-06 12:27:00,343 basehttp 16432 8036 "GET /purchased_products/ HTTP/1.1" 500 131906
ERROR 2024-04-06 12:27:00,515 log 16432 8036 Internal Server Error: /purchased_products/
Traceback (most recent call last):
  File "C:\Users\Рабочий\Desktop\djangodzr\venv\Lib\site-packages\django\db\models\fields\__init__.py", line 2117, in get_prep_value
    return int(value)
           ^^^^^^^^^^
TypeError: int() argument must be a string, a bytes-like object or a real number, not 'SimpleLazyObject'

The above exception was the direct cause of the following exception:

Traceback (most recent call last):
  File "C:\Users\Рабочий\Desktop\djangodzr\venv\Lib\site-packages\django\core\handlers\exception.py", line 55, in inner
    response = get_response(request)
               ^^^^^^^^^^^^^^^^^^^^^
  File "C:\Users\Рабочий\Desktop\djangodzr\venv\Lib\site-packages\django\core\handlers\base.py", line 197, in _get_response
    response = wrapped_callback(request, *callback_args, **callback_kwargs)
               ^^^^^^^^^^^^^^^^^^^^^^^^^^^^^^^^^^^^^^^^^^^^^^^^^^^^^^^^^^^^
  File "C:\Users\Рабочий\Desktop\djangodzr\myproj\myweb\views.py", line 105, in purchased_products
    week_orders = Order.objects.filter(client=request.user, date_created__gte=week_ago)
                  ^^^^^^^^^^^^^^^^^^^^^^^^^^^^^^^^^^^^^^^^^^^^^^^^^^^^^^^^^^^^^^^^^^^^^
  File "C:\Users\Рабочий\Desktop\djangodzr\venv\Lib\site-packages\django\db\models\manager.py", line 87, in manager_method
    return getattr(self.get_queryset(), name)(*args, **kwargs)
           ^^^^^^^^^^^^^^^^^^^^^^^^^^^^^^^^^^^^^^^^^^^^^^^^^^^
  File "C:\Users\Рабочий\Desktop\djangodzr\venv\Lib\site-packages\django\db\models\query.py", line 1476, in filter
    return self._filter_or_exclude(False, args, kwargs)
           ^^^^^^^^^^^^^^^^^^^^^^^^^^^^^^^^^^^^^^^^^^^^
  File "C:\Users\Рабочий\Desktop\djangodzr\venv\Lib\site-packages\django\db\models\query.py", line 1494, in _filter_or_exclude
    clone._filter_or_exclude_inplace(negate, args, kwargs)
  File "C:\Users\Рабочий\Desktop\djangodzr\venv\Lib\site-packages\django\db\models\query.py", line 1501, in _filter_or_exclude_inplace
    self._query.add_q(Q(*args, **kwargs))
  File "C:\Users\Рабочий\Desktop\djangodzr\venv\Lib\site-packages\django\db\models\sql\query.py", line 1613, in add_q
    clause, _ = self._add_q(q_object, self.used_aliases)
                ^^^^^^^^^^^^^^^^^^^^^^^^^^^^^^^^^^^^^^^^
  File "C:\Users\Рабочий\Desktop\djangodzr\venv\Lib\site-packages\django\db\models\sql\query.py", line 1645, in _add_q
    child_clause, needed_inner = self.build_filter(
                                 ^^^^^^^^^^^^^^^^^^
  File "C:\Users\Рабочий\Desktop\djangodzr\venv\Lib\site-packages\django\db\models\sql\query.py", line 1559, in build_filter
    condition = self.build_lookup(lookups, col, value)
                ^^^^^^^^^^^^^^^^^^^^^^^^^^^^^^^^^^^^^^
  File "C:\Users\Рабочий\Desktop\djangodzr\venv\Lib\site-packages\django\db\models\sql\query.py", line 1389, in build_lookup
    lookup = lookup_class(lhs, rhs)
             ^^^^^^^^^^^^^^^^^^^^^^
  File "C:\Users\Рабочий\Desktop\djangodzr\venv\Lib\site-packages\django\db\models\lookups.py", line 30, in __init__
    self.rhs = self.get_prep_lookup()
               ^^^^^^^^^^^^^^^^^^^^^^
  File "C:\Users\Рабочий\Desktop\djangodzr\venv\Lib\site-packages\django\db\models\fields\related_lookups.py", line 156, in get_prep_lookup
    self.rhs = target_field.get_prep_value(self.rhs)
               ^^^^^^^^^^^^^^^^^^^^^^^^^^^^^^^^^^^^^
  File "C:\Users\Рабочий\Desktop\djangodzr\venv\Lib\site-packages\django\db\models\fields\__init__.py", line 2119, in get_prep_value
    raise e.__class__(
TypeError: Field 'id' expected a number but got <SimpleLazyObject: <django.contrib.auth.models.AnonymousUser object at 0x000001EF7C9D72D0>>.
ERROR 2024-04-06 12:27:00,521 basehttp 16432 8036 "GET /purchased_products/ HTTP/1.1" 500 131906
ERROR 2024-04-06 12:27:00,689 log 16432 8036 Internal Server Error: /purchased_products/
Traceback (most recent call last):
  File "C:\Users\Рабочий\Desktop\djangodzr\venv\Lib\site-packages\django\db\models\fields\__init__.py", line 2117, in get_prep_value
    return int(value)
           ^^^^^^^^^^
TypeError: int() argument must be a string, a bytes-like object or a real number, not 'SimpleLazyObject'

The above exception was the direct cause of the following exception:

Traceback (most recent call last):
  File "C:\Users\Рабочий\Desktop\djangodzr\venv\Lib\site-packages\django\core\handlers\exception.py", line 55, in inner
    response = get_response(request)
               ^^^^^^^^^^^^^^^^^^^^^
  File "C:\Users\Рабочий\Desktop\djangodzr\venv\Lib\site-packages\django\core\handlers\base.py", line 197, in _get_response
    response = wrapped_callback(request, *callback_args, **callback_kwargs)
               ^^^^^^^^^^^^^^^^^^^^^^^^^^^^^^^^^^^^^^^^^^^^^^^^^^^^^^^^^^^^
  File "C:\Users\Рабочий\Desktop\djangodzr\myproj\myweb\views.py", line 105, in purchased_products
    week_orders = Order.objects.filter(client=request.user, date_created__gte=week_ago)
                  ^^^^^^^^^^^^^^^^^^^^^^^^^^^^^^^^^^^^^^^^^^^^^^^^^^^^^^^^^^^^^^^^^^^^^
  File "C:\Users\Рабочий\Desktop\djangodzr\venv\Lib\site-packages\django\db\models\manager.py", line 87, in manager_method
    return getattr(self.get_queryset(), name)(*args, **kwargs)
           ^^^^^^^^^^^^^^^^^^^^^^^^^^^^^^^^^^^^^^^^^^^^^^^^^^^
  File "C:\Users\Рабочий\Desktop\djangodzr\venv\Lib\site-packages\django\db\models\query.py", line 1476, in filter
    return self._filter_or_exclude(False, args, kwargs)
           ^^^^^^^^^^^^^^^^^^^^^^^^^^^^^^^^^^^^^^^^^^^^
  File "C:\Users\Рабочий\Desktop\djangodzr\venv\Lib\site-packages\django\db\models\query.py", line 1494, in _filter_or_exclude
    clone._filter_or_exclude_inplace(negate, args, kwargs)
  File "C:\Users\Рабочий\Desktop\djangodzr\venv\Lib\site-packages\django\db\models\query.py", line 1501, in _filter_or_exclude_inplace
    self._query.add_q(Q(*args, **kwargs))
  File "C:\Users\Рабочий\Desktop\djangodzr\venv\Lib\site-packages\django\db\models\sql\query.py", line 1613, in add_q
    clause, _ = self._add_q(q_object, self.used_aliases)
                ^^^^^^^^^^^^^^^^^^^^^^^^^^^^^^^^^^^^^^^^
  File "C:\Users\Рабочий\Desktop\djangodzr\venv\Lib\site-packages\django\db\models\sql\query.py", line 1645, in _add_q
    child_clause, needed_inner = self.build_filter(
                                 ^^^^^^^^^^^^^^^^^^
  File "C:\Users\Рабочий\Desktop\djangodzr\venv\Lib\site-packages\django\db\models\sql\query.py", line 1559, in build_filter
    condition = self.build_lookup(lookups, col, value)
                ^^^^^^^^^^^^^^^^^^^^^^^^^^^^^^^^^^^^^^
  File "C:\Users\Рабочий\Desktop\djangodzr\venv\Lib\site-packages\django\db\models\sql\query.py", line 1389, in build_lookup
    lookup = lookup_class(lhs, rhs)
             ^^^^^^^^^^^^^^^^^^^^^^
  File "C:\Users\Рабочий\Desktop\djangodzr\venv\Lib\site-packages\django\db\models\lookups.py", line 30, in __init__
    self.rhs = self.get_prep_lookup()
               ^^^^^^^^^^^^^^^^^^^^^^
  File "C:\Users\Рабочий\Desktop\djangodzr\venv\Lib\site-packages\django\db\models\fields\related_lookups.py", line 156, in get_prep_lookup
    self.rhs = target_field.get_prep_value(self.rhs)
               ^^^^^^^^^^^^^^^^^^^^^^^^^^^^^^^^^^^^^
  File "C:\Users\Рабочий\Desktop\djangodzr\venv\Lib\site-packages\django\db\models\fields\__init__.py", line 2119, in get_prep_value
    raise e.__class__(
TypeError: Field 'id' expected a number but got <SimpleLazyObject: <django.contrib.auth.models.AnonymousUser object at 0x000001EF7C774910>>.
ERROR 2024-04-06 12:27:00,696 basehttp 16432 8036 "GET /purchased_products/ HTTP/1.1" 500 131906
ERROR 2024-04-06 12:27:00,860 log 16432 8036 Internal Server Error: /purchased_products/
Traceback (most recent call last):
  File "C:\Users\Рабочий\Desktop\djangodzr\venv\Lib\site-packages\django\db\models\fields\__init__.py", line 2117, in get_prep_value
    return int(value)
           ^^^^^^^^^^
TypeError: int() argument must be a string, a bytes-like object or a real number, not 'SimpleLazyObject'

The above exception was the direct cause of the following exception:

Traceback (most recent call last):
  File "C:\Users\Рабочий\Desktop\djangodzr\venv\Lib\site-packages\django\core\handlers\exception.py", line 55, in inner
    response = get_response(request)
               ^^^^^^^^^^^^^^^^^^^^^
  File "C:\Users\Рабочий\Desktop\djangodzr\venv\Lib\site-packages\django\core\handlers\base.py", line 197, in _get_response
    response = wrapped_callback(request, *callback_args, **callback_kwargs)
               ^^^^^^^^^^^^^^^^^^^^^^^^^^^^^^^^^^^^^^^^^^^^^^^^^^^^^^^^^^^^
  File "C:\Users\Рабочий\Desktop\djangodzr\myproj\myweb\views.py", line 105, in purchased_products
    week_orders = Order.objects.filter(client=request.user, date_created__gte=week_ago)
                  ^^^^^^^^^^^^^^^^^^^^^^^^^^^^^^^^^^^^^^^^^^^^^^^^^^^^^^^^^^^^^^^^^^^^^
  File "C:\Users\Рабочий\Desktop\djangodzr\venv\Lib\site-packages\django\db\models\manager.py", line 87, in manager_method
    return getattr(self.get_queryset(), name)(*args, **kwargs)
           ^^^^^^^^^^^^^^^^^^^^^^^^^^^^^^^^^^^^^^^^^^^^^^^^^^^
  File "C:\Users\Рабочий\Desktop\djangodzr\venv\Lib\site-packages\django\db\models\query.py", line 1476, in filter
    return self._filter_or_exclude(False, args, kwargs)
           ^^^^^^^^^^^^^^^^^^^^^^^^^^^^^^^^^^^^^^^^^^^^
  File "C:\Users\Рабочий\Desktop\djangodzr\venv\Lib\site-packages\django\db\models\query.py", line 1494, in _filter_or_exclude
    clone._filter_or_exclude_inplace(negate, args, kwargs)
  File "C:\Users\Рабочий\Desktop\djangodzr\venv\Lib\site-packages\django\db\models\query.py", line 1501, in _filter_or_exclude_inplace
    self._query.add_q(Q(*args, **kwargs))
  File "C:\Users\Рабочий\Desktop\djangodzr\venv\Lib\site-packages\django\db\models\sql\query.py", line 1613, in add_q
    clause, _ = self._add_q(q_object, self.used_aliases)
                ^^^^^^^^^^^^^^^^^^^^^^^^^^^^^^^^^^^^^^^^
  File "C:\Users\Рабочий\Desktop\djangodzr\venv\Lib\site-packages\django\db\models\sql\query.py", line 1645, in _add_q
    child_clause, needed_inner = self.build_filter(
                                 ^^^^^^^^^^^^^^^^^^
  File "C:\Users\Рабочий\Desktop\djangodzr\venv\Lib\site-packages\django\db\models\sql\query.py", line 1559, in build_filter
    condition = self.build_lookup(lookups, col, value)
                ^^^^^^^^^^^^^^^^^^^^^^^^^^^^^^^^^^^^^^
  File "C:\Users\Рабочий\Desktop\djangodzr\venv\Lib\site-packages\django\db\models\sql\query.py", line 1389, in build_lookup
    lookup = lookup_class(lhs, rhs)
             ^^^^^^^^^^^^^^^^^^^^^^
  File "C:\Users\Рабочий\Desktop\djangodzr\venv\Lib\site-packages\django\db\models\lookups.py", line 30, in __init__
    self.rhs = self.get_prep_lookup()
               ^^^^^^^^^^^^^^^^^^^^^^
  File "C:\Users\Рабочий\Desktop\djangodzr\venv\Lib\site-packages\django\db\models\fields\related_lookups.py", line 156, in get_prep_lookup
    self.rhs = target_field.get_prep_value(self.rhs)
               ^^^^^^^^^^^^^^^^^^^^^^^^^^^^^^^^^^^^^
  File "C:\Users\Рабочий\Desktop\djangodzr\venv\Lib\site-packages\django\db\models\fields\__init__.py", line 2119, in get_prep_value
    raise e.__class__(
TypeError: Field 'id' expected a number but got <SimpleLazyObject: <django.contrib.auth.models.AnonymousUser object at 0x000001EF7C9BF1D0>>.
ERROR 2024-04-06 12:27:00,867 basehttp 16432 8036 "GET /purchased_products/ HTTP/1.1" 500 131906
ERROR 2024-04-06 12:27:01,026 log 16432 8036 Internal Server Error: /purchased_products/
Traceback (most recent call last):
  File "C:\Users\Рабочий\Desktop\djangodzr\venv\Lib\site-packages\django\db\models\fields\__init__.py", line 2117, in get_prep_value
    return int(value)
           ^^^^^^^^^^
TypeError: int() argument must be a string, a bytes-like object or a real number, not 'SimpleLazyObject'

The above exception was the direct cause of the following exception:

Traceback (most recent call last):
  File "C:\Users\Рабочий\Desktop\djangodzr\venv\Lib\site-packages\django\core\handlers\exception.py", line 55, in inner
    response = get_response(request)
               ^^^^^^^^^^^^^^^^^^^^^
  File "C:\Users\Рабочий\Desktop\djangodzr\venv\Lib\site-packages\django\core\handlers\base.py", line 197, in _get_response
    response = wrapped_callback(request, *callback_args, **callback_kwargs)
               ^^^^^^^^^^^^^^^^^^^^^^^^^^^^^^^^^^^^^^^^^^^^^^^^^^^^^^^^^^^^
  File "C:\Users\Рабочий\Desktop\djangodzr\myproj\myweb\views.py", line 105, in purchased_products
    week_orders = Order.objects.filter(client=request.user, date_created__gte=week_ago)
                  ^^^^^^^^^^^^^^^^^^^^^^^^^^^^^^^^^^^^^^^^^^^^^^^^^^^^^^^^^^^^^^^^^^^^^
  File "C:\Users\Рабочий\Desktop\djangodzr\venv\Lib\site-packages\django\db\models\manager.py", line 87, in manager_method
    return getattr(self.get_queryset(), name)(*args, **kwargs)
           ^^^^^^^^^^^^^^^^^^^^^^^^^^^^^^^^^^^^^^^^^^^^^^^^^^^
  File "C:\Users\Рабочий\Desktop\djangodzr\venv\Lib\site-packages\django\db\models\query.py", line 1476, in filter
    return self._filter_or_exclude(False, args, kwargs)
           ^^^^^^^^^^^^^^^^^^^^^^^^^^^^^^^^^^^^^^^^^^^^
  File "C:\Users\Рабочий\Desktop\djangodzr\venv\Lib\site-packages\django\db\models\query.py", line 1494, in _filter_or_exclude
    clone._filter_or_exclude_inplace(negate, args, kwargs)
  File "C:\Users\Рабочий\Desktop\djangodzr\venv\Lib\site-packages\django\db\models\query.py", line 1501, in _filter_or_exclude_inplace
    self._query.add_q(Q(*args, **kwargs))
  File "C:\Users\Рабочий\Desktop\djangodzr\venv\Lib\site-packages\django\db\models\sql\query.py", line 1613, in add_q
    clause, _ = self._add_q(q_object, self.used_aliases)
                ^^^^^^^^^^^^^^^^^^^^^^^^^^^^^^^^^^^^^^^^
  File "C:\Users\Рабочий\Desktop\djangodzr\venv\Lib\site-packages\django\db\models\sql\query.py", line 1645, in _add_q
    child_clause, needed_inner = self.build_filter(
                                 ^^^^^^^^^^^^^^^^^^
  File "C:\Users\Рабочий\Desktop\djangodzr\venv\Lib\site-packages\django\db\models\sql\query.py", line 1559, in build_filter
    condition = self.build_lookup(lookups, col, value)
                ^^^^^^^^^^^^^^^^^^^^^^^^^^^^^^^^^^^^^^
  File "C:\Users\Рабочий\Desktop\djangodzr\venv\Lib\site-packages\django\db\models\sql\query.py", line 1389, in build_lookup
    lookup = lookup_class(lhs, rhs)
             ^^^^^^^^^^^^^^^^^^^^^^
  File "C:\Users\Рабочий\Desktop\djangodzr\venv\Lib\site-packages\django\db\models\lookups.py", line 30, in __init__
    self.rhs = self.get_prep_lookup()
               ^^^^^^^^^^^^^^^^^^^^^^
  File "C:\Users\Рабочий\Desktop\djangodzr\venv\Lib\site-packages\django\db\models\fields\related_lookups.py", line 156, in get_prep_lookup
    self.rhs = target_field.get_prep_value(self.rhs)
               ^^^^^^^^^^^^^^^^^^^^^^^^^^^^^^^^^^^^^
  File "C:\Users\Рабочий\Desktop\djangodzr\venv\Lib\site-packages\django\db\models\fields\__init__.py", line 2119, in get_prep_value
    raise e.__class__(
TypeError: Field 'id' expected a number but got <SimpleLazyObject: <django.contrib.auth.models.AnonymousUser object at 0x000001EF7C9B4B90>>.
ERROR 2024-04-06 12:27:01,033 basehttp 16432 8036 "GET /purchased_products/ HTTP/1.1" 500 131906
ERROR 2024-04-06 12:27:01,183 log 16432 8036 Internal Server Error: /purchased_products/
Traceback (most recent call last):
  File "C:\Users\Рабочий\Desktop\djangodzr\venv\Lib\site-packages\django\db\models\fields\__init__.py", line 2117, in get_prep_value
    return int(value)
           ^^^^^^^^^^
TypeError: int() argument must be a string, a bytes-like object or a real number, not 'SimpleLazyObject'

The above exception was the direct cause of the following exception:

Traceback (most recent call last):
  File "C:\Users\Рабочий\Desktop\djangodzr\venv\Lib\site-packages\django\core\handlers\exception.py", line 55, in inner
    response = get_response(request)
               ^^^^^^^^^^^^^^^^^^^^^
  File "C:\Users\Рабочий\Desktop\djangodzr\venv\Lib\site-packages\django\core\handlers\base.py", line 197, in _get_response
    response = wrapped_callback(request, *callback_args, **callback_kwargs)
               ^^^^^^^^^^^^^^^^^^^^^^^^^^^^^^^^^^^^^^^^^^^^^^^^^^^^^^^^^^^^
  File "C:\Users\Рабочий\Desktop\djangodzr\myproj\myweb\views.py", line 105, in purchased_products
    week_orders = Order.objects.filter(client=request.user, date_created__gte=week_ago)
                  ^^^^^^^^^^^^^^^^^^^^^^^^^^^^^^^^^^^^^^^^^^^^^^^^^^^^^^^^^^^^^^^^^^^^^
  File "C:\Users\Рабочий\Desktop\djangodzr\venv\Lib\site-packages\django\db\models\manager.py", line 87, in manager_method
    return getattr(self.get_queryset(), name)(*args, **kwargs)
           ^^^^^^^^^^^^^^^^^^^^^^^^^^^^^^^^^^^^^^^^^^^^^^^^^^^
  File "C:\Users\Рабочий\Desktop\djangodzr\venv\Lib\site-packages\django\db\models\query.py", line 1476, in filter
    return self._filter_or_exclude(False, args, kwargs)
           ^^^^^^^^^^^^^^^^^^^^^^^^^^^^^^^^^^^^^^^^^^^^
  File "C:\Users\Рабочий\Desktop\djangodzr\venv\Lib\site-packages\django\db\models\query.py", line 1494, in _filter_or_exclude
    clone._filter_or_exclude_inplace(negate, args, kwargs)
  File "C:\Users\Рабочий\Desktop\djangodzr\venv\Lib\site-packages\django\db\models\query.py", line 1501, in _filter_or_exclude_inplace
    self._query.add_q(Q(*args, **kwargs))
  File "C:\Users\Рабочий\Desktop\djangodzr\venv\Lib\site-packages\django\db\models\sql\query.py", line 1613, in add_q
    clause, _ = self._add_q(q_object, self.used_aliases)
                ^^^^^^^^^^^^^^^^^^^^^^^^^^^^^^^^^^^^^^^^
  File "C:\Users\Рабочий\Desktop\djangodzr\venv\Lib\site-packages\django\db\models\sql\query.py", line 1645, in _add_q
    child_clause, needed_inner = self.build_filter(
                                 ^^^^^^^^^^^^^^^^^^
  File "C:\Users\Рабочий\Desktop\djangodzr\venv\Lib\site-packages\django\db\models\sql\query.py", line 1559, in build_filter
    condition = self.build_lookup(lookups, col, value)
                ^^^^^^^^^^^^^^^^^^^^^^^^^^^^^^^^^^^^^^
  File "C:\Users\Рабочий\Desktop\djangodzr\venv\Lib\site-packages\django\db\models\sql\query.py", line 1389, in build_lookup
    lookup = lookup_class(lhs, rhs)
             ^^^^^^^^^^^^^^^^^^^^^^
  File "C:\Users\Рабочий\Desktop\djangodzr\venv\Lib\site-packages\django\db\models\lookups.py", line 30, in __init__
    self.rhs = self.get_prep_lookup()
               ^^^^^^^^^^^^^^^^^^^^^^
  File "C:\Users\Рабочий\Desktop\djangodzr\venv\Lib\site-packages\django\db\models\fields\related_lookups.py", line 156, in get_prep_lookup
    self.rhs = target_field.get_prep_value(self.rhs)
               ^^^^^^^^^^^^^^^^^^^^^^^^^^^^^^^^^^^^^
  File "C:\Users\Рабочий\Desktop\djangodzr\venv\Lib\site-packages\django\db\models\fields\__init__.py", line 2119, in get_prep_value
    raise e.__class__(
TypeError: Field 'id' expected a number but got <SimpleLazyObject: <django.contrib.auth.models.AnonymousUser object at 0x000001EF7C9BBE50>>.
ERROR 2024-04-06 12:27:01,190 basehttp 16432 8036 "GET /purchased_products/ HTTP/1.1" 500 131906
ERROR 2024-04-06 12:27:01,637 log 16432 8036 Internal Server Error: /purchased_products/
Traceback (most recent call last):
  File "C:\Users\Рабочий\Desktop\djangodzr\venv\Lib\site-packages\django\db\models\fields\__init__.py", line 2117, in get_prep_value
    return int(value)
           ^^^^^^^^^^
TypeError: int() argument must be a string, a bytes-like object or a real number, not 'SimpleLazyObject'

The above exception was the direct cause of the following exception:

Traceback (most recent call last):
  File "C:\Users\Рабочий\Desktop\djangodzr\venv\Lib\site-packages\django\core\handlers\exception.py", line 55, in inner
    response = get_response(request)
               ^^^^^^^^^^^^^^^^^^^^^
  File "C:\Users\Рабочий\Desktop\djangodzr\venv\Lib\site-packages\django\core\handlers\base.py", line 197, in _get_response
    response = wrapped_callback(request, *callback_args, **callback_kwargs)
               ^^^^^^^^^^^^^^^^^^^^^^^^^^^^^^^^^^^^^^^^^^^^^^^^^^^^^^^^^^^^
  File "C:\Users\Рабочий\Desktop\djangodzr\myproj\myweb\views.py", line 105, in purchased_products
    week_orders = Order.objects.filter(client=request.user, date_created__gte=week_ago)
                  ^^^^^^^^^^^^^^^^^^^^^^^^^^^^^^^^^^^^^^^^^^^^^^^^^^^^^^^^^^^^^^^^^^^^^
  File "C:\Users\Рабочий\Desktop\djangodzr\venv\Lib\site-packages\django\db\models\manager.py", line 87, in manager_method
    return getattr(self.get_queryset(), name)(*args, **kwargs)
           ^^^^^^^^^^^^^^^^^^^^^^^^^^^^^^^^^^^^^^^^^^^^^^^^^^^
  File "C:\Users\Рабочий\Desktop\djangodzr\venv\Lib\site-packages\django\db\models\query.py", line 1476, in filter
    return self._filter_or_exclude(False, args, kwargs)
           ^^^^^^^^^^^^^^^^^^^^^^^^^^^^^^^^^^^^^^^^^^^^
  File "C:\Users\Рабочий\Desktop\djangodzr\venv\Lib\site-packages\django\db\models\query.py", line 1494, in _filter_or_exclude
    clone._filter_or_exclude_inplace(negate, args, kwargs)
  File "C:\Users\Рабочий\Desktop\djangodzr\venv\Lib\site-packages\django\db\models\query.py", line 1501, in _filter_or_exclude_inplace
    self._query.add_q(Q(*args, **kwargs))
  File "C:\Users\Рабочий\Desktop\djangodzr\venv\Lib\site-packages\django\db\models\sql\query.py", line 1613, in add_q
    clause, _ = self._add_q(q_object, self.used_aliases)
                ^^^^^^^^^^^^^^^^^^^^^^^^^^^^^^^^^^^^^^^^
  File "C:\Users\Рабочий\Desktop\djangodzr\venv\Lib\site-packages\django\db\models\sql\query.py", line 1645, in _add_q
    child_clause, needed_inner = self.build_filter(
                                 ^^^^^^^^^^^^^^^^^^
  File "C:\Users\Рабочий\Desktop\djangodzr\venv\Lib\site-packages\django\db\models\sql\query.py", line 1559, in build_filter
    condition = self.build_lookup(lookups, col, value)
                ^^^^^^^^^^^^^^^^^^^^^^^^^^^^^^^^^^^^^^
  File "C:\Users\Рабочий\Desktop\djangodzr\venv\Lib\site-packages\django\db\models\sql\query.py", line 1389, in build_lookup
    lookup = lookup_class(lhs, rhs)
             ^^^^^^^^^^^^^^^^^^^^^^
  File "C:\Users\Рабочий\Desktop\djangodzr\venv\Lib\site-packages\django\db\models\lookups.py", line 30, in __init__
    self.rhs = self.get_prep_lookup()
               ^^^^^^^^^^^^^^^^^^^^^^
  File "C:\Users\Рабочий\Desktop\djangodzr\venv\Lib\site-packages\django\db\models\fields\related_lookups.py", line 156, in get_prep_lookup
    self.rhs = target_field.get_prep_value(self.rhs)
               ^^^^^^^^^^^^^^^^^^^^^^^^^^^^^^^^^^^^^
  File "C:\Users\Рабочий\Desktop\djangodzr\venv\Lib\site-packages\django\db\models\fields\__init__.py", line 2119, in get_prep_value
    raise e.__class__(
TypeError: Field 'id' expected a number but got <SimpleLazyObject: <django.contrib.auth.models.AnonymousUser object at 0x000001EF7CA32290>>.
ERROR 2024-04-06 12:27:01,643 basehttp 16432 8036 "GET /purchased_products/ HTTP/1.1" 500 131906
ERROR 2024-04-06 12:27:01,809 log 16432 8036 Internal Server Error: /purchased_products/
Traceback (most recent call last):
  File "C:\Users\Рабочий\Desktop\djangodzr\venv\Lib\site-packages\django\db\models\fields\__init__.py", line 2117, in get_prep_value
    return int(value)
           ^^^^^^^^^^
TypeError: int() argument must be a string, a bytes-like object or a real number, not 'SimpleLazyObject'

The above exception was the direct cause of the following exception:

Traceback (most recent call last):
  File "C:\Users\Рабочий\Desktop\djangodzr\venv\Lib\site-packages\django\core\handlers\exception.py", line 55, in inner
    response = get_response(request)
               ^^^^^^^^^^^^^^^^^^^^^
  File "C:\Users\Рабочий\Desktop\djangodzr\venv\Lib\site-packages\django\core\handlers\base.py", line 197, in _get_response
    response = wrapped_callback(request, *callback_args, **callback_kwargs)
               ^^^^^^^^^^^^^^^^^^^^^^^^^^^^^^^^^^^^^^^^^^^^^^^^^^^^^^^^^^^^
  File "C:\Users\Рабочий\Desktop\djangodzr\myproj\myweb\views.py", line 105, in purchased_products
    week_orders = Order.objects.filter(client=request.user, date_created__gte=week_ago)
                  ^^^^^^^^^^^^^^^^^^^^^^^^^^^^^^^^^^^^^^^^^^^^^^^^^^^^^^^^^^^^^^^^^^^^^
  File "C:\Users\Рабочий\Desktop\djangodzr\venv\Lib\site-packages\django\db\models\manager.py", line 87, in manager_method
    return getattr(self.get_queryset(), name)(*args, **kwargs)
           ^^^^^^^^^^^^^^^^^^^^^^^^^^^^^^^^^^^^^^^^^^^^^^^^^^^
  File "C:\Users\Рабочий\Desktop\djangodzr\venv\Lib\site-packages\django\db\models\query.py", line 1476, in filter
    return self._filter_or_exclude(False, args, kwargs)
           ^^^^^^^^^^^^^^^^^^^^^^^^^^^^^^^^^^^^^^^^^^^^
  File "C:\Users\Рабочий\Desktop\djangodzr\venv\Lib\site-packages\django\db\models\query.py", line 1494, in _filter_or_exclude
    clone._filter_or_exclude_inplace(negate, args, kwargs)
  File "C:\Users\Рабочий\Desktop\djangodzr\venv\Lib\site-packages\django\db\models\query.py", line 1501, in _filter_or_exclude_inplace
    self._query.add_q(Q(*args, **kwargs))
  File "C:\Users\Рабочий\Desktop\djangodzr\venv\Lib\site-packages\django\db\models\sql\query.py", line 1613, in add_q
    clause, _ = self._add_q(q_object, self.used_aliases)
                ^^^^^^^^^^^^^^^^^^^^^^^^^^^^^^^^^^^^^^^^
  File "C:\Users\Рабочий\Desktop\djangodzr\venv\Lib\site-packages\django\db\models\sql\query.py", line 1645, in _add_q
    child_clause, needed_inner = self.build_filter(
                                 ^^^^^^^^^^^^^^^^^^
  File "C:\Users\Рабочий\Desktop\djangodzr\venv\Lib\site-packages\django\db\models\sql\query.py", line 1559, in build_filter
    condition = self.build_lookup(lookups, col, value)
                ^^^^^^^^^^^^^^^^^^^^^^^^^^^^^^^^^^^^^^
  File "C:\Users\Рабочий\Desktop\djangodzr\venv\Lib\site-packages\django\db\models\sql\query.py", line 1389, in build_lookup
    lookup = lookup_class(lhs, rhs)
             ^^^^^^^^^^^^^^^^^^^^^^
  File "C:\Users\Рабочий\Desktop\djangodzr\venv\Lib\site-packages\django\db\models\lookups.py", line 30, in __init__
    self.rhs = self.get_prep_lookup()
               ^^^^^^^^^^^^^^^^^^^^^^
  File "C:\Users\Рабочий\Desktop\djangodzr\venv\Lib\site-packages\django\db\models\fields\related_lookups.py", line 156, in get_prep_lookup
    self.rhs = target_field.get_prep_value(self.rhs)
               ^^^^^^^^^^^^^^^^^^^^^^^^^^^^^^^^^^^^^
  File "C:\Users\Рабочий\Desktop\djangodzr\venv\Lib\site-packages\django\db\models\fields\__init__.py", line 2119, in get_prep_value
    raise e.__class__(
TypeError: Field 'id' expected a number but got <SimpleLazyObject: <django.contrib.auth.models.AnonymousUser object at 0x000001EF7CA19310>>.
ERROR 2024-04-06 12:27:01,816 basehttp 16432 8036 "GET /purchased_products/ HTTP/1.1" 500 131906
ERROR 2024-04-06 12:27:01,980 log 16432 8036 Internal Server Error: /purchased_products/
Traceback (most recent call last):
  File "C:\Users\Рабочий\Desktop\djangodzr\venv\Lib\site-packages\django\db\models\fields\__init__.py", line 2117, in get_prep_value
    return int(value)
           ^^^^^^^^^^
TypeError: int() argument must be a string, a bytes-like object or a real number, not 'SimpleLazyObject'

The above exception was the direct cause of the following exception:

Traceback (most recent call last):
  File "C:\Users\Рабочий\Desktop\djangodzr\venv\Lib\site-packages\django\core\handlers\exception.py", line 55, in inner
    response = get_response(request)
               ^^^^^^^^^^^^^^^^^^^^^
  File "C:\Users\Рабочий\Desktop\djangodzr\venv\Lib\site-packages\django\core\handlers\base.py", line 197, in _get_response
    response = wrapped_callback(request, *callback_args, **callback_kwargs)
               ^^^^^^^^^^^^^^^^^^^^^^^^^^^^^^^^^^^^^^^^^^^^^^^^^^^^^^^^^^^^
  File "C:\Users\Рабочий\Desktop\djangodzr\myproj\myweb\views.py", line 105, in purchased_products
    week_orders = Order.objects.filter(client=request.user, date_created__gte=week_ago)
                  ^^^^^^^^^^^^^^^^^^^^^^^^^^^^^^^^^^^^^^^^^^^^^^^^^^^^^^^^^^^^^^^^^^^^^
  File "C:\Users\Рабочий\Desktop\djangodzr\venv\Lib\site-packages\django\db\models\manager.py", line 87, in manager_method
    return getattr(self.get_queryset(), name)(*args, **kwargs)
           ^^^^^^^^^^^^^^^^^^^^^^^^^^^^^^^^^^^^^^^^^^^^^^^^^^^
  File "C:\Users\Рабочий\Desktop\djangodzr\venv\Lib\site-packages\django\db\models\query.py", line 1476, in filter
    return self._filter_or_exclude(False, args, kwargs)
           ^^^^^^^^^^^^^^^^^^^^^^^^^^^^^^^^^^^^^^^^^^^^
  File "C:\Users\Рабочий\Desktop\djangodzr\venv\Lib\site-packages\django\db\models\query.py", line 1494, in _filter_or_exclude
    clone._filter_or_exclude_inplace(negate, args, kwargs)
  File "C:\Users\Рабочий\Desktop\djangodzr\venv\Lib\site-packages\django\db\models\query.py", line 1501, in _filter_or_exclude_inplace
    self._query.add_q(Q(*args, **kwargs))
  File "C:\Users\Рабочий\Desktop\djangodzr\venv\Lib\site-packages\django\db\models\sql\query.py", line 1613, in add_q
    clause, _ = self._add_q(q_object, self.used_aliases)
                ^^^^^^^^^^^^^^^^^^^^^^^^^^^^^^^^^^^^^^^^
  File "C:\Users\Рабочий\Desktop\djangodzr\venv\Lib\site-packages\django\db\models\sql\query.py", line 1645, in _add_q
    child_clause, needed_inner = self.build_filter(
                                 ^^^^^^^^^^^^^^^^^^
  File "C:\Users\Рабочий\Desktop\djangodzr\venv\Lib\site-packages\django\db\models\sql\query.py", line 1559, in build_filter
    condition = self.build_lookup(lookups, col, value)
                ^^^^^^^^^^^^^^^^^^^^^^^^^^^^^^^^^^^^^^
  File "C:\Users\Рабочий\Desktop\djangodzr\venv\Lib\site-packages\django\db\models\sql\query.py", line 1389, in build_lookup
    lookup = lookup_class(lhs, rhs)
             ^^^^^^^^^^^^^^^^^^^^^^
  File "C:\Users\Рабочий\Desktop\djangodzr\venv\Lib\site-packages\django\db\models\lookups.py", line 30, in __init__
    self.rhs = self.get_prep_lookup()
               ^^^^^^^^^^^^^^^^^^^^^^
  File "C:\Users\Рабочий\Desktop\djangodzr\venv\Lib\site-packages\django\db\models\fields\related_lookups.py", line 156, in get_prep_lookup
    self.rhs = target_field.get_prep_value(self.rhs)
               ^^^^^^^^^^^^^^^^^^^^^^^^^^^^^^^^^^^^^
  File "C:\Users\Рабочий\Desktop\djangodzr\venv\Lib\site-packages\django\db\models\fields\__init__.py", line 2119, in get_prep_value
    raise e.__class__(
TypeError: Field 'id' expected a number but got <SimpleLazyObject: <django.contrib.auth.models.AnonymousUser object at 0x000001EF7C9C81D0>>.
ERROR 2024-04-06 12:27:01,987 basehttp 16432 8036 "GET /purchased_products/ HTTP/1.1" 500 131906
INFO 2024-04-06 12:27:16,958 autoreload 24044 16672 Watching for file changes with StatReloader
WARNING 2024-04-06 12:27:23,752 log 24044 3216 Not Found: /
WARNING 2024-04-06 12:27:23,753 basehttp 24044 3216 "GET / HTTP/1.1" 404 2951
ERROR 2024-04-06 12:27:33,359 log 24044 3216 Internal Server Error: /purchased_products/
Traceback (most recent call last):
  File "C:\Users\Рабочий\Desktop\djangodzr\venv\Lib\site-packages\django\db\models\fields\__init__.py", line 2117, in get_prep_value
    return int(value)
           ^^^^^^^^^^
TypeError: int() argument must be a string, a bytes-like object or a real number, not 'SimpleLazyObject'

The above exception was the direct cause of the following exception:

Traceback (most recent call last):
  File "C:\Users\Рабочий\Desktop\djangodzr\venv\Lib\site-packages\django\core\handlers\exception.py", line 55, in inner
    response = get_response(request)
               ^^^^^^^^^^^^^^^^^^^^^
  File "C:\Users\Рабочий\Desktop\djangodzr\venv\Lib\site-packages\django\core\handlers\base.py", line 197, in _get_response
    response = wrapped_callback(request, *callback_args, **callback_kwargs)
               ^^^^^^^^^^^^^^^^^^^^^^^^^^^^^^^^^^^^^^^^^^^^^^^^^^^^^^^^^^^^
  File "C:\Users\Рабочий\Desktop\djangodzr\myproj\myweb\views.py", line 105, in purchased_products
    week_orders = Order.objects.filter(client=request.user, date_created__gte=week_ago)
                  ^^^^^^^^^^^^^^^^^^^^^^^^^^^^^^^^^^^^^^^^^^^^^^^^^^^^^^^^^^^^^^^^^^^^^
  File "C:\Users\Рабочий\Desktop\djangodzr\venv\Lib\site-packages\django\db\models\manager.py", line 87, in manager_method
    return getattr(self.get_queryset(), name)(*args, **kwargs)
           ^^^^^^^^^^^^^^^^^^^^^^^^^^^^^^^^^^^^^^^^^^^^^^^^^^^
  File "C:\Users\Рабочий\Desktop\djangodzr\venv\Lib\site-packages\django\db\models\query.py", line 1476, in filter
    return self._filter_or_exclude(False, args, kwargs)
           ^^^^^^^^^^^^^^^^^^^^^^^^^^^^^^^^^^^^^^^^^^^^
  File "C:\Users\Рабочий\Desktop\djangodzr\venv\Lib\site-packages\django\db\models\query.py", line 1494, in _filter_or_exclude
    clone._filter_or_exclude_inplace(negate, args, kwargs)
  File "C:\Users\Рабочий\Desktop\djangodzr\venv\Lib\site-packages\django\db\models\query.py", line 1501, in _filter_or_exclude_inplace
    self._query.add_q(Q(*args, **kwargs))
  File "C:\Users\Рабочий\Desktop\djangodzr\venv\Lib\site-packages\django\db\models\sql\query.py", line 1613, in add_q
    clause, _ = self._add_q(q_object, self.used_aliases)
                ^^^^^^^^^^^^^^^^^^^^^^^^^^^^^^^^^^^^^^^^
  File "C:\Users\Рабочий\Desktop\djangodzr\venv\Lib\site-packages\django\db\models\sql\query.py", line 1645, in _add_q
    child_clause, needed_inner = self.build_filter(
                                 ^^^^^^^^^^^^^^^^^^
  File "C:\Users\Рабочий\Desktop\djangodzr\venv\Lib\site-packages\django\db\models\sql\query.py", line 1559, in build_filter
    condition = self.build_lookup(lookups, col, value)
                ^^^^^^^^^^^^^^^^^^^^^^^^^^^^^^^^^^^^^^
  File "C:\Users\Рабочий\Desktop\djangodzr\venv\Lib\site-packages\django\db\models\sql\query.py", line 1389, in build_lookup
    lookup = lookup_class(lhs, rhs)
             ^^^^^^^^^^^^^^^^^^^^^^
  File "C:\Users\Рабочий\Desktop\djangodzr\venv\Lib\site-packages\django\db\models\lookups.py", line 30, in __init__
    self.rhs = self.get_prep_lookup()
               ^^^^^^^^^^^^^^^^^^^^^^
  File "C:\Users\Рабочий\Desktop\djangodzr\venv\Lib\site-packages\django\db\models\fields\related_lookups.py", line 156, in get_prep_lookup
    self.rhs = target_field.get_prep_value(self.rhs)
               ^^^^^^^^^^^^^^^^^^^^^^^^^^^^^^^^^^^^^
  File "C:\Users\Рабочий\Desktop\djangodzr\venv\Lib\site-packages\django\db\models\fields\__init__.py", line 2119, in get_prep_value
    raise e.__class__(
TypeError: Field 'id' expected a number but got <SimpleLazyObject: <django.contrib.auth.models.AnonymousUser object at 0x00000190CA1C0350>>.
ERROR 2024-04-06 12:27:33,368 basehttp 24044 3216 "GET /purchased_products/ HTTP/1.1" 500 131778
INFO 2024-04-06 12:31:13,066 autoreload 24044 16672 C:\Users\Рабочий\Desktop\djangodzr\myproj\myweb\views.py changed, reloading.
INFO 2024-04-06 12:31:13,587 autoreload 17580 8600 Watching for file changes with StatReloader
ERROR 2024-04-06 12:31:14,839 log 17580 19048 Internal Server Error: /purchased_products/
Traceback (most recent call last):
  File "C:\Users\Рабочий\Desktop\djangodzr\venv\Lib\site-packages\django\core\handlers\exception.py", line 55, in inner
    response = get_response(request)
               ^^^^^^^^^^^^^^^^^^^^^
  File "C:\Users\Рабочий\Desktop\djangodzr\venv\Lib\site-packages\django\core\handlers\base.py", line 197, in _get_response
    response = wrapped_callback(request, *callback_args, **callback_kwargs)
               ^^^^^^^^^^^^^^^^^^^^^^^^^^^^^^^^^^^^^^^^^^^^^^^^^^^^^^^^^^^^
  File "C:\Users\Рабочий\Desktop\djangodzr\myproj\myweb\views.py", line 105, in purchased_products
    user = request.user.get()
           ^^^^^^^^^^^^^^^^
  File "C:\Users\Рабочий\Desktop\djangodzr\venv\Lib\site-packages\django\utils\functional.py", line 253, in inner
    return func(_wrapped, *args)
           ^^^^^^^^^^^^^^^^^^^^^
AttributeError: 'AnonymousUser' object has no attribute 'get'
ERROR 2024-04-06 12:31:14,841 basehttp 17580 19048 "GET /purchased_products/ HTTP/1.1" 500 73834
INFO 2024-04-06 12:31:45,272 autoreload 15240 10300 Watching for file changes with StatReloader
ERROR 2024-04-06 12:31:54,564 log 15240 18376 Internal Server Error: /purchased_products/
Traceback (most recent call last):
  File "C:\Users\Рабочий\Desktop\djangodzr\venv\Lib\site-packages\django\core\handlers\exception.py", line 55, in inner
    response = get_response(request)
               ^^^^^^^^^^^^^^^^^^^^^
  File "C:\Users\Рабочий\Desktop\djangodzr\venv\Lib\site-packages\django\core\handlers\base.py", line 197, in _get_response
    response = wrapped_callback(request, *callback_args, **callback_kwargs)
               ^^^^^^^^^^^^^^^^^^^^^^^^^^^^^^^^^^^^^^^^^^^^^^^^^^^^^^^^^^^^
  File "C:\Users\Рабочий\Desktop\djangodzr\myproj\myweb\views.py", line 105, in purchased_products
    user = request.user.get()
           ^^^^^^^^^^^^^^^^
  File "C:\Users\Рабочий\Desktop\djangodzr\venv\Lib\site-packages\django\utils\functional.py", line 253, in inner
    return func(_wrapped, *args)
           ^^^^^^^^^^^^^^^^^^^^^
AttributeError: 'AnonymousUser' object has no attribute 'get'
ERROR 2024-04-06 12:31:54,566 basehttp 15240 18376 "GET /purchased_products/ HTTP/1.1" 500 73834
INFO 2024-04-06 12:32:45,871 autoreload 15240 10300 C:\Users\Рабочий\Desktop\djangodzr\myproj\myweb\views.py changed, reloading.
INFO 2024-04-06 12:32:46,511 autoreload 15696 16168 Watching for file changes with StatReloader
WARNING 2024-04-06 12:32:49,733 log 15696 9164 Unauthorized: /purchased_products/
WARNING 2024-04-06 12:32:49,733 basehttp 15696 9164 "GET /purchased_products/ HTTP/1.1" 401 12
INFO 2024-04-06 12:34:49,272 autoreload 15696 16168 C:\Users\Рабочий\Desktop\djangodzr\myproj\myweb\views.py changed, reloading.
INFO 2024-04-06 12:34:49,779 autoreload 15644 19260 Watching for file changes with StatReloader
ERROR 2024-04-06 12:35:12,088 log 15644 12612 Internal Server Error: /purchased_products/
Traceback (most recent call last):
  File "C:\Users\Рабочий\Desktop\djangodzr\venv\Lib\site-packages\django\db\models\fields\__init__.py", line 2117, in get_prep_value
    return int(value)
           ^^^^^^^^^^
TypeError: int() argument must be a string, a bytes-like object or a real number, not 'SimpleLazyObject'

The above exception was the direct cause of the following exception:

Traceback (most recent call last):
  File "C:\Users\Рабочий\Desktop\djangodzr\venv\Lib\site-packages\django\core\handlers\exception.py", line 55, in inner
    response = get_response(request)
               ^^^^^^^^^^^^^^^^^^^^^
  File "C:\Users\Рабочий\Desktop\djangodzr\venv\Lib\site-packages\django\core\handlers\base.py", line 197, in _get_response
    response = wrapped_callback(request, *callback_args, **callback_kwargs)
               ^^^^^^^^^^^^^^^^^^^^^^^^^^^^^^^^^^^^^^^^^^^^^^^^^^^^^^^^^^^^
  File "C:\Users\Рабочий\Desktop\djangodzr\myproj\myweb\views.py", line 105, in purchased_products
    week_orders = Order.objects.filter(client=request.user, date_created__gte=week_ago)
                  ^^^^^^^^^^^^^^^^^^^^^^^^^^^^^^^^^^^^^^^^^^^^^^^^^^^^^^^^^^^^^^^^^^^^^
  File "C:\Users\Рабочий\Desktop\djangodzr\venv\Lib\site-packages\django\db\models\manager.py", line 87, in manager_method
    return getattr(self.get_queryset(), name)(*args, **kwargs)
           ^^^^^^^^^^^^^^^^^^^^^^^^^^^^^^^^^^^^^^^^^^^^^^^^^^^
  File "C:\Users\Рабочий\Desktop\djangodzr\venv\Lib\site-packages\django\db\models\query.py", line 1476, in filter
    return self._filter_or_exclude(False, args, kwargs)
           ^^^^^^^^^^^^^^^^^^^^^^^^^^^^^^^^^^^^^^^^^^^^
  File "C:\Users\Рабочий\Desktop\djangodzr\venv\Lib\site-packages\django\db\models\query.py", line 1494, in _filter_or_exclude
    clone._filter_or_exclude_inplace(negate, args, kwargs)
  File "C:\Users\Рабочий\Desktop\djangodzr\venv\Lib\site-packages\django\db\models\query.py", line 1501, in _filter_or_exclude_inplace
    self._query.add_q(Q(*args, **kwargs))
  File "C:\Users\Рабочий\Desktop\djangodzr\venv\Lib\site-packages\django\db\models\sql\query.py", line 1613, in add_q
    clause, _ = self._add_q(q_object, self.used_aliases)
                ^^^^^^^^^^^^^^^^^^^^^^^^^^^^^^^^^^^^^^^^
  File "C:\Users\Рабочий\Desktop\djangodzr\venv\Lib\site-packages\django\db\models\sql\query.py", line 1645, in _add_q
    child_clause, needed_inner = self.build_filter(
                                 ^^^^^^^^^^^^^^^^^^
  File "C:\Users\Рабочий\Desktop\djangodzr\venv\Lib\site-packages\django\db\models\sql\query.py", line 1559, in build_filter
    condition = self.build_lookup(lookups, col, value)
                ^^^^^^^^^^^^^^^^^^^^^^^^^^^^^^^^^^^^^^
  File "C:\Users\Рабочий\Desktop\djangodzr\venv\Lib\site-packages\django\db\models\sql\query.py", line 1389, in build_lookup
    lookup = lookup_class(lhs, rhs)
             ^^^^^^^^^^^^^^^^^^^^^^
  File "C:\Users\Рабочий\Desktop\djangodzr\venv\Lib\site-packages\django\db\models\lookups.py", line 30, in __init__
    self.rhs = self.get_prep_lookup()
               ^^^^^^^^^^^^^^^^^^^^^^
  File "C:\Users\Рабочий\Desktop\djangodzr\venv\Lib\site-packages\django\db\models\fields\related_lookups.py", line 156, in get_prep_lookup
    self.rhs = target_field.get_prep_value(self.rhs)
               ^^^^^^^^^^^^^^^^^^^^^^^^^^^^^^^^^^^^^
  File "C:\Users\Рабочий\Desktop\djangodzr\venv\Lib\site-packages\django\db\models\fields\__init__.py", line 2119, in get_prep_value
    raise e.__class__(
TypeError: Field 'id' expected a number but got <SimpleLazyObject: <django.contrib.auth.models.AnonymousUser object at 0x00000234D5BCCA10>>.
ERROR 2024-04-06 12:35:12,095 basehttp 15644 12612 "GET /purchased_products/ HTTP/1.1" 500 131957
INFO 2024-04-06 12:36:10,758 autoreload 15644 19260 C:\Users\Рабочий\Desktop\djangodzr\myproj\myweb\views.py changed, reloading.
INFO 2024-04-06 12:36:11,273 autoreload 8844 24684 Watching for file changes with StatReloader
ERROR 2024-04-06 12:36:11,949 log 8844 17388 Internal Server Error: /purchased_products/
Traceback (most recent call last):
  File "C:\Users\Рабочий\Desktop\djangodzr\venv\Lib\site-packages\django\core\handlers\exception.py", line 55, in inner
    response = get_response(request)
               ^^^^^^^^^^^^^^^^^^^^^
  File "C:\Users\Рабочий\Desktop\djangodzr\venv\Lib\site-packages\django\core\handlers\base.py", line 197, in _get_response
    response = wrapped_callback(request, *callback_args, **callback_kwargs)
               ^^^^^^^^^^^^^^^^^^^^^^^^^^^^^^^^^^^^^^^^^^^^^^^^^^^^^^^^^^^^
  File "C:\Users\Рабочий\Desktop\djangodzr\myproj\myweb\views.py", line 105, in purchased_products
    week_orders = Order.objects.filter(client=request.user.id, date_created__gte=week_ago)
                  ^^^^^^^^^^^^^^^^^^^^^^^^^^^^^^^^^^^^^^^^^^^^^^^^^^^^^^^^^^^^^^^^^^^^^^^^
  File "C:\Users\Рабочий\Desktop\djangodzr\venv\Lib\site-packages\django\db\models\manager.py", line 87, in manager_method
    return getattr(self.get_queryset(), name)(*args, **kwargs)
           ^^^^^^^^^^^^^^^^^^^^^^^^^^^^^^^^^^^^^^^^^^^^^^^^^^^
  File "C:\Users\Рабочий\Desktop\djangodzr\venv\Lib\site-packages\django\db\models\query.py", line 1476, in filter
    return self._filter_or_exclude(False, args, kwargs)
           ^^^^^^^^^^^^^^^^^^^^^^^^^^^^^^^^^^^^^^^^^^^^
  File "C:\Users\Рабочий\Desktop\djangodzr\venv\Lib\site-packages\django\db\models\query.py", line 1494, in _filter_or_exclude
    clone._filter_or_exclude_inplace(negate, args, kwargs)
  File "C:\Users\Рабочий\Desktop\djangodzr\venv\Lib\site-packages\django\db\models\query.py", line 1501, in _filter_or_exclude_inplace
    self._query.add_q(Q(*args, **kwargs))
  File "C:\Users\Рабочий\Desktop\djangodzr\venv\Lib\site-packages\django\db\models\sql\query.py", line 1613, in add_q
    clause, _ = self._add_q(q_object, self.used_aliases)
                ^^^^^^^^^^^^^^^^^^^^^^^^^^^^^^^^^^^^^^^^
  File "C:\Users\Рабочий\Desktop\djangodzr\venv\Lib\site-packages\django\db\models\sql\query.py", line 1645, in _add_q
    child_clause, needed_inner = self.build_filter(
                                 ^^^^^^^^^^^^^^^^^^
  File "C:\Users\Рабочий\Desktop\djangodzr\venv\Lib\site-packages\django\db\models\sql\query.py", line 1495, in build_filter
    lookups, parts, reffed_expression = self.solve_lookup_type(arg, summarize)
                                        ^^^^^^^^^^^^^^^^^^^^^^^^^^^^^^^^^^^^^^
  File "C:\Users\Рабочий\Desktop\djangodzr\venv\Lib\site-packages\django\db\models\sql\query.py", line 1307, in solve_lookup_type
    _, field, _, lookup_parts = self.names_to_path(lookup_splitted, self.get_meta())
                                ^^^^^^^^^^^^^^^^^^^^^^^^^^^^^^^^^^^^^^^^^^^^^^^^^^^^
  File "C:\Users\Рабочий\Desktop\djangodzr\venv\Lib\site-packages\django\db\models\sql\query.py", line 1772, in names_to_path
    raise FieldError(
django.core.exceptions.FieldError: Cannot resolve keyword 'date_created' into field. Choices are: client, client_id, id, order_date, products, total_amount
ERROR 2024-04-06 12:36:11,954 basehttp 8844 17388 "GET /purchased_products/ HTTP/1.1" 500 116965
INFO 2024-04-06 12:37:36,217 autoreload 8844 24684 C:\Users\Рабочий\Desktop\djangodzr\myproj\myweb\views.py changed, reloading.
INFO 2024-04-06 12:37:36,814 autoreload 4244 18888 Watching for file changes with StatReloader
INFO 2024-04-06 12:37:37,196 basehttp 4244 2080 "GET /purchased_products/ HTTP/1.1" 200 298
INFO 2024-04-06 12:38:31,160 autoreload 4244 18888 C:\Users\Рабочий\Desktop\djangodzr\myproj\myweb\views.py changed, reloading.
INFO 2024-04-06 12:38:31,684 autoreload 6208 24612 Watching for file changes with StatReloader
INFO 2024-04-06 12:39:53,283 basehttp 6208 10496 "GET /purchased_products/ HTTP/1.1" 200 321
INFO 2024-04-06 12:40:19,879 basehttp 6208 7336 "GET /purchased_products/ HTTP/1.1" 200 430
INFO 2024-04-06 12:40:20,967 basehttp 6208 7336 "GET /purchased_products/ HTTP/1.1" 200 430
INFO 2024-04-06 12:40:59,318 basehttp 6208 23300 "GET /purchased_products/ HTTP/1.1" 200 216
INFO 2024-04-06 12:47:32,700 autoreload 6208 24612 C:\Users\Рабочий\Desktop\djangodzr\myproj\myweb\views.py changed, reloading.
INFO 2024-04-06 12:47:33,737 autoreload 1700 20040 Watching for file changes with StatReloader
INFO 2024-04-06 12:47:34,210 basehttp 1700 17628 "GET /purchased_products/ HTTP/1.1" 200 4601
INFO 2024-04-06 12:48:53,866 autoreload 1700 20040 C:\Users\Рабочий\Desktop\djangodzr\myproj\myweb\models.py changed, reloading.
INFO 2024-04-06 12:48:54,796 autoreload 15932 25108 Watching for file changes with StatReloader
INFO 2024-04-06 12:49:06,497 autoreload 15932 25108 C:\Users\Рабочий\Desktop\djangodzr\myproj\myweb\models.py changed, reloading.
INFO 2024-04-06 12:49:07,433 autoreload 19600 22068 Watching for file changes with StatReloader
INFO 2024-04-06 12:49:34,988 autoreload 19600 22068 C:\Users\Рабочий\Desktop\djangodzr\myproj\myweb\views.py changed, reloading.
INFO 2024-04-06 12:49:35,945 autoreload 19708 25396 Watching for file changes with StatReloader
INFO 2024-04-06 12:50:00,091 basehttp 19708 23788 "GET /purchased_products/ HTTP/1.1" 200 1428
INFO 2024-04-06 12:51:53,227 autoreload 19708 25396 C:\Users\Рабочий\Desktop\djangodzr\myproj\myweb\models.py changed, reloading.
INFO 2024-04-06 12:51:54,205 autoreload 21880 16544 Watching for file changes with StatReloader
INFO 2024-04-06 12:52:51,935 basehttp 21880 16908 "GET /purchased_products/ HTTP/1.1" 200 1428
INFO 2024-04-06 12:52:53,319 basehttp 21880 16908 "GET /purchased_products/ HTTP/1.1" 200 1428
INFO 2024-04-06 12:54:04,080 basehttp 21880 16908 "GET /purchased_products/ HTTP/1.1" 200 1428
INFO 2024-04-06 12:55:20,202 basehttp 21880 16908 "GET /purchased_products/ HTTP/1.1" 200 1428
INFO 2024-04-06 12:55:21,399 basehttp 21880 16908 "GET /purchased_products/ HTTP/1.1" 200 1428
INFO 2024-04-06 12:56:28,735 basehttp 21880 16908 "GET /purchased_products/ HTTP/1.1" 200 1428
INFO 2024-04-06 12:56:30,041 basehttp 21880 16908 "GET /purchased_products/ HTTP/1.1" 200 1428
INFO 2024-04-06 12:56:30,664 basehttp 21880 16908 "GET /purchased_products/ HTTP/1.1" 200 1428
INFO 2024-04-06 12:56:39,509 basehttp 21880 16908 "GET /purchased_products/ HTTP/1.1" 200 1428
INFO 2024-04-06 12:59:52,345 basehttp 21880 16908 "GET /purchased_products/ HTTP/1.1" 200 5895
INFO 2024-04-09 18:28:15,959 autoreload 5608 18268 Watching for file changes with StatReloader
WARNING 2024-04-09 18:29:06,043 log 5608 22972 Not Found: /edit_product/
WARNING 2024-04-09 18:29:06,044 basehttp 5608 22972 "GET /edit_product/ HTTP/1.1" 404 3212
INFO 2024-04-09 18:29:11,151 basehttp 5608 22972 "GET /edit_product/3 HTTP/1.1" 301 0
INFO 2024-04-09 18:29:11,205 basehttp 5608 7488 "GET /edit_product/3/ HTTP/1.1" 200 1212
ERROR 2024-04-09 18:29:29,382 log 5608 19896 Internal Server Error: /edit_product/3/
Traceback (most recent call last):
  File "C:\Users\Рабочий\Desktop\djangodzr\venv\Lib\site-packages\django\core\handlers\exception.py", line 55, in inner
    response = get_response(request)
               ^^^^^^^^^^^^^^^^^^^^^
  File "C:\Users\Рабочий\Desktop\djangodzr\venv\Lib\site-packages\django\core\handlers\base.py", line 197, in _get_response
    response = wrapped_callback(request, *callback_args, **callback_kwargs)
               ^^^^^^^^^^^^^^^^^^^^^^^^^^^^^^^^^^^^^^^^^^^^^^^^^^^^^^^^^^^^
  File "C:\Users\Рабочий\Desktop\djangodzr\myproj\myweb\views.py", line 119, in edit_product
    return redirect('product_detail', product_id=product_id)
           ^^^^^^^^^^^^^^^^^^^^^^^^^^^^^^^^^^^^^^^^^^^^^^^^^
  File "C:\Users\Рабочий\Desktop\djangodzr\venv\Lib\site-packages\django\shortcuts.py", line 49, in redirect
    return redirect_class(resolve_url(to, *args, **kwargs))
                          ^^^^^^^^^^^^^^^^^^^^^^^^^^^^^^^^
  File "C:\Users\Рабочий\Desktop\djangodzr\venv\Lib\site-packages\django\shortcuts.py", line 180, in resolve_url
    return reverse(to, args=args, kwargs=kwargs)
           ^^^^^^^^^^^^^^^^^^^^^^^^^^^^^^^^^^^^^
  File "C:\Users\Рабочий\Desktop\djangodzr\venv\Lib\site-packages\django\urls\base.py", line 88, in reverse
    return resolver._reverse_with_prefix(view, prefix, *args, **kwargs)
           ^^^^^^^^^^^^^^^^^^^^^^^^^^^^^^^^^^^^^^^^^^^^^^^^^^^^^^^^^^^^
  File "C:\Users\Рабочий\Desktop\djangodzr\venv\Lib\site-packages\django\urls\resolvers.py", line 851, in _reverse_with_prefix
    raise NoReverseMatch(msg)
django.urls.exceptions.NoReverseMatch: Reverse for 'product_detail' not found. 'product_detail' is not a valid view function or pattern name.
ERROR 2024-04-09 18:29:29,386 basehttp 5608 19896 "POST /edit_product/3/ HTTP/1.1" 500 89581
INFO 2024-04-09 18:34:32,970 autoreload 5608 18268 C:\Users\Рабочий\Desktop\djangodzr\myproj\myweb\views.py changed, reloading.
INFO 2024-04-09 18:34:33,557 autoreload 22608 16400 Watching for file changes with StatReloader
INFO 2024-04-09 18:34:48,107 autoreload 22608 16400 C:\Users\Рабочий\Desktop\djangodzr\myproj\myweb\urls.py changed, reloading.
INFO 2024-04-09 18:34:48,588 autoreload 22712 22412 Watching for file changes with StatReloader
INFO 2024-04-09 18:35:08,216 autoreload 22712 22412 C:\Users\Рабочий\Desktop\djangodzr\myproj\myweb\urls.py changed, reloading.
INFO 2024-04-09 18:35:08,745 autoreload 16852 17908 Watching for file changes with StatReloader
INFO 2024-04-09 18:37:12,109 basehttp 16852 15980 "GET /edit_product/4 HTTP/1.1" 301 0
INFO 2024-04-09 18:37:12,126 basehttp 16852 21732 "GET /edit_product/4/ HTTP/1.1" 200 1214
INFO 2024-04-09 18:37:20,424 basehttp 16852 21732 "POST /edit_product/4/ HTTP/1.1" 302 0
INFO 2024-04-09 18:37:20,438 basehttp 16852 21732 "GET /product_detail/4/ HTTP/1.1" 200 314
INFO 2024-04-09 18:40:49,366 basehttp 16852 32 "GET /edit_product/4/ HTTP/1.1" 200 1220
INFO 2024-04-09 18:40:54,466 basehttp 16852 32 "GET /edit_product/1 HTTP/1.1" 301 0
INFO 2024-04-09 18:40:54,474 basehttp 16852 13188 "GET /edit_product/1/ HTTP/1.1" 200 1218
INFO 2024-04-09 18:41:01,577 basehttp 16852 13188 "POST /edit_product/1/ HTTP/1.1" 302 0
INFO 2024-04-09 18:41:01,589 basehttp 16852 13188 "GET /product_detail/1/ HTTP/1.1" 200 336
INFO 2024-04-09 18:45:07,842 autoreload 16852 17908 C:\Users\Рабочий\Desktop\djangodzr\myproj\myweb\models.py changed, reloading.
INFO 2024-04-09 18:45:08,502 autoreload 20152 23500 Watching for file changes with StatReloader
INFO 2024-04-09 18:45:52,569 autoreload 20152 23500 C:\Users\Рабочий\Desktop\djangodzr\myproj\myweb\forms.py changed, reloading.
INFO 2024-04-09 18:45:53,057 autoreload 15008 22280 Watching for file changes with StatReloader
INFO 2024-04-09 18:46:01,900 autoreload 17732 18176 Watching for file changes with StatReloader
INFO 2024-04-09 18:47:31,368 autoreload 16360 5128 Watching for file changes with StatReloader
INFO 2024-04-09 18:48:49,018 autoreload 16360 5128 C:\Users\Рабочий\Desktop\djangodzr\myproj\myweb\urls.py changed, reloading.
INFO 2024-04-09 18:48:49,489 autoreload 16612 19776 Watching for file changes with StatReloader
INFO 2024-04-09 18:49:00,252 autoreload 10832 19876 Watching for file changes with StatReloader
INFO 2024-04-09 18:52:38,293 autoreload 14628 21540 Watching for file changes with StatReloader
INFO 2024-04-09 18:54:00,537 autoreload 22296 17932 Watching for file changes with StatReloader
INFO 2024-04-09 18:56:35,631 autoreload 21644 16940 Watching for file changes with StatReloader
INFO 2024-04-09 18:56:42,004 autoreload 21644 16940 C:\Users\Рабочий\Desktop\djangodzr\myproj\myweb\urls.py changed, reloading.
INFO 2024-04-09 18:56:42,465 autoreload 22744 21864 Watching for file changes with StatReloader
INFO 2024-04-09 18:57:34,968 autoreload 17248 21084 Watching for file changes with StatReloader
INFO 2024-04-09 18:57:43,267 autoreload 17248 21084 C:\Users\Рабочий\Desktop\djangodzr\myproj\myproj\urls.py changed, reloading.
INFO 2024-04-09 18:57:43,782 autoreload 22968 2064 Watching for file changes with StatReloader
INFO 2024-04-09 18:57:51,098 autoreload 22544 17952 Watching for file changes with StatReloader
INFO 2024-04-09 19:07:22,724 autoreload 22544 17952 C:\Users\Рабочий\Desktop\djangodzr\myproj\myproj\settings.py changed, reloading.
INFO 2024-04-09 19:07:23,284 autoreload 16764 21316 Watching for file changes with StatReloader
INFO 2024-04-09 19:07:28,869 autoreload 11164 11444 Watching for file changes with StatReloader
INFO 2024-04-09 19:13:56,675 autoreload 21972 10836 Watching for file changes with StatReloader
INFO 2024-04-09 19:17:04,613 autoreload 20284 21992 Watching for file changes with StatReloader
INFO 2024-04-09 19:17:49,878 autoreload 16840 8272 Watching for file changes with StatReloader
ERROR 2024-04-09 19:17:58,243 log 16840 20512 Internal Server Error: /product_detail/1/
Traceback (most recent call last):
  File "C:\Users\Рабочий\Desktop\djangodzr\venv\Lib\site-packages\django\db\backends\utils.py", line 105, in _execute
    return self.cursor.execute(sql, params)
           ^^^^^^^^^^^^^^^^^^^^^^^^^^^^^^^^
  File "C:\Users\Рабочий\Desktop\djangodzr\venv\Lib\site-packages\django\db\backends\sqlite3\base.py", line 329, in execute
    return super().execute(query, params)
           ^^^^^^^^^^^^^^^^^^^^^^^^^^^^^^
sqlite3.OperationalError: no such column: myweb_product.photo

The above exception was the direct cause of the following exception:

Traceback (most recent call last):
  File "C:\Users\Рабочий\Desktop\djangodzr\venv\Lib\site-packages\django\core\handlers\exception.py", line 55, in inner
    response = get_response(request)
               ^^^^^^^^^^^^^^^^^^^^^
  File "C:\Users\Рабочий\Desktop\djangodzr\venv\Lib\site-packages\django\core\handlers\base.py", line 197, in _get_response
    response = wrapped_callback(request, *callback_args, **callback_kwargs)
               ^^^^^^^^^^^^^^^^^^^^^^^^^^^^^^^^^^^^^^^^^^^^^^^^^^^^^^^^^^^^
  File "C:\Users\Рабочий\Desktop\djangodzr\myproj\myweb\views.py", line 113, in product_detail
    product = Product.objects.get(id=product_id)
              ^^^^^^^^^^^^^^^^^^^^^^^^^^^^^^^^^^
  File "C:\Users\Рабочий\Desktop\djangodzr\venv\Lib\site-packages\django\db\models\manager.py", line 87, in manager_method
    return getattr(self.get_queryset(), name)(*args, **kwargs)
           ^^^^^^^^^^^^^^^^^^^^^^^^^^^^^^^^^^^^^^^^^^^^^^^^^^^
  File "C:\Users\Рабочий\Desktop\djangodzr\venv\Lib\site-packages\django\db\models\query.py", line 645, in get
    num = len(clone)
          ^^^^^^^^^^
  File "C:\Users\Рабочий\Desktop\djangodzr\venv\Lib\site-packages\django\db\models\query.py", line 382, in __len__
    self._fetch_all()
  File "C:\Users\Рабочий\Desktop\djangodzr\venv\Lib\site-packages\django\db\models\query.py", line 1928, in _fetch_all
    self._result_cache = list(self._iterable_class(self))
                         ^^^^^^^^^^^^^^^^^^^^^^^^^^^^^^^^
  File "C:\Users\Рабочий\Desktop\djangodzr\venv\Lib\site-packages\django\db\models\query.py", line 91, in __iter__
    results = compiler.execute_sql(
              ^^^^^^^^^^^^^^^^^^^^^
  File "C:\Users\Рабочий\Desktop\djangodzr\venv\Lib\site-packages\django\db\models\sql\compiler.py", line 1562, in execute_sql
    cursor.execute(sql, params)
  File "C:\Users\Рабочий\Desktop\djangodzr\venv\Lib\site-packages\django\db\backends\utils.py", line 122, in execute
    return super().execute(sql, params)
           ^^^^^^^^^^^^^^^^^^^^^^^^^^^^
  File "C:\Users\Рабочий\Desktop\djangodzr\venv\Lib\site-packages\django\db\backends\utils.py", line 79, in execute
    return self._execute_with_wrappers(
           ^^^^^^^^^^^^^^^^^^^^^^^^^^^^
  File "C:\Users\Рабочий\Desktop\djangodzr\venv\Lib\site-packages\django\db\backends\utils.py", line 92, in _execute_with_wrappers
    return executor(sql, params, many, context)
           ^^^^^^^^^^^^^^^^^^^^^^^^^^^^^^^^^^^^
  File "C:\Users\Рабочий\Desktop\djangodzr\venv\Lib\site-packages\django\db\backends\utils.py", line 100, in _execute
    with self.db.wrap_database_errors:
  File "C:\Users\Рабочий\Desktop\djangodzr\venv\Lib\site-packages\django\db\utils.py", line 91, in __exit__
    raise dj_exc_value.with_traceback(traceback) from exc_value
  File "C:\Users\Рабочий\Desktop\djangodzr\venv\Lib\site-packages\django\db\backends\utils.py", line 105, in _execute
    return self.cursor.execute(sql, params)
           ^^^^^^^^^^^^^^^^^^^^^^^^^^^^^^^^
  File "C:\Users\Рабочий\Desktop\djangodzr\venv\Lib\site-packages\django\db\backends\sqlite3\base.py", line 329, in execute
    return super().execute(query, params)
           ^^^^^^^^^^^^^^^^^^^^^^^^^^^^^^
django.db.utils.OperationalError: no such column: myweb_product.photo
ERROR 2024-04-09 19:17:58,251 basehttp 16840 20512 "GET /product_detail/1/ HTTP/1.1" 500 141230
INFO 2024-04-09 19:18:05,222 basehttp 16840 13864 "GET /product_detail/2 HTTP/1.1" 301 0
ERROR 2024-04-09 19:18:05,251 log 16840 7732 Internal Server Error: /product_detail/2/
Traceback (most recent call last):
  File "C:\Users\Рабочий\Desktop\djangodzr\venv\Lib\site-packages\django\db\backends\utils.py", line 105, in _execute
    return self.cursor.execute(sql, params)
           ^^^^^^^^^^^^^^^^^^^^^^^^^^^^^^^^
  File "C:\Users\Рабочий\Desktop\djangodzr\venv\Lib\site-packages\django\db\backends\sqlite3\base.py", line 329, in execute
    return super().execute(query, params)
           ^^^^^^^^^^^^^^^^^^^^^^^^^^^^^^
sqlite3.OperationalError: no such column: myweb_product.photo

The above exception was the direct cause of the following exception:

Traceback (most recent call last):
  File "C:\Users\Рабочий\Desktop\djangodzr\venv\Lib\site-packages\django\core\handlers\exception.py", line 55, in inner
    response = get_response(request)
               ^^^^^^^^^^^^^^^^^^^^^
  File "C:\Users\Рабочий\Desktop\djangodzr\venv\Lib\site-packages\django\core\handlers\base.py", line 197, in _get_response
    response = wrapped_callback(request, *callback_args, **callback_kwargs)
               ^^^^^^^^^^^^^^^^^^^^^^^^^^^^^^^^^^^^^^^^^^^^^^^^^^^^^^^^^^^^
  File "C:\Users\Рабочий\Desktop\djangodzr\myproj\myweb\views.py", line 113, in product_detail
    product = Product.objects.get(id=product_id)
              ^^^^^^^^^^^^^^^^^^^^^^^^^^^^^^^^^^
  File "C:\Users\Рабочий\Desktop\djangodzr\venv\Lib\site-packages\django\db\models\manager.py", line 87, in manager_method
    return getattr(self.get_queryset(), name)(*args, **kwargs)
           ^^^^^^^^^^^^^^^^^^^^^^^^^^^^^^^^^^^^^^^^^^^^^^^^^^^
  File "C:\Users\Рабочий\Desktop\djangodzr\venv\Lib\site-packages\django\db\models\query.py", line 645, in get
    num = len(clone)
          ^^^^^^^^^^
  File "C:\Users\Рабочий\Desktop\djangodzr\venv\Lib\site-packages\django\db\models\query.py", line 382, in __len__
    self._fetch_all()
  File "C:\Users\Рабочий\Desktop\djangodzr\venv\Lib\site-packages\django\db\models\query.py", line 1928, in _fetch_all
    self._result_cache = list(self._iterable_class(self))
                         ^^^^^^^^^^^^^^^^^^^^^^^^^^^^^^^^
  File "C:\Users\Рабочий\Desktop\djangodzr\venv\Lib\site-packages\django\db\models\query.py", line 91, in __iter__
    results = compiler.execute_sql(
              ^^^^^^^^^^^^^^^^^^^^^
  File "C:\Users\Рабочий\Desktop\djangodzr\venv\Lib\site-packages\django\db\models\sql\compiler.py", line 1562, in execute_sql
    cursor.execute(sql, params)
  File "C:\Users\Рабочий\Desktop\djangodzr\venv\Lib\site-packages\django\db\backends\utils.py", line 122, in execute
    return super().execute(sql, params)
           ^^^^^^^^^^^^^^^^^^^^^^^^^^^^
  File "C:\Users\Рабочий\Desktop\djangodzr\venv\Lib\site-packages\django\db\backends\utils.py", line 79, in execute
    return self._execute_with_wrappers(
           ^^^^^^^^^^^^^^^^^^^^^^^^^^^^
  File "C:\Users\Рабочий\Desktop\djangodzr\venv\Lib\site-packages\django\db\backends\utils.py", line 92, in _execute_with_wrappers
    return executor(sql, params, many, context)
           ^^^^^^^^^^^^^^^^^^^^^^^^^^^^^^^^^^^^
  File "C:\Users\Рабочий\Desktop\djangodzr\venv\Lib\site-packages\django\db\backends\utils.py", line 100, in _execute
    with self.db.wrap_database_errors:
  File "C:\Users\Рабочий\Desktop\djangodzr\venv\Lib\site-packages\django\db\utils.py", line 91, in __exit__
    raise dj_exc_value.with_traceback(traceback) from exc_value
  File "C:\Users\Рабочий\Desktop\djangodzr\venv\Lib\site-packages\django\db\backends\utils.py", line 105, in _execute
    return self.cursor.execute(sql, params)
           ^^^^^^^^^^^^^^^^^^^^^^^^^^^^^^^^
  File "C:\Users\Рабочий\Desktop\djangodzr\venv\Lib\site-packages\django\db\backends\sqlite3\base.py", line 329, in execute
    return super().execute(query, params)
           ^^^^^^^^^^^^^^^^^^^^^^^^^^^^^^
django.db.utils.OperationalError: no such column: myweb_product.photo
ERROR 2024-04-09 19:18:05,257 basehttp 16840 7732 "GET /product_detail/2/ HTTP/1.1" 500 140927
INFO 2024-04-09 19:26:23,053 autoreload 20872 20532 Watching for file changes with StatReloader
ERROR 2024-04-09 19:26:31,426 log 20872 8220 Internal Server Error: /edit_product/1/
Traceback (most recent call last):
  File "C:\Users\Рабочий\Desktop\djangodzr\venv\Lib\site-packages\django\db\backends\utils.py", line 105, in _execute
    return self.cursor.execute(sql, params)
           ^^^^^^^^^^^^^^^^^^^^^^^^^^^^^^^^
  File "C:\Users\Рабочий\Desktop\djangodzr\venv\Lib\site-packages\django\db\backends\sqlite3\base.py", line 329, in execute
    return super().execute(query, params)
           ^^^^^^^^^^^^^^^^^^^^^^^^^^^^^^
sqlite3.OperationalError: no such column: myweb_product.photo

The above exception was the direct cause of the following exception:

Traceback (most recent call last):
  File "C:\Users\Рабочий\Desktop\djangodzr\venv\Lib\site-packages\django\core\handlers\exception.py", line 55, in inner
    response = get_response(request)
               ^^^^^^^^^^^^^^^^^^^^^
  File "C:\Users\Рабочий\Desktop\djangodzr\venv\Lib\site-packages\django\core\handlers\base.py", line 197, in _get_response
    response = wrapped_callback(request, *callback_args, **callback_kwargs)
               ^^^^^^^^^^^^^^^^^^^^^^^^^^^^^^^^^^^^^^^^^^^^^^^^^^^^^^^^^^^^
  File "C:\Users\Рабочий\Desktop\djangodzr\myproj\myweb\views.py", line 118, in edit_product
    product = Product.objects.get(id=product_id)
              ^^^^^^^^^^^^^^^^^^^^^^^^^^^^^^^^^^
  File "C:\Users\Рабочий\Desktop\djangodzr\venv\Lib\site-packages\django\db\models\manager.py", line 87, in manager_method
    return getattr(self.get_queryset(), name)(*args, **kwargs)
           ^^^^^^^^^^^^^^^^^^^^^^^^^^^^^^^^^^^^^^^^^^^^^^^^^^^
  File "C:\Users\Рабочий\Desktop\djangodzr\venv\Lib\site-packages\django\db\models\query.py", line 645, in get
    num = len(clone)
          ^^^^^^^^^^
  File "C:\Users\Рабочий\Desktop\djangodzr\venv\Lib\site-packages\django\db\models\query.py", line 382, in __len__
    self._fetch_all()
  File "C:\Users\Рабочий\Desktop\djangodzr\venv\Lib\site-packages\django\db\models\query.py", line 1928, in _fetch_all
    self._result_cache = list(self._iterable_class(self))
                         ^^^^^^^^^^^^^^^^^^^^^^^^^^^^^^^^
  File "C:\Users\Рабочий\Desktop\djangodzr\venv\Lib\site-packages\django\db\models\query.py", line 91, in __iter__
    results = compiler.execute_sql(
              ^^^^^^^^^^^^^^^^^^^^^
  File "C:\Users\Рабочий\Desktop\djangodzr\venv\Lib\site-packages\django\db\models\sql\compiler.py", line 1562, in execute_sql
    cursor.execute(sql, params)
  File "C:\Users\Рабочий\Desktop\djangodzr\venv\Lib\site-packages\django\db\backends\utils.py", line 122, in execute
    return super().execute(sql, params)
           ^^^^^^^^^^^^^^^^^^^^^^^^^^^^
  File "C:\Users\Рабочий\Desktop\djangodzr\venv\Lib\site-packages\django\db\backends\utils.py", line 79, in execute
    return self._execute_with_wrappers(
           ^^^^^^^^^^^^^^^^^^^^^^^^^^^^
  File "C:\Users\Рабочий\Desktop\djangodzr\venv\Lib\site-packages\django\db\backends\utils.py", line 92, in _execute_with_wrappers
    return executor(sql, params, many, context)
           ^^^^^^^^^^^^^^^^^^^^^^^^^^^^^^^^^^^^
  File "C:\Users\Рабочий\Desktop\djangodzr\venv\Lib\site-packages\django\db\backends\utils.py", line 100, in _execute
    with self.db.wrap_database_errors:
  File "C:\Users\Рабочий\Desktop\djangodzr\venv\Lib\site-packages\django\db\utils.py", line 91, in __exit__
    raise dj_exc_value.with_traceback(traceback) from exc_value
  File "C:\Users\Рабочий\Desktop\djangodzr\venv\Lib\site-packages\django\db\backends\utils.py", line 105, in _execute
    return self.cursor.execute(sql, params)
           ^^^^^^^^^^^^^^^^^^^^^^^^^^^^^^^^
  File "C:\Users\Рабочий\Desktop\djangodzr\venv\Lib\site-packages\django\db\backends\sqlite3\base.py", line 329, in execute
    return super().execute(query, params)
           ^^^^^^^^^^^^^^^^^^^^^^^^^^^^^^
django.db.utils.OperationalError: no such column: myweb_product.photo
ERROR 2024-04-09 19:26:31,433 basehttp 20872 8220 "GET /edit_product/1/ HTTP/1.1" 500 140742
ERROR 2024-04-09 19:26:34,397 log 20872 8220 Internal Server Error: /edit_product/4/
Traceback (most recent call last):
  File "C:\Users\Рабочий\Desktop\djangodzr\venv\Lib\site-packages\django\db\backends\utils.py", line 105, in _execute
    return self.cursor.execute(sql, params)
           ^^^^^^^^^^^^^^^^^^^^^^^^^^^^^^^^
  File "C:\Users\Рабочий\Desktop\djangodzr\venv\Lib\site-packages\django\db\backends\sqlite3\base.py", line 329, in execute
    return super().execute(query, params)
           ^^^^^^^^^^^^^^^^^^^^^^^^^^^^^^
sqlite3.OperationalError: no such column: myweb_product.photo

The above exception was the direct cause of the following exception:

Traceback (most recent call last):
  File "C:\Users\Рабочий\Desktop\djangodzr\venv\Lib\site-packages\django\core\handlers\exception.py", line 55, in inner
    response = get_response(request)
               ^^^^^^^^^^^^^^^^^^^^^
  File "C:\Users\Рабочий\Desktop\djangodzr\venv\Lib\site-packages\django\core\handlers\base.py", line 197, in _get_response
    response = wrapped_callback(request, *callback_args, **callback_kwargs)
               ^^^^^^^^^^^^^^^^^^^^^^^^^^^^^^^^^^^^^^^^^^^^^^^^^^^^^^^^^^^^
  File "C:\Users\Рабочий\Desktop\djangodzr\myproj\myweb\views.py", line 118, in edit_product
    product = Product.objects.get(id=product_id)
              ^^^^^^^^^^^^^^^^^^^^^^^^^^^^^^^^^^
  File "C:\Users\Рабочий\Desktop\djangodzr\venv\Lib\site-packages\django\db\models\manager.py", line 87, in manager_method
    return getattr(self.get_queryset(), name)(*args, **kwargs)
           ^^^^^^^^^^^^^^^^^^^^^^^^^^^^^^^^^^^^^^^^^^^^^^^^^^^
  File "C:\Users\Рабочий\Desktop\djangodzr\venv\Lib\site-packages\django\db\models\query.py", line 645, in get
    num = len(clone)
          ^^^^^^^^^^
  File "C:\Users\Рабочий\Desktop\djangodzr\venv\Lib\site-packages\django\db\models\query.py", line 382, in __len__
    self._fetch_all()
  File "C:\Users\Рабочий\Desktop\djangodzr\venv\Lib\site-packages\django\db\models\query.py", line 1928, in _fetch_all
    self._result_cache = list(self._iterable_class(self))
                         ^^^^^^^^^^^^^^^^^^^^^^^^^^^^^^^^
  File "C:\Users\Рабочий\Desktop\djangodzr\venv\Lib\site-packages\django\db\models\query.py", line 91, in __iter__
    results = compiler.execute_sql(
              ^^^^^^^^^^^^^^^^^^^^^
  File "C:\Users\Рабочий\Desktop\djangodzr\venv\Lib\site-packages\django\db\models\sql\compiler.py", line 1562, in execute_sql
    cursor.execute(sql, params)
  File "C:\Users\Рабочий\Desktop\djangodzr\venv\Lib\site-packages\django\db\backends\utils.py", line 122, in execute
    return super().execute(sql, params)
           ^^^^^^^^^^^^^^^^^^^^^^^^^^^^
  File "C:\Users\Рабочий\Desktop\djangodzr\venv\Lib\site-packages\django\db\backends\utils.py", line 79, in execute
    return self._execute_with_wrappers(
           ^^^^^^^^^^^^^^^^^^^^^^^^^^^^
  File "C:\Users\Рабочий\Desktop\djangodzr\venv\Lib\site-packages\django\db\backends\utils.py", line 92, in _execute_with_wrappers
    return executor(sql, params, many, context)
           ^^^^^^^^^^^^^^^^^^^^^^^^^^^^^^^^^^^^
  File "C:\Users\Рабочий\Desktop\djangodzr\venv\Lib\site-packages\django\db\backends\utils.py", line 100, in _execute
    with self.db.wrap_database_errors:
  File "C:\Users\Рабочий\Desktop\djangodzr\venv\Lib\site-packages\django\db\utils.py", line 91, in __exit__
    raise dj_exc_value.with_traceback(traceback) from exc_value
  File "C:\Users\Рабочий\Desktop\djangodzr\venv\Lib\site-packages\django\db\backends\utils.py", line 105, in _execute
    return self.cursor.execute(sql, params)
           ^^^^^^^^^^^^^^^^^^^^^^^^^^^^^^^^
  File "C:\Users\Рабочий\Desktop\djangodzr\venv\Lib\site-packages\django\db\backends\sqlite3\base.py", line 329, in execute
    return super().execute(query, params)
           ^^^^^^^^^^^^^^^^^^^^^^^^^^^^^^
django.db.utils.OperationalError: no such column: myweb_product.photo
ERROR 2024-04-09 19:26:34,403 basehttp 20872 8220 "POST /edit_product/4/ HTTP/1.1" 500 142266
INFO 2024-04-09 19:27:19,564 autoreload 17908 21000 Watching for file changes with StatReloader
WARNING 2024-04-09 19:27:30,817 log 17908 22196 Not Found: /
WARNING 2024-04-09 19:27:30,818 basehttp 17908 22196 "GET / HTTP/1.1" 404 3363
INFO 2024-04-09 19:27:41,960 basehttp 17908 22480 "GET /product_detail/3 HTTP/1.1" 301 0
INFO 2024-04-09 19:27:41,974 basehttp 17908 17456 "GET /product_detail/3/ HTTP/1.1" 200 324
INFO 2024-04-09 19:27:48,610 basehttp 17908 5344 "GET /product_detail/1/ HTTP/1.1" 200 336
INFO 2024-04-09 19:27:54,026 basehttp 17908 5344 "GET /product_detail/2/ HTTP/1.1" 200 326
WARNING 2024-04-09 19:28:08,916 log 17908 4680 Not Found: /edit_product
WARNING 2024-04-09 19:28:08,917 basehttp 17908 4680 "GET /edit_product HTTP/1.1" 404 3417
INFO 2024-04-09 19:28:12,359 basehttp 17908 4680 "GET /edit_product/2 HTTP/1.1" 301 0
INFO 2024-04-09 19:28:12,383 basehttp 17908 16812 "GET /edit_product/2/ HTTP/1.1" 200 1448
WARNING 2024-04-09 19:28:16,918 log 17908 19320 Not Found: /media/myproj/static/default.jpeg
WARNING 2024-04-09 19:28:16,919 basehttp 17908 19320 "GET /media/myproj/static/default.jpeg HTTP/1.1" 404 3477
INFO 2024-04-09 19:28:41,594 basehttp 17908 3892 "POST /edit_product/2/ HTTP/1.1" 302 0
INFO 2024-04-09 19:28:41,599 basehttp 17908 3892 "GET /product_detail/2/ HTTP/1.1" 200 328
INFO 2024-04-09 19:35:30,838 autoreload 17908 21000 C:\Users\Рабочий\Desktop\djangodzr\myproj\myweb\views.py changed, reloading.
INFO 2024-04-09 19:35:31,388 autoreload 10996 23468 Watching for file changes with StatReloader
INFO 2024-04-09 19:35:56,170 autoreload 10996 23468 C:\Users\Рабочий\Desktop\djangodzr\myproj\myweb\views.py changed, reloading.
INFO 2024-04-09 19:35:56,668 autoreload 6544 23544 Watching for file changes with StatReloader
INFO 2024-04-09 19:36:28,563 autoreload 6544 23544 C:\Users\Рабочий\Desktop\djangodzr\myproj\myweb\views.py changed, reloading.
INFO 2024-04-09 19:36:29,074 autoreload 20220 21856 Watching for file changes with StatReloader
WARNING 2024-04-09 19:36:46,555 log 20220 22900 Not Found: /
WARNING 2024-04-09 19:36:46,556 basehttp 20220 22900 "GET / HTTP/1.1" 404 3363
INFO 2024-04-09 19:37:03,505 basehttp 20220 19336 "GET /product HTTP/1.1" 301 0
INFO 2024-04-09 19:37:03,533 basehttp 20220 11876 "GET /product/ HTTP/1.1" 200 1141
INFO 2024-04-09 19:37:57,906 basehttp 20220 23000 "POST /product/ HTTP/1.1" 200 1318
INFO 2024-04-09 19:38:33,429 basehttp 20220 23044 "POST /product/ HTTP/1.1" 200 1318
INFO 2024-04-09 19:38:41,395 basehttp 20220 21224 "POST /product/ HTTP/1.1" 200 1318
INFO 2024-04-09 19:42:08,350 autoreload 20220 21856 C:\Users\Рабочий\Desktop\djangodzr\myproj\myweb\models.py changed, reloading.
INFO 2024-04-09 19:42:08,841 autoreload 2580 19228 Watching for file changes with StatReloader
INFO 2024-04-09 19:42:24,591 autoreload 9480 20564 Watching for file changes with StatReloader
ERROR 2024-04-09 19:43:46,878 log 9480 10872 Internal Server Error: /product/
Traceback (most recent call last):
  File "C:\Users\Рабочий\Desktop\djangodzr\venv\Lib\site-packages\django\utils\datastructures.py", line 84, in __getitem__
    list_ = super().__getitem__(key)
            ^^^^^^^^^^^^^^^^^^^^^^^^
KeyError: 'photo'

During handling of the above exception, another exception occurred:

Traceback (most recent call last):
  File "C:\Users\Рабочий\Desktop\djangodzr\venv\Lib\site-packages\django\core\handlers\exception.py", line 55, in inner
    response = get_response(request)
               ^^^^^^^^^^^^^^^^^^^^^
  File "C:\Users\Рабочий\Desktop\djangodzr\venv\Lib\site-packages\django\core\handlers\base.py", line 197, in _get_response
    response = wrapped_callback(request, *callback_args, **callback_kwargs)
               ^^^^^^^^^^^^^^^^^^^^^^^^^^^^^^^^^^^^^^^^^^^^^^^^^^^^^^^^^^^^
  File "C:\Users\Рабочий\Desktop\djangodzr\myproj\myweb\views.py", line 65, in create_product
    product.photo = request.FILES['photo'] # сохраняем картинку
                    ~~~~~~~~~~~~~^^^^^^^^^
  File "C:\Users\Рабочий\Desktop\djangodzr\venv\Lib\site-packages\django\utils\datastructures.py", line 86, in __getitem__
    raise MultiValueDictKeyError(key)
django.utils.datastructures.MultiValueDictKeyError: 'photo'
ERROR 2024-04-09 19:43:46,882 basehttp 9480 10872 "POST /product/ HTTP/1.1" 500 79365
ERROR 2024-04-09 19:43:50,751 log 9480 3592 Internal Server Error: /product/
Traceback (most recent call last):
  File "C:\Users\Рабочий\Desktop\djangodzr\venv\Lib\site-packages\django\utils\datastructures.py", line 84, in __getitem__
    list_ = super().__getitem__(key)
            ^^^^^^^^^^^^^^^^^^^^^^^^
KeyError: 'photo'

During handling of the above exception, another exception occurred:

Traceback (most recent call last):
  File "C:\Users\Рабочий\Desktop\djangodzr\venv\Lib\site-packages\django\core\handlers\exception.py", line 55, in inner
    response = get_response(request)
               ^^^^^^^^^^^^^^^^^^^^^
  File "C:\Users\Рабочий\Desktop\djangodzr\venv\Lib\site-packages\django\core\handlers\base.py", line 197, in _get_response
    response = wrapped_callback(request, *callback_args, **callback_kwargs)
               ^^^^^^^^^^^^^^^^^^^^^^^^^^^^^^^^^^^^^^^^^^^^^^^^^^^^^^^^^^^^
  File "C:\Users\Рабочий\Desktop\djangodzr\myproj\myweb\views.py", line 65, in create_product
    product.photo = request.FILES['photo'] # сохраняем картинку
                    ~~~~~~~~~~~~~^^^^^^^^^
  File "C:\Users\Рабочий\Desktop\djangodzr\venv\Lib\site-packages\django\utils\datastructures.py", line 86, in __getitem__
    raise MultiValueDictKeyError(key)
django.utils.datastructures.MultiValueDictKeyError: 'photo'
ERROR 2024-04-09 19:43:50,753 basehttp 9480 3592 "POST /product/ HTTP/1.1" 500 79365
ERROR 2024-04-09 19:43:57,733 log 9480 5464 Internal Server Error: /product/
Traceback (most recent call last):
  File "C:\Users\Рабочий\Desktop\djangodzr\venv\Lib\site-packages\django\utils\datastructures.py", line 84, in __getitem__
    list_ = super().__getitem__(key)
            ^^^^^^^^^^^^^^^^^^^^^^^^
KeyError: 'photo'

During handling of the above exception, another exception occurred:

Traceback (most recent call last):
  File "C:\Users\Рабочий\Desktop\djangodzr\venv\Lib\site-packages\django\core\handlers\exception.py", line 55, in inner
    response = get_response(request)
               ^^^^^^^^^^^^^^^^^^^^^
  File "C:\Users\Рабочий\Desktop\djangodzr\venv\Lib\site-packages\django\core\handlers\base.py", line 197, in _get_response
    response = wrapped_callback(request, *callback_args, **callback_kwargs)
               ^^^^^^^^^^^^^^^^^^^^^^^^^^^^^^^^^^^^^^^^^^^^^^^^^^^^^^^^^^^^
  File "C:\Users\Рабочий\Desktop\djangodzr\myproj\myweb\views.py", line 65, in create_product
    product.photo = request.FILES['photo'] # сохраняем картинку
                    ~~~~~~~~~~~~~^^^^^^^^^
  File "C:\Users\Рабочий\Desktop\djangodzr\venv\Lib\site-packages\django\utils\datastructures.py", line 86, in __getitem__
    raise MultiValueDictKeyError(key)
django.utils.datastructures.MultiValueDictKeyError: 'photo'
ERROR 2024-04-09 19:43:57,735 basehttp 9480 5464 "POST /product/ HTTP/1.1" 500 79365
INFO 2024-04-09 19:48:09,403 autoreload 18188 16856 Watching for file changes with StatReloader
WARNING 2024-04-09 19:48:17,953 log 18188 16608 Not Found: /
WARNING 2024-04-09 19:48:17,953 basehttp 18188 16608 "GET / HTTP/1.1" 404 3363
INFO 2024-04-09 19:48:24,689 basehttp 18188 16608 "GET /product/ HTTP/1.1" 200 1132
ERROR 2024-04-09 19:48:50,951 log 18188 9712 Internal Server Error: /product/
Traceback (most recent call last):
  File "C:\Users\Рабочий\Desktop\djangodzr\venv\Lib\site-packages\django\utils\datastructures.py", line 84, in __getitem__
    list_ = super().__getitem__(key)
            ^^^^^^^^^^^^^^^^^^^^^^^^
KeyError: 'photo'

During handling of the above exception, another exception occurred:

Traceback (most recent call last):
  File "C:\Users\Рабочий\Desktop\djangodzr\venv\Lib\site-packages\django\core\handlers\exception.py", line 55, in inner
    response = get_response(request)
               ^^^^^^^^^^^^^^^^^^^^^
  File "C:\Users\Рабочий\Desktop\djangodzr\venv\Lib\site-packages\django\core\handlers\base.py", line 197, in _get_response
    response = wrapped_callback(request, *callback_args, **callback_kwargs)
               ^^^^^^^^^^^^^^^^^^^^^^^^^^^^^^^^^^^^^^^^^^^^^^^^^^^^^^^^^^^^
  File "C:\Users\Рабочий\Desktop\djangodzr\myproj\myweb\views.py", line 65, in create_product
    product.photo = request.FILES['photo'] # сохраняем картинку
                    ~~~~~~~~~~~~~^^^^^^^^^
  File "C:\Users\Рабочий\Desktop\djangodzr\venv\Lib\site-packages\django\utils\datastructures.py", line 86, in __getitem__
    raise MultiValueDictKeyError(key)
django.utils.datastructures.MultiValueDictKeyError: 'photo'
ERROR 2024-04-09 19:48:50,955 basehttp 18188 9712 "POST /product/ HTTP/1.1" 500 79314
INFO 2024-04-09 19:50:16,245 autoreload 18408 10832 Watching for file changes with StatReloader
WARNING 2024-04-09 19:50:24,891 log 18408 19032 Not Found: /
WARNING 2024-04-09 19:50:24,892 basehttp 18408 19032 "GET / HTTP/1.1" 404 3363
INFO 2024-04-09 19:50:31,071 basehttp 18408 19412 "GET /product/ HTTP/1.1" 200 1343
INFO 2024-04-09 19:51:26,493 autoreload 17696 14004 Watching for file changes with StatReloader
INFO 2024-04-09 19:51:28,978 basehttp 17696 11260 "GET /product/ HTTP/1.1" 200 1335
INFO 2024-04-09 19:51:29,287 basehttp 17696 11260 "GET /product/ HTTP/1.1" 200 1335
INFO 2024-04-09 19:51:52,588 basehttp 17696 14400 "GET /product/ HTTP/1.1" 200 1132
INFO 2024-04-09 19:52:40,826 basehttp 17696 21192 "GET /product/ HTTP/1.1" 200 2305
INFO 2024-04-09 19:52:41,673 basehttp 17696 21192 "GET /product/ HTTP/1.1" 200 2305
ERROR 2024-04-09 19:53:04,440 log 17696 22420 Internal Server Error: /product/
Traceback (most recent call last):
  File "C:\Users\Рабочий\Desktop\djangodzr\venv\Lib\site-packages\django\utils\datastructures.py", line 84, in __getitem__
    list_ = super().__getitem__(key)
            ^^^^^^^^^^^^^^^^^^^^^^^^
KeyError: 'photo'

During handling of the above exception, another exception occurred:

Traceback (most recent call last):
  File "C:\Users\Рабочий\Desktop\djangodzr\venv\Lib\site-packages\django\core\handlers\exception.py", line 55, in inner
    response = get_response(request)
               ^^^^^^^^^^^^^^^^^^^^^
  File "C:\Users\Рабочий\Desktop\djangodzr\venv\Lib\site-packages\django\core\handlers\base.py", line 197, in _get_response
    response = wrapped_callback(request, *callback_args, **callback_kwargs)
               ^^^^^^^^^^^^^^^^^^^^^^^^^^^^^^^^^^^^^^^^^^^^^^^^^^^^^^^^^^^^
  File "C:\Users\Рабочий\Desktop\djangodzr\myproj\myweb\views.py", line 65, in create_product
    product.photo = request.FILES['photo'] # сохраняем картинку
                    ~~~~~~~~~~~~~^^^^^^^^^
  File "C:\Users\Рабочий\Desktop\djangodzr\venv\Lib\site-packages\django\utils\datastructures.py", line 86, in __getitem__
    raise MultiValueDictKeyError(key)
django.utils.datastructures.MultiValueDictKeyError: 'photo'
ERROR 2024-04-09 19:53:04,443 basehttp 17696 22420 "POST /product/ HTTP/1.1" 500 79349
INFO 2024-04-09 19:56:23,897 autoreload 10080 13988 Watching for file changes with StatReloader
WARNING 2024-04-09 19:56:30,352 log 10080 16336 Not Found: /
WARNING 2024-04-09 19:56:30,353 basehttp 10080 16336 "GET / HTTP/1.1" 404 3363
INFO 2024-04-09 19:56:37,157 basehttp 10080 5304 "GET /product/ HTTP/1.1" 200 2342
INFO 2024-04-09 19:57:07,015 basehttp 10080 12484 "GET /product/ HTTP/1.1" 200 2342
INFO 2024-04-09 19:57:07,711 basehttp 10080 12484 "GET /product/ HTTP/1.1" 200 2342
INFO 2024-04-09 19:57:08,035 basehttp 10080 12484 "GET /product/ HTTP/1.1" 200 2342
INFO 2024-04-09 19:57:14,792 basehttp 10080 12484 "GET /product/ HTTP/1.1" 200 1199
INFO 2024-04-09 19:57:15,412 basehttp 10080 12484 "GET /product/ HTTP/1.1" 200 1199
INFO 2024-04-09 19:57:16,424 basehttp 10080 12484 "GET /product/ HTTP/1.1" 200 1199
ERROR 2024-04-09 19:58:01,169 log 10080 8928 Internal Server Error: /product/
Traceback (most recent call last):
  File "C:\Users\Рабочий\Desktop\djangodzr\venv\Lib\site-packages\django\utils\datastructures.py", line 84, in __getitem__
    list_ = super().__getitem__(key)
            ^^^^^^^^^^^^^^^^^^^^^^^^
KeyError: 'photo'

During handling of the above exception, another exception occurred:

Traceback (most recent call last):
  File "C:\Users\Рабочий\Desktop\djangodzr\venv\Lib\site-packages\django\core\handlers\exception.py", line 55, in inner
    response = get_response(request)
               ^^^^^^^^^^^^^^^^^^^^^
  File "C:\Users\Рабочий\Desktop\djangodzr\venv\Lib\site-packages\django\core\handlers\base.py", line 197, in _get_response
    response = wrapped_callback(request, *callback_args, **callback_kwargs)
               ^^^^^^^^^^^^^^^^^^^^^^^^^^^^^^^^^^^^^^^^^^^^^^^^^^^^^^^^^^^^
  File "C:\Users\Рабочий\Desktop\djangodzr\myproj\myweb\views.py", line 65, in create_product
    product.photo = request.FILES['photo'] # сохраняем картинку
                    ~~~~~~~~~~~~~^^^^^^^^^
  File "C:\Users\Рабочий\Desktop\djangodzr\venv\Lib\site-packages\django\utils\datastructures.py", line 86, in __getitem__
    raise MultiValueDictKeyError(key)
django.utils.datastructures.MultiValueDictKeyError: 'photo'
ERROR 2024-04-09 19:58:01,172 basehttp 10080 8928 "POST /product/ HTTP/1.1" 500 79347
ERROR 2024-04-09 19:58:25,051 log 10080 8928 Internal Server Error: /product/
Traceback (most recent call last):
  File "C:\Users\Рабочий\Desktop\djangodzr\venv\Lib\site-packages\django\utils\datastructures.py", line 84, in __getitem__
    list_ = super().__getitem__(key)
            ^^^^^^^^^^^^^^^^^^^^^^^^
KeyError: 'photo'

During handling of the above exception, another exception occurred:

Traceback (most recent call last):
  File "C:\Users\Рабочий\Desktop\djangodzr\venv\Lib\site-packages\django\core\handlers\exception.py", line 55, in inner
    response = get_response(request)
               ^^^^^^^^^^^^^^^^^^^^^
  File "C:\Users\Рабочий\Desktop\djangodzr\venv\Lib\site-packages\django\core\handlers\base.py", line 197, in _get_response
    response = wrapped_callback(request, *callback_args, **callback_kwargs)
               ^^^^^^^^^^^^^^^^^^^^^^^^^^^^^^^^^^^^^^^^^^^^^^^^^^^^^^^^^^^^
  File "C:\Users\Рабочий\Desktop\djangodzr\myproj\myweb\views.py", line 65, in create_product
    product.photo = request.FILES['photo'] # сохраняем картинку
                    ~~~~~~~~~~~~~^^^^^^^^^
  File "C:\Users\Рабочий\Desktop\djangodzr\venv\Lib\site-packages\django\utils\datastructures.py", line 86, in __getitem__
    raise MultiValueDictKeyError(key)
django.utils.datastructures.MultiValueDictKeyError: 'photo'
ERROR 2024-04-09 19:58:25,053 basehttp 10080 8928 "POST /product/ HTTP/1.1" 500 79347
ERROR 2024-04-09 19:58:37,090 log 10080 8928 Internal Server Error: /product/
Traceback (most recent call last):
  File "C:\Users\Рабочий\Desktop\djangodzr\venv\Lib\site-packages\django\core\handlers\exception.py", line 55, in inner
    response = get_response(request)
               ^^^^^^^^^^^^^^^^^^^^^
  File "C:\Users\Рабочий\Desktop\djangodzr\venv\Lib\site-packages\django\core\handlers\base.py", line 197, in _get_response
    response = wrapped_callback(request, *callback_args, **callback_kwargs)
               ^^^^^^^^^^^^^^^^^^^^^^^^^^^^^^^^^^^^^^^^^^^^^^^^^^^^^^^^^^^^
  File "C:\Users\Рабочий\Desktop\djangodzr\myproj\myweb\views.py", line 70, in create_product
    os.rename(product.photo.path, os.path.join(settings.MEDIA_ROOT, new_path))
FileNotFoundError: [WinError 3] Системе не удается найти указанный путь: 'C:\\Users\\Рабочий\\Desktop\\djangodzr\\myproj\\media\\product_photos\\вопрос.png' -> 'C:\\Users\\Рабочий\\Desktop\\djangodzr\\myproj\\media\\product_photos/product_photos/вопрос.png'
ERROR 2024-04-09 19:58:37,092 basehttp 10080 8928 "POST /product/ HTTP/1.1" 500 72527
INFO 2024-04-09 20:00:34,781 autoreload 10080 13988 C:\Users\Рабочий\Desktop\djangodzr\myproj\myweb\views.py changed, reloading.
INFO 2024-04-09 20:00:35,270 autoreload 22196 20880 Watching for file changes with StatReloader
INFO 2024-04-09 20:00:51,890 autoreload 22196 20880 C:\Users\Рабочий\Desktop\djangodzr\myproj\myweb\views.py changed, reloading.
INFO 2024-04-09 20:00:52,397 autoreload 17388 18124 Watching for file changes with StatReloader
ERROR 2024-04-09 20:01:11,294 log 17388 16872 Internal Server Error: /product/
Traceback (most recent call last):
  File "C:\Users\Рабочий\Desktop\djangodzr\venv\Lib\site-packages\django\core\handlers\exception.py", line 55, in inner
    response = get_response(request)
               ^^^^^^^^^^^^^^^^^^^^^
  File "C:\Users\Рабочий\Desktop\djangodzr\venv\Lib\site-packages\django\core\handlers\base.py", line 197, in _get_response
    response = wrapped_callback(request, *callback_args, **callback_kwargs)
               ^^^^^^^^^^^^^^^^^^^^^^^^^^^^^^^^^^^^^^^^^^^^^^^^^^^^^^^^^^^^
  File "C:\Users\Рабочий\Desktop\djangodzr\myproj\myweb\views.py", line 74, in create_product
    os.rename(product.photo.path, os.path.join(settings.MEDIA_ROOT, new_path))
FileNotFoundError: [WinError 3] Системе не удается найти указанный путь: 'C:\\Users\\Рабочий\\Desktop\\djangodzr\\myproj\\media\\product_photos\\вопрос_MpD66Wj.png' -> 'C:\\Users\\Рабочий\\Desktop\\djangodzr\\myproj\\media\\product_photos/product_photos/вопрос_MpD66Wj.png'
ERROR 2024-04-09 20:01:11,297 basehttp 17388 16872 "POST /product/ HTTP/1.1" 500 72448
ERROR 2024-04-09 20:01:18,728 log 17388 16872 Internal Server Error: /product/
Traceback (most recent call last):
  File "C:\Users\Рабочий\Desktop\djangodzr\venv\Lib\site-packages\django\core\handlers\exception.py", line 55, in inner
    response = get_response(request)
               ^^^^^^^^^^^^^^^^^^^^^
  File "C:\Users\Рабочий\Desktop\djangodzr\venv\Lib\site-packages\django\core\handlers\base.py", line 197, in _get_response
    response = wrapped_callback(request, *callback_args, **callback_kwargs)
               ^^^^^^^^^^^^^^^^^^^^^^^^^^^^^^^^^^^^^^^^^^^^^^^^^^^^^^^^^^^^
  File "C:\Users\Рабочий\Desktop\djangodzr\myproj\myweb\views.py", line 74, in create_product
    os.rename(product.photo.path, os.path.join(settings.MEDIA_ROOT, new_path))
FileNotFoundError: [WinError 3] Системе не удается найти указанный путь: 'C:\\Users\\Рабочий\\Desktop\\djangodzr\\myproj\\media\\product_photos\\вопрос_R5xOsHK.png' -> 'C:\\Users\\Рабочий\\Desktop\\djangodzr\\myproj\\media\\product_photos/product_photos/вопрос_R5xOsHK.png'
ERROR 2024-04-09 20:01:18,730 basehttp 17388 16872 "POST /product/ HTTP/1.1" 500 72323
INFO 2024-04-09 20:01:26,168 autoreload 22920 22040 Watching for file changes with StatReloader
WARNING 2024-04-09 20:01:32,359 log 22920 21624 Not Found: /
WARNING 2024-04-09 20:01:32,360 basehttp 22920 21624 "GET / HTTP/1.1" 404 3363
INFO 2024-04-09 20:01:39,159 basehttp 22920 21624 "GET /product/ HTTP/1.1" 200 2342
INFO 2024-04-09 20:02:02,462 basehttp 22920 22308 "GET /product/ HTTP/1.1" 200 1430
INFO 2024-04-09 20:02:27,870 basehttp 22920 22308 "GET /product/ HTTP/1.1" 200 2342
ERROR 2024-04-09 20:02:42,647 log 22920 22308 Internal Server Error: /product/
Traceback (most recent call last):
  File "C:\Users\Рабочий\Desktop\djangodzr\venv\Lib\site-packages\django\core\handlers\exception.py", line 55, in inner
    response = get_response(request)
               ^^^^^^^^^^^^^^^^^^^^^
  File "C:\Users\Рабочий\Desktop\djangodzr\venv\Lib\site-packages\django\core\handlers\base.py", line 197, in _get_response
    response = wrapped_callback(request, *callback_args, **callback_kwargs)
               ^^^^^^^^^^^^^^^^^^^^^^^^^^^^^^^^^^^^^^^^^^^^^^^^^^^^^^^^^^^^
  File "C:\Users\Рабочий\Desktop\djangodzr\myproj\myweb\views.py", line 74, in create_product
    os.rename(product.photo.path, os.path.join(settings.MEDIA_ROOT, new_path))
FileNotFoundError: [WinError 3] Системе не удается найти указанный путь: 'C:\\Users\\Рабочий\\Desktop\\djangodzr\\myproj\\media\\product_photos\\вопрос_hAtkvIb.png' -> 'C:\\Users\\Рабочий\\Desktop\\djangodzr\\myproj\\media\\product_photos/product_photos/вопрос_hAtkvIb.png'
ERROR 2024-04-09 20:02:42,649 basehttp 22920 22308 "POST /product/ HTTP/1.1" 500 72426
ERROR 2024-04-09 20:03:30,474 log 22920 492 Internal Server Error: /product/
Traceback (most recent call last):
  File "C:\Users\Рабочий\Desktop\djangodzr\venv\Lib\site-packages\django\core\handlers\exception.py", line 55, in inner
    response = get_response(request)
               ^^^^^^^^^^^^^^^^^^^^^
  File "C:\Users\Рабочий\Desktop\djangodzr\venv\Lib\site-packages\django\core\handlers\base.py", line 197, in _get_response
    response = wrapped_callback(request, *callback_args, **callback_kwargs)
               ^^^^^^^^^^^^^^^^^^^^^^^^^^^^^^^^^^^^^^^^^^^^^^^^^^^^^^^^^^^^
  File "C:\Users\Рабочий\Desktop\djangodzr\myproj\myweb\views.py", line 74, in create_product
    os.rename(product.photo.path, os.path.join(settings.MEDIA_ROOT, new_path))
FileNotFoundError: [WinError 3] Системе не удается найти указанный путь: 'C:\\Users\\Рабочий\\Desktop\\djangodzr\\myproj\\media\\product_photos\\вопрос_iqT5e0F.png' -> 'C:\\Users\\Рабочий\\Desktop\\djangodzr\\myproj\\media\\product_photos/product_photos/вопрос_iqT5e0F.png'
ERROR 2024-04-09 20:03:30,476 basehttp 22920 492 "POST /product/ HTTP/1.1" 500 72426
INFO 2024-04-09 20:04:27,293 autoreload 21928 9708 Watching for file changes with StatReloader
INFO 2024-04-09 20:04:35,073 basehttp 21928 632 "GET /product/ HTTP/1.1" 200 2342
ERROR 2024-04-09 20:04:52,096 log 21928 632 Internal Server Error: /product/
Traceback (most recent call last):
  File "C:\Users\Рабочий\Desktop\djangodzr\venv\Lib\site-packages\django\core\handlers\exception.py", line 55, in inner
    response = get_response(request)
               ^^^^^^^^^^^^^^^^^^^^^
  File "C:\Users\Рабочий\Desktop\djangodzr\venv\Lib\site-packages\django\core\handlers\base.py", line 197, in _get_response
    response = wrapped_callback(request, *callback_args, **callback_kwargs)
               ^^^^^^^^^^^^^^^^^^^^^^^^^^^^^^^^^^^^^^^^^^^^^^^^^^^^^^^^^^^^
  File "C:\Users\Рабочий\Desktop\djangodzr\myproj\myweb\views.py", line 74, in create_product
    os.rename(product.photo.path, os.path.join(settings.MEDIA_ROOT, new_path))
FileNotFoundError: [WinError 3] Системе не удается найти указанный путь: 'C:\\Users\\Рабочий\\Desktop\\djangodzr\\myproj\\media\\product_photos\\вопрос_Z3G7UBR.png' -> 'C:\\Users\\Рабочий\\Desktop\\djangodzr\\myproj\\media\\product_photos/product_photos/вопрос_Z3G7UBR.png'
ERROR 2024-04-09 20:04:52,099 basehttp 21928 632 "POST /product/ HTTP/1.1" 500 72429
ERROR 2024-04-09 20:07:16,503 log 21928 19560 Internal Server Error: /product/
Traceback (most recent call last):
  File "C:\Users\Рабочий\Desktop\djangodzr\venv\Lib\site-packages\django\core\handlers\exception.py", line 55, in inner
    response = get_response(request)
               ^^^^^^^^^^^^^^^^^^^^^
  File "C:\Users\Рабочий\Desktop\djangodzr\venv\Lib\site-packages\django\core\handlers\base.py", line 197, in _get_response
    response = wrapped_callback(request, *callback_args, **callback_kwargs)
               ^^^^^^^^^^^^^^^^^^^^^^^^^^^^^^^^^^^^^^^^^^^^^^^^^^^^^^^^^^^^
  File "C:\Users\Рабочий\Desktop\djangodzr\myproj\myweb\views.py", line 74, in create_product
    os.rename(product.photo.path, os.path.join(settings.MEDIA_ROOT, new_path))
FileNotFoundError: [WinError 3] Системе не удается найти указанный путь: 'C:\\Users\\Рабочий\\Desktop\\djangodzr\\myproj\\media\\product_photos\\вопрос.png' -> 'C:\\Users\\Рабочий\\Desktop\\djangodzr\\myproj\\media\\product_photos/product_photos/вопрос.png'
ERROR 2024-04-09 20:07:16,505 basehttp 21928 19560 "POST /product/ HTTP/1.1" 500 72373
INFO 2024-04-09 20:11:07,331 autoreload 21928 9708 C:\Users\Рабочий\Desktop\djangodzr\myproj\myweb\views.py changed, reloading.
INFO 2024-04-09 20:11:07,815 autoreload 13844 9312 Watching for file changes with StatReloader
INFO 2024-04-09 20:11:42,783 autoreload 13844 9312 C:\Users\Рабочий\Desktop\djangodzr\myproj\myweb\views.py changed, reloading.
INFO 2024-04-09 20:11:43,281 autoreload 19776 17616 Watching for file changes with StatReloader
INFO 2024-04-09 20:12:01,941 autoreload 19776 17616 C:\Users\Рабочий\Desktop\djangodzr\myproj\myweb\views.py changed, reloading.
INFO 2024-04-09 20:12:02,480 autoreload 18156 2544 Watching for file changes with StatReloader
ERROR 2024-04-09 20:15:11,288 log 18156 18004 Internal Server Error: /product/
Traceback (most recent call last):
  File "C:\Users\Рабочий\Desktop\djangodzr\venv\Lib\site-packages\django\core\handlers\exception.py", line 55, in inner
    response = get_response(request)
               ^^^^^^^^^^^^^^^^^^^^^
  File "C:\Users\Рабочий\Desktop\djangodzr\venv\Lib\site-packages\django\core\handlers\base.py", line 197, in _get_response
    response = wrapped_callback(request, *callback_args, **callback_kwargs)
               ^^^^^^^^^^^^^^^^^^^^^^^^^^^^^^^^^^^^^^^^^^^^^^^^^^^^^^^^^^^^
  File "C:\Users\Рабочий\Desktop\djangodzr\myproj\myweb\views.py", line 74, in create_product
    os.rename(product.photo.path, os.path.join(settings.MEDIA_ROOT, new_path))
FileNotFoundError: [WinError 3] Системе не удается найти указанный путь: 'C:\\Users\\Рабочий\\Desktop\\djangodzr\\myproj\\media\\product_photos\\вопрос_uL8UvdW.png' -> 'C:\\Users\\Рабочий\\Desktop\\djangodzr\\myproj\\media\\product_photos/product_photos/вопрос_uL8UvdW.png'
ERROR 2024-04-09 20:15:11,290 basehttp 18156 18004 "POST /product/ HTTP/1.1" 500 72455
ERROR 2024-04-09 20:17:53,058 log 18156 12768 Internal Server Error: /product/
Traceback (most recent call last):
  File "C:\Users\Рабочий\Desktop\djangodzr\venv\Lib\site-packages\django\core\handlers\exception.py", line 55, in inner
    response = get_response(request)
               ^^^^^^^^^^^^^^^^^^^^^
  File "C:\Users\Рабочий\Desktop\djangodzr\venv\Lib\site-packages\django\core\handlers\base.py", line 197, in _get_response
    response = wrapped_callback(request, *callback_args, **callback_kwargs)
               ^^^^^^^^^^^^^^^^^^^^^^^^^^^^^^^^^^^^^^^^^^^^^^^^^^^^^^^^^^^^
  File "C:\Users\Рабочий\Desktop\djangodzr\myproj\myweb\views.py", line 74, in create_product
    os.rename(product.photo.path, os.path.join(settings.MEDIA_ROOT, new_path))
FileNotFoundError: [WinError 3] Системе не удается найти указанный путь: 'C:\\Users\\Рабочий\\Desktop\\djangodzr\\myproj\\media\\product_photos\\вопрос_QqqX9EJ.png' -> 'C:\\Users\\Рабочий\\Desktop\\djangodzr\\myproj\\media\\product_photos/product_photos/вопрос_QqqX9EJ.png'
ERROR 2024-04-09 20:17:53,060 basehttp 18156 12768 "POST /product/ HTTP/1.1" 500 72447
ERROR 2024-04-09 20:18:11,144 log 18156 12768 Internal Server Error: /product/
Traceback (most recent call last):
  File "C:\Users\Рабочий\Desktop\djangodzr\venv\Lib\site-packages\django\core\handlers\exception.py", line 55, in inner
    response = get_response(request)
               ^^^^^^^^^^^^^^^^^^^^^
  File "C:\Users\Рабочий\Desktop\djangodzr\venv\Lib\site-packages\django\core\handlers\base.py", line 197, in _get_response
    response = wrapped_callback(request, *callback_args, **callback_kwargs)
               ^^^^^^^^^^^^^^^^^^^^^^^^^^^^^^^^^^^^^^^^^^^^^^^^^^^^^^^^^^^^
  File "C:\Users\Рабочий\Desktop\djangodzr\myproj\myweb\views.py", line 74, in create_product
    os.rename(product.photo.path, os.path.join(settings.MEDIA_ROOT, new_path))
FileNotFoundError: [WinError 3] Системе не удается найти указанный путь: 'C:\\Users\\Рабочий\\Desktop\\djangodzr\\myproj\\media\\product_photos\\Дыня.jpg' -> 'C:\\Users\\Рабочий\\Desktop\\djangodzr\\myproj\\media\\product_photos/product_photos/Дыня.jpg'
ERROR 2024-04-09 20:18:11,147 basehttp 18156 12768 "POST /product/ HTTP/1.1" 500 72361
INFO 2024-04-09 20:21:34,606 autoreload 18156 2544 C:\Users\Рабочий\Desktop\djangodzr\myproj\myweb\views.py changed, reloading.
INFO 2024-04-09 20:21:35,107 autoreload 21740 640 Watching for file changes with StatReloader
ERROR 2024-04-09 20:22:29,678 log 21740 5116 Internal Server Error: /product/
Traceback (most recent call last):
  File "C:\Users\Рабочий\Desktop\djangodzr\venv\Lib\site-packages\django\core\handlers\exception.py", line 55, in inner
    response = get_response(request)
               ^^^^^^^^^^^^^^^^^^^^^
  File "C:\Users\Рабочий\Desktop\djangodzr\venv\Lib\site-packages\django\core\handlers\base.py", line 197, in _get_response
    response = wrapped_callback(request, *callback_args, **callback_kwargs)
               ^^^^^^^^^^^^^^^^^^^^^^^^^^^^^^^^^^^^^^^^^^^^^^^^^^^^^^^^^^^^
  File "C:\Users\Рабочий\Desktop\djangodzr\myproj\myweb\views.py", line 79, in create_product
    return redirect('product_detail', pk=product.pk)
           ^^^^^^^^^^^^^^^^^^^^^^^^^^^^^^^^^^^^^^^^^
  File "C:\Users\Рабочий\Desktop\djangodzr\venv\Lib\site-packages\django\shortcuts.py", line 49, in redirect
    return redirect_class(resolve_url(to, *args, **kwargs))
                          ^^^^^^^^^^^^^^^^^^^^^^^^^^^^^^^^
  File "C:\Users\Рабочий\Desktop\djangodzr\venv\Lib\site-packages\django\shortcuts.py", line 180, in resolve_url
    return reverse(to, args=args, kwargs=kwargs)
           ^^^^^^^^^^^^^^^^^^^^^^^^^^^^^^^^^^^^^
  File "C:\Users\Рабочий\Desktop\djangodzr\venv\Lib\site-packages\django\urls\base.py", line 88, in reverse
    return resolver._reverse_with_prefix(view, prefix, *args, **kwargs)
           ^^^^^^^^^^^^^^^^^^^^^^^^^^^^^^^^^^^^^^^^^^^^^^^^^^^^^^^^^^^^
  File "C:\Users\Рабочий\Desktop\djangodzr\venv\Lib\site-packages\django\urls\resolvers.py", line 851, in _reverse_with_prefix
    raise NoReverseMatch(msg)
django.urls.exceptions.NoReverseMatch: Reverse for 'product_detail' with keyword arguments '{'pk': 15}' not found. 1 pattern(s) tried: ['product_detail/(?P<product_id>[0-9]+)/\\Z']
ERROR 2024-04-09 20:22:29,682 basehttp 21740 5116 "POST /product/ HTTP/1.1" 500 92353
INFO 2024-04-09 20:23:20,679 autoreload 21740 640 C:\Users\Рабочий\Desktop\djangodzr\myproj\myweb\views.py changed, reloading.
INFO 2024-04-09 20:23:21,204 autoreload 18268 18996 Watching for file changes with StatReloader
INFO 2024-04-09 20:24:23,613 autoreload 18268 18996 C:\Users\Рабочий\Desktop\djangodzr\myproj\myweb\views.py changed, reloading.
INFO 2024-04-09 20:24:24,076 autoreload 10052 13520 Watching for file changes with StatReloader
INFO 2024-04-09 20:26:29,620 autoreload 10052 13520 C:\Users\Рабочий\Desktop\djangodzr\myproj\myweb\views.py changed, reloading.
INFO 2024-04-09 20:26:30,078 autoreload 18484 6032 Watching for file changes with StatReloader
INFO 2024-04-09 20:27:18,319 autoreload 18484 6032 C:\Users\Рабочий\Desktop\djangodzr\myproj\myweb\views.py changed, reloading.
INFO 2024-04-09 20:27:18,838 autoreload 19704 16696 Watching for file changes with StatReloader
ERROR 2024-04-09 20:27:21,125 log 19704 18396 Internal Server Error: /product/
ERROR 2024-04-09 20:27:21,126 basehttp 19704 18396 "POST /product/ HTTP/1.1" 500 59
ERROR 2024-04-09 20:27:51,953 log 19704 18396 Internal Server Error: /product/
ERROR 2024-04-09 20:27:51,954 basehttp 19704 18396 "POST /product/ HTTP/1.1" 500 59
WARNING 2024-04-09 20:30:28,683 log 19704 18396 Not Found: /
WARNING 2024-04-09 20:30:28,684 basehttp 19704 18396 "GET / HTTP/1.1" 404 3363
INFO 2024-04-09 20:30:43,138 basehttp 19704 18396 "GET /edit_product/1/ HTTP/1.1" 200 1563
INFO 2024-04-09 20:30:48,499 basehttp 19704 18396 "GET /edit_product/8 HTTP/1.1" 301 0
INFO 2024-04-09 20:30:48,507 basehttp 19704 19512 "GET /edit_product/8/ HTTP/1.1" 200 1583
INFO 2024-04-09 20:30:57,517 basehttp 19704 19512 "POST /edit_product/8/ HTTP/1.1" 302 0
INFO 2024-04-09 20:30:57,523 basehttp 19704 19512 "GET /product_detail/8/ HTTP/1.1" 200 311
INFO 2024-04-09 20:31:05,471 basehttp 19704 19512 "GET /edit_product/8/ HTTP/1.1" 200 1588
INFO 2024-04-09 20:31:21,275 basehttp 19704 19512 "POST /edit_product/8/ HTTP/1.1" 302 0
INFO 2024-04-09 20:31:21,281 basehttp 19704 19512 "GET /product_detail/8/ HTTP/1.1" 200 323
INFO 2024-04-09 20:31:39,111 basehttp 19704 19512 "GET /product_detail/7 HTTP/1.1" 301 0
INFO 2024-04-09 20:31:39,116 basehttp 19704 20932 "GET /product_detail/7/ HTTP/1.1" 200 324
INFO 2024-04-09 20:31:47,424 basehttp 19704 20932 "GET /edit_product/1/ HTTP/1.1" 200 1563
INFO 2024-04-09 20:31:52,000 basehttp 19704 20932 "GET /edit_product/7 HTTP/1.1" 301 0
INFO 2024-04-09 20:31:52,008 basehttp 19704 22344 "GET /edit_product/7/ HTTP/1.1" 200 1601
INFO 2024-04-09 20:32:03,468 basehttp 19704 22344 "POST /edit_product/7/ HTTP/1.1" 302 0
INFO 2024-04-09 20:32:03,473 basehttp 19704 22344 "GET /product_detail/7/ HTTP/1.1" 200 328
INFO 2024-04-11 18:55:18,805 autoreload 17732 14084 Watching for file changes with StatReloader
WARNING 2024-04-11 18:55:31,229 log 17732 17288 Not Found: /
WARNING 2024-04-11 18:55:31,230 basehttp 17732 17288 "GET / HTTP/1.1" 404 3363
WARNING 2024-04-11 18:55:31,310 log 17732 17288 Not Found: /favicon.ico
WARNING 2024-04-11 18:55:31,312 basehttp 17732 17288 "GET /favicon.ico HTTP/1.1" 404 3414
INFO 2024-04-11 18:55:41,108 basehttp 17732 3932 "GET /purchased_products HTTP/1.1" 301 0
INFO 2024-04-11 18:55:41,162 basehttp 17732 16568 "GET /purchased_products/ HTTP/1.1" 200 5615
INFO 2024-04-11 18:56:07,153 basehttp 17732 7512 "GET /edit_product/3/ HTTP/1.1" 200 1551
WARNING 2024-04-11 18:56:16,916 log 17732 10300 Not Found: /media/myproj/static/default.jpeg
WARNING 2024-04-11 18:56:16,916 basehttp 17732 10300 "GET /media/myproj/static/default.jpeg HTTP/1.1" 404 3477
INFO 2024-04-11 18:56:44,163 autoreload 17732 14084 C:\Users\Рабочий\Desktop\djangodzr\myproj\myweb\urls.py changed, reloading.
INFO 2024-04-11 18:56:44,736 autoreload 19496 8256 Watching for file changes with StatReloader
INFO 2024-04-11 20:33:06,285 autoreload 16856 8864 Watching for file changes with StatReloader
WARNING 2024-04-11 20:33:40,284 log 16856 5352 Not Found: /
WARNING 2024-04-11 20:33:40,285 basehttp 16856 5352 "GET / HTTP/1.1" 404 3363
INFO 2024-04-11 20:33:47,930 basehttp 16856 5352 "GET /edit_product/1/ HTTP/1.1" 200 1563
INFO 2024-04-11 20:33:53,161 basehttp 16856 23096 "GET /edit_product/7/ HTTP/1.1" 200 1605
INFO 2024-04-11 20:34:00,471 basehttp 16856 4580 "GET /edit_product/10 HTTP/1.1" 301 0
INFO 2024-04-11 20:34:00,478 basehttp 16856 20960 "GET /edit_product/10/ HTTP/1.1" 200 1585
INFO 2024-04-11 20:34:19,887 basehttp 16856 704 "POST /edit_product/10/ HTTP/1.1" 302 0
INFO 2024-04-11 20:34:19,901 basehttp 16856 704 "GET /product_detail/10/ HTTP/1.1" 200 337
INFO 2024-04-11 20:36:09,336 basehttp 16856 7832 "GET /edit_product/10/ HTTP/1.1" 200 1613
INFO 2024-04-11 20:36:09,987 basehttp 16856 7832 "GET /edit_product/10/ HTTP/1.1" 200 1622
INFO 2024-04-11 20:36:18,223 basehttp 16856 7832 "GET /edit_product/10/ HTTP/1.1" 200 1622
INFO 2024-04-11 20:36:19,373 basehttp 16856 11124 "GET /edit_product/10/ HTTP/1.1" 200 1613
INFO 2024-04-11 20:43:23,126 basehttp 16856 3472 "GET /edit_product/10/ HTTP/1.1" 200 1613
INFO 2024-04-11 20:43:23,987 basehttp 16856 3472 "GET /edit_product/10/ HTTP/1.1" 200 1613
INFO 2024-04-11 20:43:24,894 basehttp 16856 3472 "GET /edit_product/10/ HTTP/1.1" 200 1613
INFO 2024-04-11 20:43:25,331 basehttp 16856 3472 "GET /edit_product/10/ HTTP/1.1" 200 1613
INFO 2024-04-11 20:43:25,554 basehttp 16856 3472 "GET /edit_product/10/ HTTP/1.1" 200 1613
INFO 2024-04-11 20:43:42,731 basehttp 16856 10304 "GET /edit_product/10/ HTTP/1.1" 200 1613
INFO 2024-04-11 20:43:43,369 basehttp 16856 10304 "GET /edit_product/10/ HTTP/1.1" 200 1613
INFO 2024-04-11 20:43:43,447 autoreload 16856 8864 C:\Users\Рабочий\Desktop\djangodzr\myproj\myproj\settings.py changed, reloading.
INFO 2024-04-11 20:43:44,048 autoreload 20416 14212 Watching for file changes with StatReloader
INFO 2024-04-11 20:44:08,831 autoreload 20416 14212 C:\Users\Рабочий\Desktop\djangodzr\myproj\myproj\settings.py changed, reloading.
INFO 2024-04-11 20:44:09,340 autoreload 9224 9292 Watching for file changes with StatReloader
INFO 2024-04-11 20:45:55,912 basehttp 9224 14524 "GET /edit_product/10/ HTTP/1.1" 200 1613
INFO 2024-04-11 20:45:56,321 basehttp 9224 14524 "GET /edit_product/10/ HTTP/1.1" 200 1613
INFO 2024-04-11 20:45:56,516 basehttp 9224 14524 "GET /edit_product/10/ HTTP/1.1" 200 1613
INFO 2024-04-11 20:45:56,688 basehttp 9224 14524 "GET /edit_product/10/ HTTP/1.1" 200 1613
INFO 2024-04-11 20:45:56,837 basehttp 9224 14524 "GET /edit_product/10/ HTTP/1.1" 200 1613
INFO 2024-04-11 20:46:11,122 autoreload 2292 8176 Watching for file changes with StatReloader
INFO 2024-04-11 20:46:14,102 basehttp 2292 19552 "GET /edit_product/10/ HTTP/1.1" 200 1613
INFO 2024-04-11 20:46:14,726 basehttp 2292 19552 "GET /edit_product/10/ HTTP/1.1" 200 1613
INFO 2024-04-11 20:46:16,576 basehttp 2292 19552 "POST /edit_product/10/ HTTP/1.1" 302 0
INFO 2024-04-11 20:46:16,582 basehttp 2292 19552 "GET /product_detail/10/ HTTP/1.1" 200 337
INFO 2024-04-11 20:49:10,930 basehttp 2292 21716 "GET /edit_product/10/ HTTP/1.1" 200 1613
INFO 2024-04-11 20:49:11,514 basehttp 2292 21716 "GET /edit_product/10/ HTTP/1.1" 200 1613
WARNING 2024-04-11 20:49:34,290 log 2292 15648 Not Found: /media/product_photos/вопрос_Z3G7UBR.png
WARNING 2024-04-11 20:49:34,291 basehttp 2292 15648 "GET /media/product_photos/%D0%B2%D0%BE%D0%BF%D1%80%D0%BE%D1%81_Z3G7UBR.png HTTP/1.1" 404 3540
INFO 2024-04-11 20:51:13,825 basehttp 2292 12052 "GET /edit_product/10/ HTTP/1.1" 200 1613
INFO 2024-04-11 20:51:15,003 basehttp 2292 12052 "GET /edit_product/10/ HTTP/1.1" 200 1613
WARNING 2024-04-11 20:51:22,972 log 2292 20688 Not Found: /
WARNING 2024-04-11 20:51:22,973 basehttp 2292 20688 "GET / HTTP/1.1" 404 3363
INFO 2024-04-11 20:51:38,986 basehttp 2292 23292 "GET /product/ HTTP/1.1" 200 2342
WARNING 2024-04-11 20:51:54,669 log 2292 5424 Not Found: /
WARNING 2024-04-11 20:51:54,670 basehttp 2292 5424 "GET / HTTP/1.1" 404 3363
WARNING 2024-04-11 20:52:01,683 log 2292 18076 Not Found: /product_detail
WARNING 2024-04-11 20:52:01,683 basehttp 2292 18076 "GET /product_detail HTTP/1.1" 404 3423
INFO 2024-04-11 20:52:07,566 basehttp 2292 18076 "GET /product_detail/1/ HTTP/1.1" 200 336
INFO 2024-04-11 20:52:10,874 basehttp 2292 19140 "GET /edit_product/1/ HTTP/1.1" 200 1563
WARNING 2024-04-11 20:52:14,211 log 2292 19140 Not Found: /media/myproj/static/default.jpeg
WARNING 2024-04-11 20:52:14,211 basehttp 2292 19140 "GET /media/myproj/static/default.jpeg HTTP/1.1" 404 3477
INFO 2024-04-11 20:55:03,073 autoreload 2292 8176 C:\Users\Рабочий\Desktop\djangodzr\myproj\myproj\settings.py changed, reloading.
INFO 2024-04-11 20:55:06,706 autoreload 19972 16436 Watching for file changes with StatReloader
INFO 2024-04-11 20:55:13,132 autoreload 19972 16436 C:\Users\Рабочий\Desktop\djangodzr\myproj\myproj\settings.py changed, reloading.
INFO 2024-04-11 20:55:13,608 autoreload 4944 17048 Watching for file changes with StatReloader
INFO 2024-04-11 20:55:21,852 basehttp 4944 20236 "GET /edit_product/1/ HTTP/1.1" 200 1563
INFO 2024-04-11 20:56:22,328 basehttp 4944 708 "GET /edit_product/1/ HTTP/1.1" 200 1563
INFO 2024-04-11 20:56:22,331 autoreload 4944 17048 C:\Users\Рабочий\Desktop\djangodzr\myproj\myweb\migrations\0004_product_photo_alter_order_total_amount.py changed, reloading.
INFO 2024-04-11 20:56:22,839 autoreload 9988 17528 Watching for file changes with StatReloader
INFO 2024-04-11 20:56:35,377 autoreload 9988 17528 C:\Users\Рабочий\Desktop\djangodzr\myproj\myweb\migrations\0004_product_photo_alter_order_total_amount.py changed, reloading.
INFO 2024-04-11 20:56:35,851 autoreload 8836 18316 Watching for file changes with StatReloader
INFO 2024-04-11 20:57:12,895 autoreload 8836 18316 C:\Users\Рабочий\Desktop\djangodzr\myproj\myweb\migrations\0004_product_photo_alter_order_total_amount.py changed, reloading.
INFO 2024-04-11 20:57:13,393 autoreload 10552 16432 Watching for file changes with StatReloader
INFO 2024-04-11 20:58:48,540 autoreload 10552 16432 C:\Users\Рабочий\Desktop\djangodzr\myproj\myweb\migrations\0004_product_photo_alter_order_total_amount.py changed, reloading.
INFO 2024-04-11 20:58:49,058 autoreload 17916 15632 Watching for file changes with StatReloader
INFO 2024-04-11 20:58:49,754 basehttp 17916 2284 "GET /edit_product/1/ HTTP/1.1" 200 1563
INFO 2024-04-11 20:58:51,376 basehttp 17916 19508 "GET /edit_product/1/ HTTP/1.1" 200 1563
INFO 2024-04-11 20:58:53,033 basehttp 17916 19508 "GET /edit_product/1/ HTTP/1.1" 200 1563
INFO 2024-04-11 20:58:53,550 basehttp 17916 19508 "GET /edit_product/1/ HTTP/1.1" 200 1563
INFO 2024-04-11 20:58:53,940 basehttp 17916 19508 "GET /edit_product/1/ HTTP/1.1" 200 1563
INFO 2024-04-11 20:58:54,113 basehttp 17916 19508 "GET /edit_product/1/ HTTP/1.1" 200 1563
INFO 2024-04-11 20:58:54,270 basehttp 17916 19508 "GET /edit_product/1/ HTTP/1.1" 200 1563
INFO 2024-04-11 20:58:54,420 basehttp 17916 19508 "GET /edit_product/1/ HTTP/1.1" 200 1563
INFO 2024-04-11 20:58:54,540 basehttp 17916 19508 "GET /edit_product/1/ HTTP/1.1" 200 1563
INFO 2024-04-11 20:58:59,048 basehttp 17916 19508 "GET /edit_product/1/ HTTP/1.1" 200 1563
INFO 2024-04-11 20:59:30,758 autoreload 18764 23104 Watching for file changes with StatReloader
INFO 2024-04-11 20:59:32,166 basehttp 18764 18328 "GET /edit_product/1/ HTTP/1.1" 200 1563
INFO 2024-04-11 20:59:32,910 basehttp 18764 18328 "GET /edit_product/1/ HTTP/1.1" 200 1563
INFO 2024-04-11 20:59:33,481 basehttp 18764 18328 "GET /edit_product/1/ HTTP/1.1" 200 1563
INFO 2024-04-11 20:59:33,930 basehttp 18764 18328 "GET /edit_product/1/ HTTP/1.1" 200 1563
INFO 2024-04-11 21:00:01,037 basehttp 18764 20360 "GET /edit_product/1/ HTTP/1.1" 200 1563
INFO 2024-04-11 21:00:01,814 basehttp 18764 13480 "GET /edit_product/1/ HTTP/1.1" 200 1563
INFO 2024-04-11 21:00:02,446 basehttp 18764 13480 "GET /edit_product/1/ HTTP/1.1" 200 1563
INFO 2024-04-11 21:00:02,835 basehttp 18764 13480 "GET /edit_product/1/ HTTP/1.1" 200 1563
INFO 2024-04-11 21:00:03,015 basehttp 18764 13480 "GET /edit_product/1/ HTTP/1.1" 200 1563
INFO 2024-04-11 21:00:03,172 basehttp 18764 13480 "GET /edit_product/1/ HTTP/1.1" 200 1563
INFO 2024-04-11 21:00:03,323 basehttp 18764 13480 "GET /edit_product/1/ HTTP/1.1" 200 1563
INFO 2024-04-11 21:00:22,791 autoreload 17828 23176 Watching for file changes with StatReloader
INFO 2024-04-11 21:02:49,738 autoreload 16792 1576 Watching for file changes with StatReloader
INFO 2024-04-11 21:02:58,660 basehttp 16792 3044 "GET /edit_product/1/ HTTP/1.1" 200 1563
INFO 2024-04-11 21:03:00,832 basehttp 16792 3044 "GET /edit_product/1/ HTTP/1.1" 200 1563
INFO 2024-04-11 21:03:07,590 basehttp 16792 16224 "POST /edit_product/1/ HTTP/1.1" 302 0
INFO 2024-04-11 21:03:07,597 basehttp 16792 16224 "GET /product_detail/1/ HTTP/1.1" 200 330
INFO 2024-04-11 21:03:52,507 autoreload 16792 1576 C:\Users\Рабочий\Desktop\djangodzr\myproj\myweb\migrations\0004_product_photo_alter_order_total_amount.py changed, reloading.
